Workbook

Sheet feedback_send
C3: ='(1-2) 기초자료_퇴직급여 '!D12&" feedback" -> feedback
C6: (1_1) 기초자료_퇴직급여 시트에서 다음 사항 누락되었습니다. 기재 부탁드립니다.
B8: 1 | C8: 사외적립자산
B10: =B8+1 -> 2 | C10: 국민연금전환금
B12: =B10+1 -> 3 | C12: 정년
B14: =B12+1 -> 4 | C14: 1년미만 근무기간 처리방법
B16: =B14+1 -> 5 | C16: 임금상승률
B18: 6 | C18: 채권등급
C22: (2-2) 재직자 명부 시트에서 다음사항 확인 부탁드립니다.
B24: 1 | C24: 빈칸 있는 곳 확인하여 채워 달라고 전달.
B26: 2 | C26: 다음 재직자 분들은 평균임금이 1,000,000원 미만입니다.
C27: 회사 정책상 그러 할 수 있으나, 확인 부탁드립니다.
C29: 사원번호 | D29: 평균임금
D30: =VLOOKUP(C30,'(2-2) 재직자 명부'!$B$2:$J$164,5,0) -> #N/A
D31: =VLOOKUP(C31,'(2-2) 재직자 명부'!$B$2:$J$164,5,0) -> #N/A
D32: =VLOOKUP(C32,'(2-2) 재직자 명부'!$B$2:$J$164,5,0) -> #N/A
D33: =VLOOKUP(C33,'(2-2) 재직자 명부'!$B$2:$J$164,5,0) -> #N/A
D34: =VLOOKUP(C34,'(2-2) 재직자 명부'!$B$2:$J$164,5,0) -> #N/A
B36: 3 | C36: 다음 재직자 분들의 명부 추계액과 gia산출 추계액 값 차이가 큽니다.
C37: 회사 정책상 그러 할 수 있으나, 확인 부탁드립니다.
C38: (중간정산일자 누락, 입사일자 오류, 적용배수 오류)
C40: 사원번호 | D40: 당년도퇴직금추계액 | E40: 차년도 퇴직금추계액
D41: =VLOOKUP(C41,'(2-2) 재직자 명부'!$B$2:$L$218,6,0) -> #N/A | E41: =VLOOKUP(C41,'(2-2) 재직자 명부'!$B$2:$L$218,7,0) -> #N/A

Sheet (1-1) self-checklist
A1: 예
A2: 아니오
B3: ***작성 완료 후 최종 확인사항
B5: 기초자료와 명부 작성 완료 후 아래 표에서 최종확인 부탁드립니다.
B6: 아니오 선택 시, (1_2) 기초자료_퇴직급여와 명부 시트에서 해당사항 수정 부탁드립니다.
B8: 시트 | C8: # | D8: 항목 | E8: 확인 사항 | F8: 답변(드롭박스에서 선택)
B9: (1-2) 기초자료 _퇴직급여 | C9: 1 | D9: 사외적립자산 | E9: 회계 장부 반영 금액과 일치합니까? | F9: 아니오
C10: 2 | D10: 정년 | E10: ="정년은 만 "&'(1-2) 기초자료_퇴직급여 '!$F$103&" 세 입니까?" -> 정년은 만 60 세 입니까? | F10: 예
C11: 3 | D11: 임금피크제 | E11: =IF('(1-2) 기초자료_퇴직급여 '!$F$104="","임금피크제 적용 여부 선택 부탁드립니다",IF('(1-2) 기초자료_퇴직급여 '!$F$104="YES","만 "&'(1-2) 기초자료_퇴직급여 '!I104&"세 부터 임금피크제가 적용됩니까?","임금피크제 미적용 기업입니까?")) -> 임금피크제 미적용 기업입니까? | F11: 예
C12: 4 | D12: 기타장기종업원급여 | E12: =IF('(1-2) 기초자료_퇴직급여 '!F105="","기타장기종업원급여 적용 여부 선택 부탁드립니다","기타장기종업원급여 "&IF('(1-2) 기초자료_퇴직급여 '!$F$105="YES","적용","미적용")&" 기업입니까?") -> 기타장기종업원급여 미적용 기업입니까? | F12: 예
C13: 5 | D13: 퇴직금제도 | E13: =IF('(1-2) 기초자료_퇴직급여 '!$F$108="","퇴직금제도 선택 부탁드립니다","퇴직금제도는 "&'(1-2) 기초자료_퇴직급여 '!$F$108&"를 적용합니까?") -> 퇴직금제도는 법정제를 적용합니까? | F13: 예
C14: 6 | D14: 연봉제/호봉제 | E14: =IF('(1-2) 기초자료_퇴직급여 '!$I$112="","임금체계 선택 부탁드립니다.",IF('(1-2) 기초자료_퇴직급여 '!$I$112="예 (호봉제)","근무기간에 따른 호봉 적용 기업 맞습니까?","근무기간에 따른 호봉 미적용 기업입니까?")) -> 근무기간에 따른 호봉 미적용 기업입니까? | F14: 아니오
C15: ='(2-2) 재직자 명부'!B9 -> 8 | D15: 채권등급 | E15: ="할인율 산출기준 채권 "&'(1-2) 기초자료_퇴직급여 '!$D$121&" 적용 기업입니까?" -> 할인율 산출기준 채권 회사채AA+ 적용 기업입니까? | F15: 아니오
B16: (2-2) 재직자명부 | C16: 1 | D16: 1년 미만 재직자 | E16: 1년 미만 재직자도 기재 하셨습니까? | F16: 예
C17: 2 | D17: 퇴직금 추계액 | E17: 모든 재직자의 당년도, 차년도 퇴직금 추계액을 입력하셨습니까? (1년 미만 재직자의 경우 일할 계산) | F17: 아니오
C18: 3 | D18: 기준급여 | E18: 3개월 미만 재직자의 경우 한달 근무 시 지급받는 급여로 기재 하셨습니까? | F18: 예
C19: 4 | D19: 평가기준일 퇴사자 | E19: 평가기준일 발생 퇴직금을 비용(미지급 포함) 처리 하셨습니까? | F19: 예
C20: 5 | D20: 평가기준일 퇴사자 | E20: =IF(F19="예","재직자명부에서 평가기준일 퇴사자 제외 하셨습니까?","비용처리 안하셨다면 1월 퇴사 처리 예정입니까?") -> 재직자명부에서 평가기준일 퇴사자 제외 하셨습니까? | F20: 예
C21: 6 | D21: 중간정산 대상자 | E21: 근퇴법 시행령 제3조에(퇴직금 중간정산 사유)에 해당됩니까? | F21: 예
B22: (2-3) 퇴직자명부 | C22: 1 | D22: 평가기준일 퇴사자 | E22: =IF(F19="예","퇴직자명부에 평가기준일 퇴사자를 포함하셨습니까?","퇴직자명부에서 평가기준일 퇴사자를 제외하셨습니까?") -> 퇴직자명부에 평가기준일 퇴사자를 포함하셨습니까? | F22: 예

Sheet (1-2) 기초자료_퇴직급여 
B2: (1-2) 퇴직급여채무 평가를 위한 기초자료
B4: * 근퇴법에서는 퇴직급여제도를 퇴직금제도, 퇴직연금제도(DB, DC, IRP)로 구분합니다.
B5: IFRS 퇴직급여채무평가 대상은 DC(IRP 포함)에 가입한 재직자를 제외한 전 종업원(1년 미만 근속자 포함)입니다.
B6: 따라서 기초자료, 재직자 및 퇴직자명부는 IFRS 퇴직급여채무평가 대상자에 한하여 작성하여 주시기 바랍니다.
B8: ☞ 퇴직금 또는 기타장기종업원급여의 지급규정 변경시 변경내용을 제공하여 주시기 바랍니다. (예 : 법정제 → 누진제 등, 장기근속포상금 변경 등)
B10: 1. 일반사항
B12: 회사명
B13: 담당자
B14: 전화번호
B15: 이메일
B16: 결산월 | D16: 2025.12.31
B17: 주 소 | D17: 보고서 전달 받으실 주소 기재 부탁드립니다.
B19: 2. 평가대상 및 퇴직급여 지급(환입) 현황
B21: ☞ DC형 퇴직연금가입자(IRP 포함)를 제외한 전 임직원을 기준으로 작성
B22: ☞ 금액은 모두 (+)로 기재 | J22: ☞ FALSE일 경우 명부와 자료 불일치. 확인 부탁드립니다.
B24: 항목 | D24: 내용 | J24: 기초자료 및 명부 일치여부 | K24: 비 고
D25: 작성기준일 | I25: 251231 | K25: 기초자료 및 명부 작성 기준일
B26: 평가 대상 | C26: 재직자수 (명) | D26: 임원 | F26: 0 | G26: 0 | H26: 0 | I26: 17 | J26: =COUNTIF('(2-2) 재직자 명부'!I:I,3)=I26 -> TRUE | K26: 작성기준일 현재 재직자 수 (2-2) 재직자 명부의 재직자 수와 일치
D27: 직원 | F27: 0 | G27: 0 | H27: 0 | I27: 664 | J27: =COUNTIF('(2-2) 재직자 명부'!I:I,1)+COUNTIF('(2-2) 재직자 명부'!I:I,2)=I27 -> TRUE
D28: 계약직 | F28: 0 | G28: 0 | H28: 0 | I28: 69 | J28: =COUNTIF('(2-2) 재직자 명부'!I:I,4)=I28 -> TRUE
D29: 합계 | F29: =SUM(F26:F28) -> 0 | G29: =SUM(G26:G28) -> 0 | H29: =SUM(H26:H28) -> 0 | I29: =SUM(I26:I28) -> 750 | J29: =COUNTA('(2-2) 재직자 명부'!B2:B60000)=I29 -> TRUE
C30: 퇴직자수 (명) | D30: 임원 | F30: 0 | G30: 0 | H30: 0 | I30: 2 | J30: =COUNTIFS('(2-3) 퇴직자 및 DC전환자 명부'!I:I,1,'(2-3) 퇴직자 및 DC전환자 명부'!H:H,3)=I30 -> FALSE | K30: 기초부터 누계 퇴직자 수 (2-3) 퇴직자 명부의 퇴직자 수와 일치
D31: 직원 | F31: 0 | G31: 0 | H31: 0 | I31: 381 | J31: =COUNTIFS('(2-3) 퇴직자 및 DC전환자 명부'!I:I,1,'(2-3) 퇴직자 및 DC전환자 명부'!H:H,1)+COUNTIFS('(2-3) 퇴직자 및 DC전환자 명부'!I:I,1,'(2-3) 퇴직자 및 DC전환자 명부'!H:H,2)=I31 -> FALSE
D32: 계약직 | F32: 0 | G32: 0 | H32: 0 | I32: 94 | J32: =COUNTIFS('(2-3) 퇴직자 및 DC전환자 명부'!I:I,1,'(2-3) 퇴직자 및 DC전환자 명부'!H:H,4)=I32 -> FALSE
D33: 합계 | F33: =SUM(F30:F32) -> 0 | G33: =SUM(G30:G32) -> 0 | H33: =SUM(H30:H32) -> 0 | I33: =SUM(I30:I32) -> 477 | J33: =COUNTIF('(2-3) 퇴직자 및 DC전환자 명부'!I:I,1)=I33 -> FALSE
C34: 중간정산자수 | D34: {=IFERROR(SUMPRODUCT(--(YEAR('(2-2) 재직자 명부'!J2:J10000)=VALUE("20"&LEFT(I25,2)))),0)} -> 26 | E34: {=IFERROR(SUMPRODUCT(--(LEFT('(2-2) 재직자 명부'!J:J,4)="20"&LEFT(I25,2))),0)} -> 0 | F34: 0 | G34: 0 | H34: 0 | I34: 26 | J34: =I34=(E34+D34) -> TRUE | K34: 기초부터 누계 중간정산자 수 (2-2) 재직자 명부의 당기 중간정산자 수와 일치
C35: DC전환자수 | F35: 0 | G35: 0 | H35: 0 | I35: 0 | J35: =COUNTIF('(2-3) 퇴직자 및 DC전환자 명부'!I:I,2)=I35 -> TRUE | K35: 기초부터 누계 DC전환자 수 (2-3) DC전환자 명부의 DC전환자 수와 일치
B36: 퇴직금 추계액 (원) | D36: 임원 | F36: 0 | G36: 0 | H36: 0 | I36: 0 | J36: =ABS(SUMIF('(2-2) 재직자 명부'!I:I,3,'(2-2) 재직자 명부'!G:G)-I36)<1 -> FALSE | K36: 작성기준일 현재 퇴직금 추계액 (2-2) 재직자 명부의 당년도 퇴직금추계액과 일치
D37: 직원 | F37: 0 | G37: 0 | H37: 0 | I37: 0 | J37: =ABS(SUMIF('(2-2) 재직자 명부'!I:I,1,'(2-2) 재직자 명부'!G:G)+SUMIF('(2-2) 재직자 명부'!I:I,2,'(2-2) 재직자 명부'!G:G)-I37)<1 -> FALSE
D38: 계약직 | F38: 0 | G38: 0 | H38: 0 | I38: 0 | J38: =ABS(SUMIF('(2-2) 재직자 명부'!I:I,4,'(2-2) 재직자 명부'!G:G)-I38)<1 -> FALSE
D39: 합계 | F39: =SUM(F36:F38) -> 0 | G39: =SUM(G36:G38) -> 0 | H39: =SUM(H36:H38) -> 0 | I39: =SUM(I36:I38) -> 0 | J39: =ABS(SUM('(2-2) 재직자 명부'!G:G)-I39)<1 -> FALSE
B41: 퇴직부채 감소 (증가)액(원) | C41: 급여지급액 (A) | D41: 퇴직금 (a) | F41: 0 | G41: 0 | H41: 0 | I41: 6789774140 | J41: =ABS(SUMIF('(2-3) 퇴직자 및 DC전환자 명부'!I:I,1,'(2-3) 퇴직자 및 DC전환자 명부'!G:G)-I41)<1 -> FALSE | K41: 기초부터 누계 퇴직금 지급액(퇴직급여충당금 감소 처리) (2-3) 퇴직자 명부의 퇴직금 합계와 일치
D42: 중간정산금액 (b) | F42: 0 | G42: 0 | H42: 0 | I42: 691876810 | J42: =ABS((K44+L44)-I42)<1 -> FALSE | K42: 기초부터 누계 중간정산금액(퇴직급여충당금 감소 처리) (2-2) 재직자 명부의 중간정산액 합계와 일치
D43: DC 전환금 (c) | F43: 0 | G43: 0 | H43: 0 | I43: 0 | J43: =ABS(SUMIF('(2-3) 퇴직자 및 DC전환자 명부'!I:I,2,'(2-3) 퇴직자 및 DC전환자 명부'!G:G)-I43)<1 -> TRUE | K43: 기초부터 누계 DC전환금액(퇴직급여충당금 감소 처리) (2-3) DC전환자 명부의 DC전환금 합계와 일치
D44: 소계 (a+b+c) | F44: =SUM(F41:F43) -> 0 | G44: =SUM(G41:G43) -> 0 | H44: =SUM(H41:H43) -> 0 | I44: =SUM(I41:I43) -> 7481650950 | J44: =ABS((SUM('(2-3) 퇴직자 및 DC전환자 명부'!G:G)+I42)-I44)<1 -> TRUE | K44: =SUMIFS('(2-2) 재직자 명부'!K:K,'(2-2) 재직자 명부'!J:J,">10000000",'(2-2) 재직자 명부'!J:J,">"&LEFT(I25,4)&"0000") -> 0 | L44: =SUMIFS('(2-2) 재직자 명부'!K:K,'(2-2) 재직자 명부'!J:J,"<10000000",'(2-2) 재직자 명부'!J:J,">="&DATE(LEFT(I25,4),1,1)) -> 0
C45: 관계사전입(전출)액 (B) | D45: 관계사 전입액 (d) | F45: 0 | G45: 0 | H45: 0 | I45: 0 | J45: =ABS(SUMIF('(2-4) 추가 명부'!J:J,1,'(2-4) 추가 명부'!G:G)-I45)<1 -> TRUE | K45: 기초부터 누계 관계사 전입(전출)액 (2-4) 추가 명부의 관계사 전입(전출)액 합계와 일치
D46: 관계사 전출액 (e) | F46: 0 | G46: 0 | H46: 0 | I46: 79296260 | J46: =ABS(SUMIF('(2-4) 추가 명부'!J:J,2,'(2-4) 추가 명부'!G:G)-I46)<1 -> FALSE
D47: 소계 (d-e) | F47: =F45-F46 -> 0 | G47: =G45-G46 -> 0 | H47: =H45-H46 -> 0 | I47: =I45-I46 -> -79296260 | J47: =ABS((SUMIF('(2-4) 추가 명부'!J:J,1,'(2-4) 추가 명부'!G:G)-SUMIF('(2-4) 추가 명부'!J:J,2,'(2-4) 추가 명부'!G:G))-I47)<1 -> FALSE
C48: 사업결합(처분)액 (C) | D48: 사업결합액 (f) | F48: 0 | G48: 0 | H48: 0 | I48: 0 | J48: =ABS(SUMIF('(2-4) 추가 명부'!J:J,3,'(2-4) 추가 명부'!G:G)-I48)<1 -> TRUE | K48: 기초부터 누계 사업결합(처분)액 (2-4) 추가 명부의 사업결합(처분) 금액 합계와 일치
D49: 사업처분액 (g) | F49: 0 | G49: 0 | H49: 0 | I49: 0 | J49: =ABS(SUMIF('(2-4) 추가 명부'!J:J,4,'(2-4) 추가 명부'!G:G)-I49)<1 -> TRUE
...

Sheet (1-3) 기초자료_기타장기종업원급여
B2: (1-3) 기타장기종업원급여채무 평가를 위한 기초자료
B4: 1. 기타장기종업원급여 지급규정
B5: - 관련규정을 다음과 같이 요약하여 주시기 바랍니다.
B6: - 아래 양식 이외에 필요한 정보가 있으면 양식에 추가하여 작성하여 주시기 바랍니다.
B7: - 아래의 표는 예시로 작성된 것이며, 귀사의 규정에 맞게 수정하여 주시면 됩니다.
B9: ( 예시 )
B10: 근속년수 | C10: 지급액 | D10: 지급기준 | E10: 지급방법 | F10: 기타
B11: 10년 근속상 | C11: 금 5돈 | D11: 8월중 일괄지급, 만 10년 근무자 | E11: 금 또는 금에 해당하는 복리포인트
B12: 15년 근속상 | C12: 금 5돈 | D12: 8월중 일괄지급, 만 15년 근무자 | E12: 금 또는 금에 해당하는 복리포인트
B13: 20년 근속상 | C13: 금 10돈, 여행경비(통상급여의 60%) | D13: 8월중 일괄지급, 만 20년 근무자 | E13: 금 또는 금에 해당하는 복리포인트
B14: 25년 근속상 | C14: 금 20돈, 여행경비(통상급여의 70%) | D14: 8월중 일괄지급, 만 25년 근무자 | E14: 여행권 지급 또는 여행권에 해당하는 복리포인트
B17: 2. 기타장기종업원급여 지급내역 (최근 3년)
B18: - 아래 양식이 적합하지 않으면 양식을 변경하여 작성하여 주시기 바랍니다.
B19: - 인원은 명, 금액은 원입니다. 단위를 확인하여 주시기 바랍니다.
B20: - 과거 3년 동안, 연도별 지급내역을 기록하여 주십시오 (기간은 회사가 비용으로 처리한 날짜 기준입니다)
B21: - 아래의 표는 예시로 작성된 것이며, 예시를 참고로 하여 귀사의 실제 지급내역을 입력해 주시기 바랍니다.
B23: <작성방법>
B24: ① 근속자(명) | C24: 해당인원 수 기재
B25: ② 장기근속 축하금 | C25: 실적 발생금액 합계
B26: ③ 세부내역 | C26: 포인트, 현금, 실물(금, 또는 여행권) 지급 여부 기재
B28: 평가기준일 직전 1년 (2022.1.1~2022.06.30)
B29: 근속년수 | C29: 근속자(명) | D29: 장기근속축하금(합계, 원) | E29: 세부 내역
B30: 10년 근속상
B31: 15년 근속상
B32: 20년 근속상
B33: 25년 근속상
B34: 합계

Sheet (2-1) 명부 작성방법
C2: (2-1) 명부 작성방법
C3: ☞ 모든 항목은 필수 입력 사항입니다.
C4: ☞ 명부는 "(2-2) 재직자 명부", "(2-3) 퇴직자 및 DC 전환자 명부", "(2-3) 추가 명부" 로 구분됩니다.
C6: 구분 | D6: 항목명 | E6: 작성방법
C7: 공통 | E7: 평가기준일을 기준으로 작성 양식 변경 절대 불가 1년 미만 근속 재직자 포함 퇴직금을 지급하지 않는 재직자 제외 DC 또는 IRP 제도 가입자는 제외
D8: 사원번호 | E8: 회사가 정한 사원번호 입력 (개인 실명 기재 금지)
D9: 생년월일 | E9: yyyymmdd 형식
D10: 성별 | E10: 남 : 1, 여 : 2
D11: 입사일자 | E11: yyyymmdd 형식, 최초 입사일자 (퇴직금 산정 기준일) 입력
C12: 재직자 명부 | D12: 기준급여 | E12: 퇴직금 지급의 기준이 되는 월 기준급여 입력 (예: 법정제인 경우 평균임금)
D13: 당년도 퇴직금추계액 | E13: 사규에서 정하는 퇴직금 추계액 입력(평가기준일 기준) 임원, 계약직은 필수 입력
D14: 차년도 퇴직금추계액 | E14: 사규에서 정하는 차년도퇴직금추계액 입력(평가기준일로 부터 1년후 퇴직을 가정) 임원, 계약직은 필수 입력
D15: 종업원 구분 | E15: 일반직: 1, 임원: 3, 계약직: 4 계약직이라도 정규직의 퇴직금규정을 적용하고 정년이 일반직과 동일한 경우 2 입력(직종 3, 4는 정년이 적용되지 않음)
D16: 중간정산기준일 | E16: 입사 후 중간정산 한 적이 있는 경우 반드시 입력 중간정산일 당일 입력 여러 번 중간정산한 경우 최종 중간정산일자 입력
D17: 중간정산액 | E17: =LEFT('(1-2) 기초자료_퇴직급여 '!I25,4)&"년에 중간정산 한 재직자는 반드시 입력"& "(그 외의 중간정산자는 입력하지 않아도 됨)" -> 2512년에 중간정산 한 재직자는 반드시 입력(그 외의 중간정산자는 입력하지 않아도 됨)
D18: 제도구분 | E18: 퇴직금 제도가 구분 되어 적용되는 경우 숫자로 구분 (1,2,3..) 구분되지 않는 경우는 입력하지 않아도 됨 (예 생산: 1 , 사무직: 2)
C19: 퇴직자 및 DC전환자 명부 | E19: 300인 이상인 기업의 경우 3년치(평가기준일 직전 3년간) 퇴직자명부 작성 300인 미만인 경우 해당 회계년도의 퇴직자만 작성
D20: 퇴직일 / DC전환일 | E20: 퇴직일 또는 DC 전환일 입력
D21: 사유 | E21: 1: 퇴직, 2: DC전환 구분 입력
D22: 제도구분 | E22: 퇴직금 제도가 구분 되어 적용되는 경우 숫자로 구분 (1,2,3..) 구분되지 않는 경우는 입력하지 않아도 됨 (예 생산: 1 , 사무직: 2)
C23: 추가 명부 | D23: 유의적인 채무 변동이 있을 경우 변동 원인을 평가하여 반영하기 위한 명부
E24: 다음 중 해당사항이 있는 경우에만 입력 : 축소, 정산, 사업결합, 사업분할,기타장기종업원급여 해당 사건 발생일을 기준으로 작성
D25: 기준급여, 직종, 중간정산일 | E25: 재직자 명부와 동일한 방식으로 작성
D26: 사유발생일 시점 퇴직금추계액 | E26: 사유발생일 시점에 퇴직 시 지급하여야 하는 퇴직금 입력
D27: 사유 | E27: 1: 관계사전입, 2: 관계사전출, 3: 사업결합, 4: 사업처분, 5: 기타장기종업원 해당사항 숫자로 입력
D28: 사유발생일 | E28: 해당 사유 발생일 입력

Sheet (2-2) 재직자 명부
A1: 참고사항 | B1: 사원번호 | C1: 생년월일 | D1: 성별 (1:남자, 2:여자) | E1: 입사일자 | F1: 기준급여 | G1: 당년도 퇴직금추계액 | H1: 차년도 퇴직금추계액 (임원, 정년초과자, 계약직은 반드시 입력) | I1: 종업원 구분 (1:직원, 3:임원, 4:계약직) | J1: 중간정산기준일 | K1: 중간정산액 | L1: 제도구분 (1,2,3) | M1: 적용배수
A2: ※ 양식 변경 절대 불가 | B2: 1 | C2: 1979/06/22 | D2: 2 | E2: 37834 | F2: 7508526.7 | G2: 168458430 | I2: 1
A3: 입사일자 | B3: 2 | C3: 1972/10/11 | D3: 1 | E3: 39776 | F3: 10277371 | G3: 175897920 | I3: 1
A4: 최초 입사일자 입력 | B4: 3 | C4: 1985/06/26 | D4: 2 | E4: 44536 | F4: 9568750 | G4: 38982830 | I4: 1
A5: 기준급여 | B5: 4 | C5: 1979/12/25 | D5: 2 | E5: 40126 | F5: 6408030 | G5: 103529190 | I5: 1
A6: 퇴직금 계산시 사용되는 평균임금 | B6: 5 | C6: 1984/07/21 | D6: 1 | E6: 43451 | F6: 5318177.5 | G6: 37474940 | I6: 1
A7: 당년도 퇴직금추계액 | B7: 6 | C7: 1992/08/25 | D7: 2 | E7: 44900 | F7: 4376200 | G7: 13464310 | I7: 1
A8: 작성기준일 현재 퇴직시 지급하는 퇴직금 | B8: 7 | C8: 1992/02/12 | D8: 2 | E8: 45460 | F8: 4205840 | G8: 6487370 | I8: 1
A9: (임원, 계약직 필수 입력) | B9: 8 | C9: 1978/08/07 | D9: 1 | E9: 44987 | F9: 9249690 | G9: 26253920 | I9: 1
A10: 차년도 퇴직금추계액 | B10: 9 | C10: 1985/05/05 | D10: 1 | E10: 42767 | F10: 5325600 | G10: 23097060 | I10: 1 | J10: 44439
A11: 작성기준일로부터 1년 후 퇴직시 지급하는 퇴직금 | B11: 10 | C11: 1987/08/20 | D11: 1 | E11: 44956 | F11: 5500750 | G11: 16080280 | I11: 1
A12: (임원, 계약직 필수 입력) | B12: 11 | C12: 1990/01/01 | D12: 1 | E12: 44781 | F12: 5142570 | G12: 1718890 | I12: 1 | J12: 45900 | K12: 16150060
A13: 중간정산기준일 | B13: 12 | C13: 1975/01/27 | D13: 1 | E13: 37257 | F13: 7749310 | G13: 56240890 | I13: 1 | J13: 43373
A14: 입사 후 중간정산한 적이 있는 경우 반드시 입력 | B14: 13 | C14: 1980/04/01 | D14: 1 | E14: 42352 | F14: 8523870.8 | G14: 85729130 | I14: 1
A15: 중간정산 당일로 입력 | B15: 14 | C15: 1985/12/11 | D15: 1 | E15: 44655 | F15: 6806750.8 | G15: 25511330 | I15: 1
A16: 중간정산액 | B16: 15 | C16: 1987/09/19 | D16: 1 | E16: 44040 | F16: 4884325 | G16: 26535940 | I16: 1
A17: =LEFT('(1-2) 기초자료_퇴직급여 '!I25,4)&"년에 중간정산한 종업원은 반드시 입력" -> 2512년에 중간정산한 종업원은 반드시 입력 | B17: 16 | C17: 1993/12/02 | D17: 1 | E17: 45139 | F17: 4616410 | G17: 2706610 | I17: 1 | J17: 45808 | K17: 8672730
A18: 그 외 중간정산자는 입력하지 않아도 됨 | B18: 17 | C18: 1992/09/11 | D18: 1 | E18: 45579 | F18: 3416670 | G18: 4156170 | I18: 1
A19: 제도구분 | B19: 18 | C19: 1982/01/03 | D19: 1 | E19: 45243 | F19: 7757196.7 | G19: 16577030 | I19: 1
A20: 구분되는 제도를 반영하는 경우 입력 (숫자기입) | B20: 19 | C20: 1990/04/07 | D20: 1 | E20: 43444 | F20: 4137537.5 | G20: 29234820 | I20: 1
A21: 적용배수 | B21: 20 | C21: 1992/08/12 | D21: 2 | E21: 45621 | F21: 5750000 | G21: 6332880 | I21: 1
A22: 임원의 경우 적용 배수 입력 ( 예: 1.5, 2, 3... ) | B22: 21 | C22: 1981/07/15 | D22: 1 | E22: 45432 | F22: 6870840 | G22: 11125120 | I22: 1
A23: 기타 | B23: 22 | C23: 1996/06/16 | D23: 2 | E23: 43801 | F23: 3812720 | G23: 23210590 | I23: 1
A24: 전액 확정기여형(DC) 제도 가입자는 제외 | B24: 23 | C24: 1986/04/28 | D24: 1 | E24: 44006 | F24: 5040370 | G24: 27853230 | I24: 1
A25: 1년 미만 재직자도 입력 | B25: 24 | C25: 1988/02/23 | D25: 2 | E25: 44144 | F25: 3866300 | G25: 19903510 | I25: 1
A26: 기준급여 * 지급률 = 당년도 퇴직금추계액 | B26: 25 | C26: 1993/06/08 | D26: 2 | E26: 44291 | F26: 3965290 | G26: 18816120 | I26: 1
B27: 26 | C27: 1993/07/12 | D27: 2 | E27: 45411 | F27: 3410420 | G27: 5718300 | I27: 1
B28: 27 | C28: 1994/05/31 | D28: 1 | E28: 45544 | F28: 3083340 | G28: 4046360 | I28: 1
B29: 28 | C29: 1986/10/08 | D29: 1 | E29: 44984 | F29: 6641320 | G29: 545870 | I29: 1 | J29: 45992 | K29: 18789790
B30: 29 | C30: 2001/12/07 | D30: 2 | E30: 43899 | F30: 3250000 | G30: 18912330 | I30: 1
B31: 30 | C31: 1993/02/13 | D31: 2 | E31: 43915 | F31: 4031580 | G31: 23283760 | I31: 1
B32: 31 | C32: 1973/01/20 | D32: 1 | E32: 37922 | F32: 7795250 | G32: 114216440 | I32: 1 | J32: 40674
B33: 32 | C33: 1980/05/21 | D33: 1 | E33: 41155 | F33: 5878380 | G33: 78399880 | I33: 1
B34: 33 | C34: 1980/10/05 | D34: 2 | E34: 40658 | F34: 4546100 | G34: 66821450 | I34: 1
B35: 34 | C35: 2000/04/19 | D35: 2 | E35: 43549 | F35: 3650000 | G35: 24740000 | I35: 1
B36: 35 | C36: 2000/08/12 | D36: 2 | E36: 43549 | F36: 3650000 | G36: 24740000 | I36: 1
B37: 36 | C37: 2001/06/26 | D37: 2 | E37: 43880 | F37: 2792970 | G37: 16398180 | I37: 1
B38: 37 | C38: 2002/05/30 | D38: 2 | E38: 44179 | F38: 2783310 | G38: 14061440 | I38: 1
B39: 38 | C39: 1972/10/28 | D39: 1 | E39: 44279 | F39: 5427350 | G39: 25932330 | I39: 1
B40: 39 | C40: 1978/06/28 | D40: 2 | E40: 44279 | F40: 3959600 | G40: 18919300 | I40: 1
...

Sheet (2-3) 퇴직자 및 DC전환자 명부
A1: 참고사항 | B1: 사원번호 | C1: 생년월일 | D1: 성별 (1:남자, 2:여자) | E1: 입사일자 | F1: 퇴직일 또는 DC전환일 | G1: 퇴직금 또는 DC전환금 | H1: 종업원 구분 (1:직원, 3:임원, 4:계약직) | I1: 사유 (1: 퇴직, 2: DC전환) | J1: 제도구분 (1,2,3)
A2: ※ 양식 변경 절대 불가 | B2: 751 | C2: 1988/02/25 | D2: 2 | E2: 40129 | F2: 2025/01/31 | G2: 66291490 | I2: 퇴직금정산
A3: 해당 회계연도에 발생한 사항 입력 | B3: 752 | C3: 1982/06/25 | D3: 1 | E3: 40452 | F3: 2025/01/31 | G3: 33810340 | I3: 퇴직금정산
A4: 퇴직금(DC전환금)이 0인 경우에도 입력 | B4: 753 | C4: 1985/07/09 | D4: 1 | E4: 41214 | F4: 2025/01/31 | G4: 69126270 | I4: 퇴직금정산
A5: 전액 확정기여형(DC)을 가입한 퇴직자 제외 | B5: 754 | C5: 1991/10/10 | D5: 2 | E5: 44242 | F5: 2025/01/31 | G5: 23483530 | I5: 퇴직금정산
B6: 755 | C6: 1990/10/29 | D6: 1 | E6: 44732 | F6: 2025/01/31 | G6: 14264030 | I6: 퇴직금정산
B7: 756 | C7: 1992/08/12 | D7: 1 | E7: 43885 | F7: 2025/01/31 | G7: 15862910 | I7: 퇴직금정산
B8: 757 | C8: 1994/06/01 | D8: 2 | E8: 45112 | F8: 2025/01/31 | G8: 7984600 | I8: 퇴직금정산
B9: 758 | C9: 1976/01/01 | D9: 1 | E9: 40518 | F9: 2025/01/31 | G9: 136870140 | I9: 퇴직금정산
B10: 759 | C10: 1984/01/30 | D10: 1 | E10: 44298 | F10: 2025/01/31 | G10: 32841920 | I10: 퇴직금정산
B11: 760 | C11: 1987/06/28 | D11: 1 | E11: 44690 | F11: 2025/01/31 | G11: 20152640 | I11: 퇴직금정산
B12: 761 | C12: 1990/11/28 | D12: 2 | E12: 44601 | F12: 2025/01/30 | G12: 14018690 | I12: 퇴직금정산
B13: 762 | C13: 1972/06/15 | D13: 2 | E13: 45320 | F13: 2025/01/28 | G13: 2648390 | I13: 퇴직금정산
B14: 763 | C14: 1988/05/10 | D14: 1 | E14: 44494 | F14: 2025/01/20 | G14: 14560870 | I14: 퇴직금정산
B15: 764 | C15: 1989/01/27 | D15: 1 | E15: 45166 | F15: 2025/01/20 | G15: 11549020 | I15: 퇴직금정산
B16: 765 | C16: 1974/11/20 | D16: 2 | E16: 45306 | F16: 2025/01/14 | G16: 3320400 | I16: 퇴직금정산
B17: 766 | C17: 1983/11/02 | D17: 2 | E17: 44606 | F17: 2025/01/11 | G17: 9358230 | I17: 퇴직금정산
... B478: 1227 | C478: 1987/10/15 | D478: 2 | E478: 41214 | F478: 2025/12/15 | G478: 83856550 | I478: 퇴직금정산

Sheet (2-4) 추가 명부
A1: 참고사항 | B1: 사원번호 | C1: 생년월일 | D1: 성별 (1:남자, 2:여자) | E1: 입사일자 | F1: 기준급여 | G1: 사유발생일 시점 발생금액 | H1: 종업원 구분 (1:직원, 3:임원, 4:계약직) | I1: 중간정산기준일 | J1: 사유 (1:관계사전입, 2:관계사전출, 3:사업결합, 4:사업처분 5:기타장기종업원) | K1: 사유발생일
A2: ※ 양식 변경 절대 불가 | B2: 1228 | C2: 1988/11/15 | D2: 1 | E2: 44116 | F2: 2025/05/31 | G2: 24412870
A3: 아래의 사항에 해당하는 경우 입력 | B3: 1229 | C3: 1985/08/21 | D3: 1 | E3: 44200 | F3: 2025/05/31 | G3: 23811270
A4: : 축소, 정산, 사업결합, 사업분할 | B4: 1230 | C4: 1993/03/23 | D4: 2 | E4: 44832 | F4: 2025/05/31 | G4: 11651250
A5: 해당 사유 발생일을 기준으로 입력 | B5: 1231 | C5: 1989/05/19 | D5: 2 | E5: 44833 | F5: 2025/05/31 | G5: 12049560
A6: 입사일자 | B6: 1232 | C6: 1990/01/07 | D6: 1 | E6: 45390 | F6: 2025/05/31 | G6: 4051370
A7: 최초 입사일자 입력 | B7: 1233 | C7: 1997/08/14 | D7: 1 | E7: 45425 | F7: 2025/05/31 | G7: 3319940
A8: 기준급여
A9: 퇴직금 계산시 사용되는 평균임금
A10: 사유 발생일 기준
A11: 당년도 퇴직금추계액
A12: 사유발생일 현재 퇴직금추계액
A13: (임원, 계약직 필수 입력)
A14: 중간정산기준일
A15: 입사 후 중간정산한 적이 있는 경우 반드시 입력
A16: 중간정산 당일로 입력
