Workbook

Sheet feedback_send
C3: ='(1-2) 기초자료_퇴직급여 '!D12&" feedback" -> feedback
C6: (1_1) 기초자료_퇴직급여 시트에서 다음 사항 누락되었습니다. 기재 부탁드립니다.
B8: 1 | C8: 사외적립자산
B10: =B8+1 -> 2 | C10: 국민연금전환금
B12: =B10+1 -> 3 | C12: 정년
B14: =B12+1 -> 4 | C14: 1년미만 근무기간 처리방법
B16: =B14+1 -> 5 | C16: 임금상승률
B18: 6 | C18: 채권등급
C22: (2-2) 재직자 명부 시트에서 다음사항 확인 부탁드립니다.
B24: 1 | C24: 빈칸 있는 곳 확인하여 채워 달라고 전달.
B26: 2 | C26: 다음 재직자 분들은 평균임금이 1,000,000원 미만입니다.
C27: 회사 정책상 그러 할 수 있으나, 확인 부탁드립니다.
C29: 사원번호 | D29: 평균임금
D30: =VLOOKUP(C30,'(2-2) 재직자 명부'!$B$2:$J$164,5,0) -> #N/A
D31: =VLOOKUP(C31,'(2-2) 재직자 명부'!$B$2:$J$164,5,0) -> #N/A
D32: =VLOOKUP(C32,'(2-2) 재직자 명부'!$B$2:$J$164,5,0) -> #N/A
D33: =VLOOKUP(C33,'(2-2) 재직자 명부'!$B$2:$J$164,5,0) -> #N/A
D34: =VLOOKUP(C34,'(2-2) 재직자 명부'!$B$2:$J$164,5,0) -> #N/A
B36: 3 | C36: 다음 재직자 분들의 명부 추계액과 gia산출 추계액 값 차이가 큽니다.
C37: 회사 정책상 그러 할 수 있으나, 확인 부탁드립니다.
C38: (중간정산일자 누락, 입사일자 오류, 적용배수 오류)
C40: 사원번호 | D40: 당년도퇴직금추계액 | E40: 차년도 퇴직금추계액
D41: =VLOOKUP(C41,'(2-2) 재직자 명부'!$B$2:$L$218,6,0) -> #N/A | E41: =VLOOKUP(C41,'(2-2) 재직자 명부'!$B$2:$L$218,7,0) -> #N/A

Sheet 재직자명부_시스템input
A1: 사원번호 | B1: 성명 | C1: 생년월일 | D1: 성별 (1:남자, 2:여자) | E1: 입사일자 | F1: 기준급여 | G1: 당년도 퇴직금추계액 | H1: 차년도 퇴직금추계액 | I1: 직종구분 (1,2:직원, 3:임원, 4:계약직) | J1: 중간정산기준일 | K1: 중간정산액 | L1: 적용제도번호 | M1: 직급 | N1: 추가CODE1 | O1: 추가CODE2 | P1: 추가CODE3 | Q1: 추가CODE4 | R1: 추가CODE5 | S1: 추가CODE6 | T1: 추가CODE7 | U1: 추가CODE8 | V1: 추가CODE9 | W1: 추가CODE10 | X1: 추가CHAR1 (가입여부 Y/N) | Y1: 추가CHAR2 (1:축소, 2:청산, 3:사업결합, 4:청산_중간정산) | Z1: 추가CHAR3 | AA1: 추가CHAR4 | AB1: 추가CHAR5 | AC1: 추가CHAR6 | AD1: 추가CHAR7 | AE1: 추가CHAR8 | AF1: 추가CHAR9 | AG1: 추가CHAR10 | AH1: 추가NUMBER1 추가지급률
A2: =IF('(2-2) 재직자 명부'!B2="","",'(2-2) 재직자 명부'!B2) -> 1 | B2: =A2 -> 1 | C2: =IF('(2-2) 재직자 명부'!C2="","",'(2-2) 재직자 명부'!C2) -> 19670702 | D2: =IF('(2-2) 재직자 명부'!D2="","",'(2-2) 재직자 명부'!D2) -> 1 | E2: =IF('(2-2) 재직자 명부'!E2="","",'(2-2) 재직자 명부'!E2) -> 36770 | F2: =IF('(2-2) 재직자 명부'!F2="","",'(2-2) 재직자 명부'!F2) -> 47270000 | G2: =IFERROR(IF('(2-2) 재직자 명부'!G2="",VLOOKUP(A2,추계액검증!$C:$V,추계액검증!#REF!,0),'(2-2) 재직자 명부'!G2),"") -> 3.59252e+09 | H2: =IFERROR(IF('(2-2) 재직자 명부'!H2="",VLOOKUP(A2,추계액검증!$C:$V,추계액검증!$T$4,0),'(2-2) 재직자 명부'!H2),"") -> 3.73433e+09 | I2: =IF('(2-2) 재직자 명부'!I2="","",'(2-2) 재직자 명부'!I2) -> 3 | J2: =IF('(2-2) 재직자 명부'!J2="","",'(2-2) 재직자 명부'!J2) | K2: =IF('(2-2) 재직자 명부'!K2="","",'(2-2) 재직자 명부'!K2) | L2: =IF('(2-2) 재직자 명부'!L2="","",'(2-2) 재직자 명부'!L2)
A3: =IF('(2-2) 재직자 명부'!B3="","",'(2-2) 재직자 명부'!B3) -> 2 | B3: =A3 -> 2 | C3: =IF('(2-2) 재직자 명부'!C3="","",'(2-2) 재직자 명부'!C3) -> 19691224 | D3: =IF('(2-2) 재직자 명부'!D3="","",'(2-2) 재직자 명부'!D3) -> 1 | E3: =IF('(2-2) 재직자 명부'!E3="","",'(2-2) 재직자 명부'!E3) -> 39083 | F3: =IF('(2-2) 재직자 명부'!F3="","",'(2-2) 재직자 명부'!F3) -> 77830000 | G3: =IFERROR(IF('(2-2) 재직자 명부'!G3="",VLOOKUP(A3,추계액검증!$C:$V,추계액검증!#REF!,0),'(2-2) 재직자 명부'!G3),"") -> 4436310000 | H3: =IFERROR(IF('(2-2) 재직자 명부'!H3="",VLOOKUP(A3,추계액검증!$C:$V,추계액검증!$T$4,0),'(2-2) 재직자 명부'!H3),"") -> 4669800000 | I3: =IF('(2-2) 재직자 명부'!I3="","",'(2-2) 재직자 명부'!I3) -> 3 | J3: =IF('(2-2) 재직자 명부'!J3="","",'(2-2) 재직자 명부'!J3) | K3: =IF('(2-2) 재직자 명부'!K3="","",'(2-2) 재직자 명부'!K3)
A4: =IF('(2-2) 재직자 명부'!B4="","",'(2-2) 재직자 명부'!B4) -> 3 | B4: =A4 -> 3 | C4: =IF('(2-2) 재직자 명부'!C4="","",'(2-2) 재직자 명부'!C4) -> 19580912 | D4: =IF('(2-2) 재직자 명부'!D4="","",'(2-2) 재직자 명부'!D4) -> 1 | E4: =IF('(2-2) 재직자 명부'!E4="","",'(2-2) 재직자 명부'!E4) -> 42811 | F4: =IF('(2-2) 재직자 명부'!F4="","",'(2-2) 재직자 명부'!F4) -> 23630000 | G4: =IFERROR(IF('(2-2) 재직자 명부'!G4="",VLOOKUP(A4,추계액검증!$C:$V,추계액검증!#REF!,0),'(2-2) 재직자 명부'!G4),"") -> 638010000 | H4: =IFERROR(IF('(2-2) 재직자 명부'!H4="",VLOOKUP(A4,추계액검증!$C:$V,추계액검증!$T$4,0),'(2-2) 재직자 명부'!H4),"") -> 708900000 | I4: =IF('(2-2) 재직자 명부'!I4="","",'(2-2) 재직자 명부'!I4) -> 3 | J4: =IF('(2-2) 재직자 명부'!J4="","",'(2-2) 재직자 명부'!J4) | K4: =IF('(2-2) 재직자 명부'!K4="","",'(2-2) 재직자 명부'!K4)
A5: =IF('(2-2) 재직자 명부'!B5="","",'(2-2) 재직자 명부'!B5) -> 4 | B5: =A5 -> 4 | C5: =IF('(2-2) 재직자 명부'!C5="","",'(2-2) 재직자 명부'!C5) -> 19681023 | D5: =IF('(2-2) 재직자 명부'!D5="","",'(2-2) 재직자 명부'!D5) -> 1 | E5: =IF('(2-2) 재직자 명부'!E5="","",'(2-2) 재직자 명부'!E5) -> 44927 | F5: =IF('(2-2) 재직자 명부'!F5="","",'(2-2) 재직자 명부'!F5) -> 12100000 | G5: =IFERROR(IF('(2-2) 재직자 명부'!G5="",VLOOKUP(A5,추계액검증!$C:$V,추계액검증!#REF!,0),'(2-2) 재직자 명부'!G5),"") -> 108900000 | H5: =IFERROR(IF('(2-2) 재직자 명부'!H5="",VLOOKUP(A5,추계액검증!$C:$V,추계액검증!$T$4,0),'(2-2) 재직자 명부'!H5),"") -> 145200000 | I5: =IF('(2-2) 재직자 명부'!I5="","",'(2-2) 재직자 명부'!I5) -> 3 | J5: =IF('(2-2) 재직자 명부'!J5="","",'(2-2) 재직자 명부'!J5) | K5: =IF('(2-2) 재직자 명부'!K5="","",'(2-2) 재직자 명부'!K5)
A6: =IF('(2-2) 재직자 명부'!B6="","",'(2-2) 재직자 명부'!B6) -> 5 | B6: =A6 -> 5 | C6: =IF('(2-2) 재직자 명부'!C6="","",'(2-2) 재직자 명부'!C6) -> 19641227 | D6: =IF('(2-2) 재직자 명부'!D6="","",'(2-2) 재직자 명부'!D6) -> 1 | E6: =IF('(2-2) 재직자 명부'!E6="","",'(2-2) 재직자 명부'!E6) -> 45292 | F6: =IF('(2-2) 재직자 명부'!F6="","",'(2-2) 재직자 명부'!F6) -> 15900000 | G6: =IFERROR(IF('(2-2) 재직자 명부'!G6="",VLOOKUP(A6,추계액검증!$C:$V,추계액검증!#REF!,0),'(2-2) 재직자 명부'!G6),"") -> 95400000 | H6: =IFERROR(IF('(2-2) 재직자 명부'!H6="",VLOOKUP(A6,추계액검증!$C:$V,추계액검증!$T$4,0),'(2-2) 재직자 명부'!H6),"") -> 143100000 | I6: =IF('(2-2) 재직자 명부'!I6="","",'(2-2) 재직자 명부'!I6) -> 3 | J6: =IF('(2-2) 재직자 명부'!J6="","",'(2-2) 재직자 명부'!J6) | K6: =IF('(2-2) 재직자 명부'!K6="","",'(2-2) 재직자 명부'!K6)
A7: =IF('(2-2) 재직자 명부'!B7="","",'(2-2) 재직자 명부'!B7) -> 6 | B7: =A7 -> 6 | C7: =IF('(2-2) 재직자 명부'!C7="","",'(2-2) 재직자 명부'!C7) -> 19930729 | D7: =IF('(2-2) 재직자 명부'!D7="","",'(2-2) 재직자 명부'!D7) -> 1 | E7: =IF('(2-2) 재직자 명부'!E7="","",'(2-2) 재직자 명부'!E7) -> 43435 | F7: =IF('(2-2) 재직자 명부'!F7="","",'(2-2) 재직자 명부'!F7) -> 4203350 | G7: =IFERROR(IF('(2-2) 재직자 명부'!G7="",VLOOKUP(A7,추계액검증!$C:$V,추계액검증!#REF!,0),'(2-2) 재직자 명부'!G7),"") -> 29773730 | H7: =IFERROR(IF('(2-2) 재직자 명부'!H7="",VLOOKUP(A7,추계액검증!$C:$V,추계액검증!$T$4,0),'(2-2) 재직자 명부'!H7),"") | I7: =IF('(2-2) 재직자 명부'!I7="","",'(2-2) 재직자 명부'!I7) -> 1 | J7: =IF('(2-2) 재직자 명부'!J7="","",'(2-2) 재직자 명부'!J7) | K7: =IF('(2-2) 재직자 명부'!K7="","",'(2-2) 재직자 명부'!K7)
A8: =IF('(2-2) 재직자 명부'!B8="","",'(2-2) 재직자 명부'!B8) -> 7 | B8: =A8 -> 7 | C8: =IF('(2-2) 재직자 명부'!C8="","",'(2-2) 재직자 명부'!C8) -> 19730205 | D8: =IF('(2-2) 재직자 명부'!D8="","",'(2-2) 재직자 명부'!D8) -> 1 | E8: =IF('(2-2) 재직자 명부'!E8="","",'(2-2) 재직자 명부'!E8) -> 43282 | F8: =IF('(2-2) 재직자 명부'!F8="","",'(2-2) 재직자 명부'!F8) -> 6465480 | G8: =IFERROR(IF('(2-2) 재직자 명부'!G8="",VLOOKUP(A8,추계액검증!$C:$V,추계액검증!#REF!,0),'(2-2) 재직자 명부'!G8),"") -> 48491100 | H8: =IFERROR(IF('(2-2) 재직자 명부'!H8="",VLOOKUP(A8,추계액검증!$C:$V,추계액검증!$T$4,0),'(2-2) 재직자 명부'!H8),"") | I8: =IF('(2-2) 재직자 명부'!I8="","",'(2-2) 재직자 명부'!I8) -> 1 | J8: =IF('(2-2) 재직자 명부'!J8="","",'(2-2) 재직자 명부'!J8) | K8: =IF('(2-2) 재직자 명부'!K8="","",'(2-2) 재직자 명부'!K8)
A9: =IF('(2-2) 재직자 명부'!B9="","",'(2-2) 재직자 명부'!B9) -> 8 | B9: =A9 -> 8 | C9: =IF('(2-2) 재직자 명부'!C9="","",'(2-2) 재직자 명부'!C9) -> 19860403 | D9: =IF('(2-2) 재직자 명부'!D9="","",'(2-2) 재직자 명부'!D9) -> 1 | E9: =IF('(2-2) 재직자 명부'!E9="","",'(2-2) 재직자 명부'!E9) -> 43997 | F9: =IF('(2-2) 재직자 명부'!F9="","",'(2-2) 재직자 명부'!F9) -> 4780400 | G9: =IFERROR(IF('(2-2) 재직자 명부'!G9="",VLOOKUP(A9,추계액검증!$C:$V,추계액검증!#REF!,0),'(2-2) 재직자 명부'!G9),"") -> 26514850 | H9: =IFERROR(IF('(2-2) 재직자 명부'!H9="",VLOOKUP(A9,추계액검증!$C:$V,추계액검증!$T$4,0),'(2-2) 재직자 명부'!H9),"") | I9: =IF('(2-2) 재직자 명부'!I9="","",'(2-2) 재직자 명부'!I9) -> 1 | J9: =IF('(2-2) 재직자 명부'!J9="","",'(2-2) 재직자 명부'!J9) | K9: =IF('(2-2) 재직자 명부'!K9="","",'(2-2) 재직자 명부'!K9)
A10: =IF('(2-2) 재직자 명부'!B10="","",'(2-2) 재직자 명부'!B10) -> 9 | B10: =A10 -> 9 | C10: =IF('(2-2) 재직자 명부'!C10="","",'(2-2) 재직자 명부'!C10) -> 19720823 | D10: =IF('(2-2) 재직자 명부'!D10="","",'(2-2) 재직자 명부'!D10) -> 1 | E10: =IF('(2-2) 재직자 명부'!E10="","",'(2-2) 재직자 명부'!E10) -> 35202 | F10: =IF('(2-2) 재직자 명부'!F10="","",'(2-2) 재직자 명부'!F10) -> 7846620 | G10: =IFERROR(IF('(2-2) 재직자 명부'!G10="",VLOOKUP(A10,추계액검증!$C:$V,추계액검증!#REF!,0),'(2-2) 재직자 명부'!G10),"") -> 232451640 | H10: =IFERROR(IF('(2-2) 재직자 명부'!H10="",VLOOKUP(A10,추계액검증!$C:$V,추계액검증!$T$4,0),'(2-2) 재직자 명부'!H10),"") | I10: =IF('(2-2) 재직자 명부'!I10="","",'(2-2) 재직자 명부'!I10) -> 1 | J10: =IF('(2-2) 재직자 명부'!J10="","",'(2-2) 재직자 명부'!J10) | K10: =IF('(2-2) 재직자 명부'!K10="","",'(2-2) 재직자 명부'!K10)
A11: =IF('(2-2) 재직자 명부'!B11="","",'(2-2) 재직자 명부'!B11) -> 10 | B11: =A11 -> 10 | C11: =IF('(2-2) 재직자 명부'!C11="","",'(2-2) 재직자 명부'!C11) -> 19760126 | D11: =IF('(2-2) 재직자 명부'!D11="","",'(2-2) 재직자 명부'!D11) -> 1 | E11: =IF('(2-2) 재직자 명부'!E11="","",'(2-2) 재직자 명부'!E11) -> 36557 | F11: =IF('(2-2) 재직자 명부'!F11="","",'(2-2) 재직자 명부'!F11) -> 6783220 | G11: =IFERROR(IF('(2-2) 재직자 명부'!G11="",VLOOKUP(A11,추계액검증!$C:$V,추계액검증!#REF!,0),'(2-2) 재직자 명부'!G11),"") -> 175798460 | H11: =IFERROR(IF('(2-2) 재직자 명부'!H11="",VLOOKUP(A11,추계액검증!$C:$V,추계액검증!$T$4,0),'(2-2) 재직자 명부'!H11),"") | I11: =IF('(2-2) 재직자 명부'!I11="","",'(2-2) 재직자 명부'!I11) -> 1 | J11: =IF('(2-2) 재직자 명부'!J11="","",'(2-2) 재직자 명부'!J11) | K11: =IF('(2-2) 재직자 명부'!K11="","",'(2-2) 재직자 명부'!K11)
A12: =IF('(2-2) 재직자 명부'!B12="","",'(2-2) 재직자 명부'!B12) -> 11 | B12: =A12 -> 11 | C12: =IF('(2-2) 재직자 명부'!C12="","",'(2-2) 재직자 명부'!C12) -> 19670727 | D12: =IF('(2-2) 재직자 명부'!D12="","",'(2-2) 재직자 명부'!D12) -> 1 | E12: =IF('(2-2) 재직자 명부'!E12="","",'(2-2) 재직자 명부'!E12) -> 36825 | F12: =IF('(2-2) 재직자 명부'!F12="","",'(2-2) 재직자 명부'!F12) -> 6564940 | G12: =IFERROR(IF('(2-2) 재직자 명부'!G12="",VLOOKUP(A12,추계액검증!$C:$V,추계액검증!#REF!,0),'(2-2) 재직자 명부'!G12),"") -> 165325580 | H12: =IFERROR(IF('(2-2) 재직자 명부'!H12="",VLOOKUP(A12,추계액검증!$C:$V,추계액검증!$T$4,0),'(2-2) 재직자 명부'!H12),"") | I12: =IF('(2-2) 재직자 명부'!I12="","",'(2-2) 재직자 명부'!I12) -> 1 | J12: =IF('(2-2) 재직자 명부'!J12="","",'(2-2) 재직자 명부'!J12) | K12: =IF('(2-2) 재직자 명부'!K12="","",'(2-2) 재직자 명부'!K12)
A13: =IF('(2-2) 재직자 명부'!B13="","",'(2-2) 재직자 명부'!B13) -> 12 | B13: =A13 -> 12 | C13: =IF('(2-2) 재직자 명부'!C13="","",'(2-2) 재직자 명부'!C13) -> 19800220 | D13: =IF('(2-2) 재직자 명부'!D13="","",'(2-2) 재직자 명부'!D13) -> 1 | E13: =IF('(2-2) 재직자 명부'!E13="","",'(2-2) 재직자 명부'!E13) -> 37902 | F13: =IF('(2-2) 재직자 명부'!F13="","",'(2-2) 재직자 명부'!F13) -> 6476000 | G13: =IFERROR(IF('(2-2) 재직자 명부'!G13="",VLOOKUP(A13,추계액검증!$C:$V,추계액검증!#REF!,0),'(2-2) 재직자 명부'!G13),"") -> 143977160 | H13: =IFERROR(IF('(2-2) 재직자 명부'!H13="",VLOOKUP(A13,추계액검증!$C:$V,추계액검증!$T$4,0),'(2-2) 재직자 명부'!H13),"") | I13: =IF('(2-2) 재직자 명부'!I13="","",'(2-2) 재직자 명부'!I13) -> 1 | J13: =IF('(2-2) 재직자 명부'!J13="","",'(2-2) 재직자 명부'!J13) | K13: =IF('(2-2) 재직자 명부'!K13="","",'(2-2) 재직자 명부'!K13)
A14: =IF('(2-2) 재직자 명부'!B14="","",'(2-2) 재직자 명부'!B14) -> 13 | B14: =A14 -> 13 | C14: =IF('(2-2) 재직자 명부'!C14="","",'(2-2) 재직자 명부'!C14) -> 19811219 | D14: =IF('(2-2) 재직자 명부'!D14="","",'(2-2) 재직자 명부'!D14) -> 1 | E14: =IF('(2-2) 재직자 명부'!E14="","",'(2-2) 재직자 명부'!E14) -> 39143 | F14: =IF('(2-2) 재직자 명부'!F14="","",'(2-2) 재직자 명부'!F14) -> 6594780 | G14: =IFERROR(IF('(2-2) 재직자 명부'!G14="",VLOOKUP(A14,추계액검증!$C:$V,추계액검증!#REF!,0),'(2-2) 재직자 명부'!G14),"") -> 124194170 | H14: =IFERROR(IF('(2-2) 재직자 명부'!H14="",VLOOKUP(A14,추계액검증!$C:$V,추계액검증!$T$4,0),'(2-2) 재직자 명부'!H14),"") | I14: =IF('(2-2) 재직자 명부'!I14="","",'(2-2) 재직자 명부'!I14) -> 1 | J14: =IF('(2-2) 재직자 명부'!J14="","",'(2-2) 재직자 명부'!J14) | K14: =IF('(2-2) 재직자 명부'!K14="","",'(2-2) 재직자 명부'!K14)
... A219: =IF('(2-2) 재직자 명부'!B219="","",'(2-2) 재직자 명부'!B219) | B219: =A219 | C219: =IF('(2-2) 재직자 명부'!C219="","",'(2-2) 재직자 명부'!C219) | D219: =IF('(2-2) 재직자 명부'!D219="","",'(2-2) 재직자 명부'!D219) | E219: =IF('(2-2) 재직자 명부'!E219="","",'(2-2) 재직자 명부'!E219) | F219: =IF('(2-2) 재직자 명부'!F219="","",'(2-2) 재직자 명부'!F219) | G219: =IFERROR(IF('(2-2) 재직자 명부'!G219="",VLOOKUP(A219,추계액검증!$C:$V,추계액검증!#REF!,0),'(2-2) 재직자 명부'!G219),"") | H219: =IFERROR(IF('(2-2) 재직자 명부'!H219="",VLOOKUP(A219,추계액검증!$C:$V,추계액검증!$T$4,0),'(2-2) 재직자 명부'!H219),"") | I219: =IF('(2-2) 재직자 명부'!I219="","",'(2-2) 재직자 명부'!I219) | J219: =IF('(2-2) 재직자 명부'!J219="","",'(2-2) 재직자 명부'!J219) | K219: =IF('(2-2) 재직자 명부'!K219="","",'(2-2) 재직자 명부'!K219)
B220: =A220 -> 0 | C220: =IF('(2-2) 재직자 명부'!C220="","",'(2-2) 재직자 명부'!C220) | D220: =IF('(2-2) 재직자 명부'!D220="","",'(2-2) 재직자 명부'!D220) | E220: =IF('(2-2) 재직자 명부'!E220="","",'(2-2) 재직자 명부'!E220) | F220: =IF('(2-2) 재직자 명부'!F220="","",'(2-2) 재직자 명부'!F220) | G220: =IFERROR(IF('(2-2) 재직자 명부'!G220="",VLOOKUP(A220,추계액검증!$C:$V,추계액검증!#REF!,0),'(2-2) 재직자 명부'!G220),"") | H220: =IFERROR(IF('(2-2) 재직자 명부'!H220="",VLOOKUP(A220,추계액검증!$C:$V,추계액검증!$T$4,0),'(2-2) 재직자 명부'!H220),"") | I220: =IF('(2-2) 재직자 명부'!I220="","",'(2-2) 재직자 명부'!I220) | J220: =IF('(2-2) 재직자 명부'!J220="","",'(2-2) 재직자 명부'!J220) | K220: =IF('(2-2) 재직자 명부'!K220="","",'(2-2) 재직자 명부'!K220)
B221: =A221 -> 0 | C221: =IF('(2-2) 재직자 명부'!C221="","",'(2-2) 재직자 명부'!C221) | D221: =IF('(2-2) 재직자 명부'!D221="","",'(2-2) 재직자 명부'!D221) | E221: =IF('(2-2) 재직자 명부'!E221="","",'(2-2) 재직자 명부'!E221) | F221: =IF('(2-2) 재직자 명부'!F221="","",'(2-2) 재직자 명부'!F221) | G221: =IFERROR(IF('(2-2) 재직자 명부'!G221="",VLOOKUP(A221,추계액검증!$C:$V,추계액검증!#REF!,0),'(2-2) 재직자 명부'!G221),"") | H221: =IFERROR(IF('(2-2) 재직자 명부'!H221="",VLOOKUP(A221,추계액검증!$C:$V,추계액검증!$T$4,0),'(2-2) 재직자 명부'!H221),"") | I221: =IF('(2-2) 재직자 명부'!I221="","",'(2-2) 재직자 명부'!I221) | J221: =IF('(2-2) 재직자 명부'!J221="","",'(2-2) 재직자 명부'!J221) | K221: =IF('(2-2) 재직자 명부'!K221="","",'(2-2) 재직자 명부'!K221)
B222: =A222 -> 0 | C222: =IF('(2-2) 재직자 명부'!C222="","",'(2-2) 재직자 명부'!C222) | D222: =IF('(2-2) 재직자 명부'!D222="","",'(2-2) 재직자 명부'!D222) | E222: =IF('(2-2) 재직자 명부'!E222="","",'(2-2) 재직자 명부'!E222) | F222: =IF('(2-2) 재직자 명부'!F222="","",'(2-2) 재직자 명부'!F222) | G222: =IFERROR(IF('(2-2) 재직자 명부'!G222="",VLOOKUP(A222,추계액검증!$C:$V,추계액검증!#REF!,0),'(2-2) 재직자 명부'!G222),"") | H222: =IFERROR(IF('(2-2) 재직자 명부'!H222="",VLOOKUP(A222,추계액검증!$C:$V,추계액검증!$T$4,0),'(2-2) 재직자 명부'!H222),"") | I222: =IF('(2-2) 재직자 명부'!I222="","",'(2-2) 재직자 명부'!I222) | J222: =IF('(2-2) 재직자 명부'!J222="","",'(2-2) 재직자 명부'!J222) | K222: =IF('(2-2) 재직자 명부'!K222="","",'(2-2) 재직자 명부'!K222)
B223: =A223 -> 0 | C223: =IF('(2-2) 재직자 명부'!C223="","",'(2-2) 재직자 명부'!C223) | D223: =IF('(2-2) 재직자 명부'!D223="","",'(2-2) 재직자 명부'!D223) | E223: =IF('(2-2) 재직자 명부'!E223="","",'(2-2) 재직자 명부'!E223) | F223: =IF('(2-2) 재직자 명부'!F223="","",'(2-2) 재직자 명부'!F223) | G223: =IFERROR(IF('(2-2) 재직자 명부'!G223="",VLOOKUP(A223,추계액검증!$C:$V,추계액검증!#REF!,0),'(2-2) 재직자 명부'!G223),"") | H223: =IFERROR(IF('(2-2) 재직자 명부'!H223="",VLOOKUP(A223,추계액검증!$C:$V,추계액검증!$T$4,0),'(2-2) 재직자 명부'!H223),"") | I223: =IF('(2-2) 재직자 명부'!I223="","",'(2-2) 재직자 명부'!I223) | J223: =IF('(2-2) 재직자 명부'!J223="","",'(2-2) 재직자 명부'!J223) | K223: =IF('(2-2) 재직자 명부'!K223="","",'(2-2) 재직자 명부'!K223)
B224: =A224 -> 0 | C224: =IF('(2-2) 재직자 명부'!C224="","",'(2-2) 재직자 명부'!C224) | D224: =IF('(2-2) 재직자 명부'!D224="","",'(2-2) 재직자 명부'!D224) | E224: =IF('(2-2) 재직자 명부'!E224="","",'(2-2) 재직자 명부'!E224) | F224: =IF('(2-2) 재직자 명부'!F224="","",'(2-2) 재직자 명부'!F224) | G224: =IFERROR(IF('(2-2) 재직자 명부'!G224="",VLOOKUP(A224,추계액검증!$C:$V,추계액검증!#REF!,0),'(2-2) 재직자 명부'!G224),"") | H224: =IFERROR(IF('(2-2) 재직자 명부'!H224="",VLOOKUP(A224,추계액검증!$C:$V,추계액검증!$T$4,0),'(2-2) 재직자 명부'!H224),"") | I224: =IF('(2-2) 재직자 명부'!I224="","",'(2-2) 재직자 명부'!I224) | J224: =IF('(2-2) 재직자 명부'!J224="","",'(2-2) 재직자 명부'!J224) | K224: =IF('(2-2) 재직자 명부'!K224="","",'(2-2) 재직자 명부'!K224)
B225: =A225 -> 0 | C225: =IF('(2-2) 재직자 명부'!C225="","",'(2-2) 재직자 명부'!C225) | D225: =IF('(2-2) 재직자 명부'!D225="","",'(2-2) 재직자 명부'!D225) | E225: =IF('(2-2) 재직자 명부'!E225="","",'(2-2) 재직자 명부'!E225) | F225: =IF('(2-2) 재직자 명부'!F225="","",'(2-2) 재직자 명부'!F225) | G225: =IFERROR(IF('(2-2) 재직자 명부'!G225="",VLOOKUP(A225,추계액검증!$C:$V,추계액검증!#REF!,0),'(2-2) 재직자 명부'!G225),"") | H225: =IFERROR(IF('(2-2) 재직자 명부'!H225="",VLOOKUP(A225,추계액검증!$C:$V,추계액검증!$T$4,0),'(2-2) 재직자 명부'!H225),"") | I225: =IF('(2-2) 재직자 명부'!I225="","",'(2-2) 재직자 명부'!I225) | J225: =IF('(2-2) 재직자 명부'!J225="","",'(2-2) 재직자 명부'!J225) | K225: =IF('(2-2) 재직자 명부'!K225="","",'(2-2) 재직자 명부'!K225)
B226: =A226 -> 0 | C226: =IF('(2-2) 재직자 명부'!C226="","",'(2-2) 재직자 명부'!C226) | D226: =IF('(2-2) 재직자 명부'!D226="","",'(2-2) 재직자 명부'!D226) | E226: =IF('(2-2) 재직자 명부'!E226="","",'(2-2) 재직자 명부'!E226) | F226: =IF('(2-2) 재직자 명부'!F226="","",'(2-2) 재직자 명부'!F226) | G226: =IFERROR(IF('(2-2) 재직자 명부'!G226="",VLOOKUP(A226,추계액검증!$C:$V,추계액검증!#REF!,0),'(2-2) 재직자 명부'!G226),"") | H226: =IFERROR(IF('(2-2) 재직자 명부'!H226="",VLOOKUP(A226,추계액검증!$C:$V,추계액검증!$T$4,0),'(2-2) 재직자 명부'!H226),"") | I226: =IF('(2-2) 재직자 명부'!I226="","",'(2-2) 재직자 명부'!I226) | J226: =IF('(2-2) 재직자 명부'!J226="","",'(2-2) 재직자 명부'!J226) | K226: =IF('(2-2) 재직자 명부'!K226="","",'(2-2) 재직자 명부'!K226)
B227: =A227 -> 0 | C227: =IF('(2-2) 재직자 명부'!C227="","",'(2-2) 재직자 명부'!C227) | D227: =IF('(2-2) 재직자 명부'!D227="","",'(2-2) 재직자 명부'!D227) | E227: =IF('(2-2) 재직자 명부'!E227="","",'(2-2) 재직자 명부'!E227) | F227: =IF('(2-2) 재직자 명부'!F227="","",'(2-2) 재직자 명부'!F227) | G227: =IFERROR(IF('(2-2) 재직자 명부'!G227="",VLOOKUP(A227,추계액검증!$C:$V,추계액검증!#REF!,0),'(2-2) 재직자 명부'!G227),"") | H227: =IFERROR(IF('(2-2) 재직자 명부'!H227="",VLOOKUP(A227,추계액검증!$C:$V,추계액검증!$T$4,0),'(2-2) 재직자 명부'!H227),"") | I227: =IF('(2-2) 재직자 명부'!I227="","",'(2-2) 재직자 명부'!I227) | J227: =IF('(2-2) 재직자 명부'!J227="","",'(2-2) 재직자 명부'!J227) | K227: =IF('(2-2) 재직자 명부'!K227="","",'(2-2) 재직자 명부'!K227)
B228: =A228 -> 0 | C228: =IF('(2-2) 재직자 명부'!C228="","",'(2-2) 재직자 명부'!C228) | D228: =IF('(2-2) 재직자 명부'!D228="","",'(2-2) 재직자 명부'!D228) | E228: =IF('(2-2) 재직자 명부'!E228="","",'(2-2) 재직자 명부'!E228) | F228: =IF('(2-2) 재직자 명부'!F228="","",'(2-2) 재직자 명부'!F228) | G228: =IFERROR(IF('(2-2) 재직자 명부'!G228="",VLOOKUP(A228,추계액검증!$C:$V,추계액검증!#REF!,0),'(2-2) 재직자 명부'!G228),"") | H228: =IFERROR(IF('(2-2) 재직자 명부'!H228="",VLOOKUP(A228,추계액검증!$C:$V,추계액검증!$T$4,0),'(2-2) 재직자 명부'!H228),"") | I228: =IF('(2-2) 재직자 명부'!I228="","",'(2-2) 재직자 명부'!I228) | J228: =IF('(2-2) 재직자 명부'!J228="","",'(2-2) 재직자 명부'!J228) | K228: =IF('(2-2) 재직자 명부'!K228="","",'(2-2) 재직자 명부'!K228)
B229: =A229 -> 0 | C229: =IF('(2-2) 재직자 명부'!C229="","",'(2-2) 재직자 명부'!C229) | D229: =IF('(2-2) 재직자 명부'!D229="","",'(2-2) 재직자 명부'!D229) | E229: =IF('(2-2) 재직자 명부'!E229="","",'(2-2) 재직자 명부'!E229) | F229: =IF('(2-2) 재직자 명부'!F229="","",'(2-2) 재직자 명부'!F229) | G229: =IFERROR(IF('(2-2) 재직자 명부'!G229="",VLOOKUP(A229,추계액검증!$C:$V,추계액검증!#REF!,0),'(2-2) 재직자 명부'!G229),"") | H229: =IFERROR(IF('(2-2) 재직자 명부'!H229="",VLOOKUP(A229,추계액검증!$C:$V,추계액검증!$T$4,0),'(2-2) 재직자 명부'!H229),"") | I229: =IF('(2-2) 재직자 명부'!I229="","",'(2-2) 재직자 명부'!I229) | J229: =IF('(2-2) 재직자 명부'!J229="","",'(2-2) 재직자 명부'!J229) | K229: =IF('(2-2) 재직자 명부'!K229="","",'(2-2) 재직자 명부'!K229)
B230: =A230 -> 0 | C230: =IF('(2-2) 재직자 명부'!C230="","",'(2-2) 재직자 명부'!C230) | D230: =IF('(2-2) 재직자 명부'!D230="","",'(2-2) 재직자 명부'!D230) | E230: =IF('(2-2) 재직자 명부'!E230="","",'(2-2) 재직자 명부'!E230) | F230: =IF('(2-2) 재직자 명부'!F230="","",'(2-2) 재직자 명부'!F230) | G230: =IFERROR(IF('(2-2) 재직자 명부'!G230="",VLOOKUP(A230,추계액검증!$C:$V,추계액검증!#REF!,0),'(2-2) 재직자 명부'!G230),"") | H230: =IFERROR(IF('(2-2) 재직자 명부'!H230="",VLOOKUP(A230,추계액검증!$C:$V,추계액검증!$T$4,0),'(2-2) 재직자 명부'!H230),"") | I230: =IF('(2-2) 재직자 명부'!I230="","",'(2-2) 재직자 명부'!I230) | J230: =IF('(2-2) 재직자 명부'!J230="","",'(2-2) 재직자 명부'!J230) | K230: =IF('(2-2) 재직자 명부'!K230="","",'(2-2) 재직자 명부'!K230)
B231: =A231 -> 0 | C231: =IF('(2-2) 재직자 명부'!C231="","",'(2-2) 재직자 명부'!C231) | D231: =IF('(2-2) 재직자 명부'!D231="","",'(2-2) 재직자 명부'!D231) | E231: =IF('(2-2) 재직자 명부'!E231="","",'(2-2) 재직자 명부'!E231) | F231: =IF('(2-2) 재직자 명부'!F231="","",'(2-2) 재직자 명부'!F231) | G231: =IFERROR(IF('(2-2) 재직자 명부'!G231="",VLOOKUP(A231,추계액검증!$C:$V,추계액검증!#REF!,0),'(2-2) 재직자 명부'!G231),"") | H231: =IFERROR(IF('(2-2) 재직자 명부'!H231="",VLOOKUP(A231,추계액검증!$C:$V,추계액검증!$T$4,0),'(2-2) 재직자 명부'!H231),"") | I231: =IF('(2-2) 재직자 명부'!I231="","",'(2-2) 재직자 명부'!I231) | J231: =IF('(2-2) 재직자 명부'!J231="","",'(2-2) 재직자 명부'!J231) | K231: =IF('(2-2) 재직자 명부'!K231="","",'(2-2) 재직자 명부'!K231)
... B2484: =A2484 -> 0 | C2484: =IF('(2-2) 재직자 명부'!C2484="","",'(2-2) 재직자 명부'!C2484) | D2484: =IF('(2-2) 재직자 명부'!D2484="","",'(2-2) 재직자 명부'!D2484) | E2484: =IF('(2-2) 재직자 명부'!E2484="","",'(2-2) 재직자 명부'!E2484) | F2484: =IF('(2-2) 재직자 명부'!F2484="","",'(2-2) 재직자 명부'!F2484) | G2484: =IFERROR(IF('(2-2) 재직자 명부'!G2484="",VLOOKUP(A2484,추계액검증!$C:$V,추계액검증!#REF!,0),'(2-2) 재직자 명부'!G2484),"") | H2484: =IFERROR(IF('(2-2) 재직자 명부'!H2484="",VLOOKUP(A2484,추계액검증!$C:$V,추계액검증!$T$4,0),'(2-2) 재직자 명부'!H2484),"") | I2484: =IF('(2-2) 재직자 명부'!I2484="","",'(2-2) 재직자 명부'!I2484) | J2484: =IF('(2-2) 재직자 명부'!J2484="","",'(2-2) 재직자 명부'!J2484) | K2484: =IF('(2-2) 재직자 명부'!K2484="","",'(2-2) 재직자 명부'!K2484)

Sheet 퇴직자명부_시스템input
A1: 사원번호 | B1: 성명 | C1: 생년월일 | D1: 성별 (1:남자, 2:여자) | E1: 입사일자 | F1: 퇴직일자 | G1: 추가CODE1 | H1: 추가CODE2 | I1: 추가CODE3 | J1: 추가CHAR1 | K1: 추가CHAR2 | L1: 추가CHAR3 | M1: 추가NUMBER1 (퇴직금지급액) | N1: 추가NUMBER2 (장기종업원지급액) | O1: 추가NUMBER3 | P1: 추가DATE1 | Q1: 추가DATE2
A2: =IF('(2-4) 퇴직자 및 DC전환자 명부'!B3="","",'(2-4) 퇴직자 및 DC전환자 명부'!B3) -> 156 | B2: =IF(A2="","",A2) -> 156 | C2: =IF('(2-4) 퇴직자 및 DC전환자 명부'!#REF!="","",'(2-4) 퇴직자 및 DC전환자 명부'!#REF!) -> #REF! | D2: =IF('(2-4) 퇴직자 및 DC전환자 명부'!#REF!="","",'(2-4) 퇴직자 및 DC전환자 명부'!#REF!) -> #REF! | E2: =IF('(2-4) 퇴직자 및 DC전환자 명부'!#REF!="","",'(2-4) 퇴직자 및 DC전환자 명부'!#REF!) -> #REF! | F2: =IF('(2-4) 퇴직자 및 DC전환자 명부'!#REF!="","",'(2-4) 퇴직자 및 DC전환자 명부'!#REF!) -> #REF! | M2: =IF('(2-4) 퇴직자 및 DC전환자 명부'!#REF!="","",'(2-4) 퇴직자 및 DC전환자 명부'!#REF!) -> #REF!
A3: =IF('(2-4) 퇴직자 및 DC전환자 명부'!B4="","",'(2-4) 퇴직자 및 DC전환자 명부'!B4) -> 156 | B3: =IF(A3="","",A3) -> 156 | C3: =IF('(2-4) 퇴직자 및 DC전환자 명부'!C3="","",'(2-4) 퇴직자 및 DC전환자 명부'!C3) -> 19870511 | D3: =IF('(2-4) 퇴직자 및 DC전환자 명부'!D3="","",'(2-4) 퇴직자 및 DC전환자 명부'!D3) -> 1 | E3: =IF('(2-4) 퇴직자 및 DC전환자 명부'!E3="","",'(2-4) 퇴직자 및 DC전환자 명부'!E3) -> 20140106 | F3: =IF('(2-4) 퇴직자 및 DC전환자 명부'!F3="","",'(2-4) 퇴직자 및 DC전환자 명부'!F3) -> 20250131 | M3: =IF('(2-4) 퇴직자 및 DC전환자 명부'!G3="","",'(2-4) 퇴직자 및 DC전환자 명부'!G3) -> 60229060
A4: =IF('(2-4) 퇴직자 및 DC전환자 명부'!B5="","",'(2-4) 퇴직자 및 DC전환자 명부'!B5) -> 157 | B4: =IF(A4="","",A4) -> 157 | C4: =IF('(2-4) 퇴직자 및 DC전환자 명부'!#REF!="","",'(2-4) 퇴직자 및 DC전환자 명부'!#REF!) -> #REF! | D4: =IF('(2-4) 퇴직자 및 DC전환자 명부'!#REF!="","",'(2-4) 퇴직자 및 DC전환자 명부'!#REF!) -> #REF! | E4: =IF('(2-4) 퇴직자 및 DC전환자 명부'!#REF!="","",'(2-4) 퇴직자 및 DC전환자 명부'!#REF!) -> #REF! | F4: =IF('(2-4) 퇴직자 및 DC전환자 명부'!#REF!="","",'(2-4) 퇴직자 및 DC전환자 명부'!#REF!) -> #REF! | M4: =IF('(2-4) 퇴직자 및 DC전환자 명부'!#REF!="","",'(2-4) 퇴직자 및 DC전환자 명부'!#REF!) -> #REF!
A5: =IF('(2-4) 퇴직자 및 DC전환자 명부'!B6="","",'(2-4) 퇴직자 및 DC전환자 명부'!B6) -> 157 | B5: =IF(A5="","",A5) -> 157 | C5: =IF('(2-4) 퇴직자 및 DC전환자 명부'!C4="","",'(2-4) 퇴직자 및 DC전환자 명부'!C4) -> 19920713 | D5: =IF('(2-4) 퇴직자 및 DC전환자 명부'!D4="","",'(2-4) 퇴직자 및 DC전환자 명부'!D4) -> 2 | E5: =IF('(2-4) 퇴직자 및 DC전환자 명부'!E4="","",'(2-4) 퇴직자 및 DC전환자 명부'!E4) -> 20241021 | F5: =IF('(2-4) 퇴직자 및 DC전환자 명부'!F4="","",'(2-4) 퇴직자 및 DC전환자 명부'!F4) -> 20250205 | M5: =IF('(2-4) 퇴직자 및 DC전환자 명부'!G4="","",'(2-4) 퇴직자 및 DC전환자 명부'!G4) -> 0
A6: =IF('(2-4) 퇴직자 및 DC전환자 명부'!B7="","",'(2-4) 퇴직자 및 DC전환자 명부'!B7) -> 158 | B6: =IF(A6="","",A6) -> 158 | C6: =IF('(2-4) 퇴직자 및 DC전환자 명부'!C5="","",'(2-4) 퇴직자 및 DC전환자 명부'!C5) -> 20030227 | D6: =IF('(2-4) 퇴직자 및 DC전환자 명부'!D5="","",'(2-4) 퇴직자 및 DC전환자 명부'!D5) -> 2 | E6: =IF('(2-4) 퇴직자 및 DC전환자 명부'!E5="","",'(2-4) 퇴직자 및 DC전환자 명부'!E5) -> 20210322 | F6: =IF('(2-4) 퇴직자 및 DC전환자 명부'!F5="","",'(2-4) 퇴직자 및 DC전환자 명부'!F5) -> 20250311 | M6: =IF('(2-4) 퇴직자 및 DC전환자 명부'!G5="","",'(2-4) 퇴직자 및 DC전환자 명부'!G5) -> 10380260
A7: =IF('(2-4) 퇴직자 및 DC전환자 명부'!B8="","",'(2-4) 퇴직자 및 DC전환자 명부'!B8) -> 158 | B7: =IF(A7="","",A7) -> 158 | C7: =IF('(2-4) 퇴직자 및 DC전환자 명부'!C7="","",'(2-4) 퇴직자 및 DC전환자 명부'!C7) -> 19610518 | D7: =IF('(2-4) 퇴직자 및 DC전환자 명부'!D7="","",'(2-4) 퇴직자 및 DC전환자 명부'!D7) -> 1 | E7: =IF('(2-4) 퇴직자 및 DC전환자 명부'!E7="","",'(2-4) 퇴직자 및 DC전환자 명부'!E7) -> 20240819 | F7: =IF('(2-4) 퇴직자 및 DC전환자 명부'!F7="","",'(2-4) 퇴직자 및 DC전환자 명부'!F7) -> 20250405 | M7: =IF('(2-4) 퇴직자 및 DC전환자 명부'!G7="","",'(2-4) 퇴직자 및 DC전환자 명부'!G7) -> 0
A8: =IF('(2-4) 퇴직자 및 DC전환자 명부'!B9="","",'(2-4) 퇴직자 및 DC전환자 명부'!B9) -> 159 | B8: =IF(A8="","",A8) -> 159 | C8: =IF('(2-4) 퇴직자 및 DC전환자 명부'!C8="","",'(2-4) 퇴직자 및 DC전환자 명부'!C8) -> 19940329 | D8: =IF('(2-4) 퇴직자 및 DC전환자 명부'!D8="","",'(2-4) 퇴직자 및 DC전환자 명부'!D8) -> 2 | E8: =IF('(2-4) 퇴직자 및 DC전환자 명부'!E8="","",'(2-4) 퇴직자 및 DC전환자 명부'!E8) -> 20250514 | F8: =IF('(2-4) 퇴직자 및 DC전환자 명부'!F8="","",'(2-4) 퇴직자 및 DC전환자 명부'!F8) -> 20250518 | M8: =IF('(2-4) 퇴직자 및 DC전환자 명부'!G8="","",'(2-4) 퇴직자 및 DC전환자 명부'!G8) -> 0
A9: =IF('(2-4) 퇴직자 및 DC전환자 명부'!B10="","",'(2-4) 퇴직자 및 DC전환자 명부'!B10) -> 159 | B9: =IF(A9="","",A9) -> 159 | C9: =IF('(2-4) 퇴직자 및 DC전환자 명부'!C9="","",'(2-4) 퇴직자 및 DC전환자 명부'!C9) -> 19980107 | D9: =IF('(2-4) 퇴직자 및 DC전환자 명부'!D9="","",'(2-4) 퇴직자 및 DC전환자 명부'!D9) -> 1 | E9: =IF('(2-4) 퇴직자 및 DC전환자 명부'!E9="","",'(2-4) 퇴직자 및 DC전환자 명부'!E9) -> 20230201 | F9: =IF('(2-4) 퇴직자 및 DC전환자 명부'!F9="","",'(2-4) 퇴직자 및 DC전환자 명부'!F9) -> 20250707 | M9: =IF('(2-4) 퇴직자 및 DC전환자 명부'!G9="","",'(2-4) 퇴직자 및 DC전환자 명부'!G9) -> 7788670
A10: =IF('(2-4) 퇴직자 및 DC전환자 명부'!B11="","",'(2-4) 퇴직자 및 DC전환자 명부'!B11) -> 160 | B10: =IF(A10="","",A10) -> 160 | C10: =IF('(2-4) 퇴직자 및 DC전환자 명부'!C10="","",'(2-4) 퇴직자 및 DC전환자 명부'!C10) -> 20050113 | D10: =IF('(2-4) 퇴직자 및 DC전환자 명부'!D10="","",'(2-4) 퇴직자 및 DC전환자 명부'!D10) -> 2 | E10: =IF('(2-4) 퇴직자 및 DC전환자 명부'!E10="","",'(2-4) 퇴직자 및 DC전환자 명부'!E10) -> 20240219 | F10: =IF('(2-4) 퇴직자 및 DC전환자 명부'!F10="","",'(2-4) 퇴직자 및 DC전환자 명부'!F10) -> 20250903 | M10: =IF('(2-4) 퇴직자 및 DC전환자 명부'!G10="","",'(2-4) 퇴직자 및 DC전환자 명부'!G10) -> 3624310
A11: =IF('(2-4) 퇴직자 및 DC전환자 명부'!B12="","",'(2-4) 퇴직자 및 DC전환자 명부'!B12) -> 160 | B11: =IF(A11="","",A11) -> 160 | C11: =IF('(2-4) 퇴직자 및 DC전환자 명부'!C11="","",'(2-4) 퇴직자 및 DC전환자 명부'!C11) -> 19981204 | D11: =IF('(2-4) 퇴직자 및 DC전환자 명부'!D11="","",'(2-4) 퇴직자 및 DC전환자 명부'!D11) -> 1 | E11: =IF('(2-4) 퇴직자 및 DC전환자 명부'!E11="","",'(2-4) 퇴직자 및 DC전환자 명부'!E11) -> 20250701 | F11: =IF('(2-4) 퇴직자 및 DC전환자 명부'!F11="","",'(2-4) 퇴직자 및 DC전환자 명부'!F11) -> 20250930 | M11: =IF('(2-4) 퇴직자 및 DC전환자 명부'!G11="","",'(2-4) 퇴직자 및 DC전환자 명부'!G11) -> 0
A12: =IF('(2-4) 퇴직자 및 DC전환자 명부'!B13="","",'(2-4) 퇴직자 및 DC전환자 명부'!B13) -> 161 | B12: =IF(A12="","",A12) -> 161 | C12: =IF('(2-4) 퇴직자 및 DC전환자 명부'!C14="","",'(2-4) 퇴직자 및 DC전환자 명부'!C14) -> 19811016 | D12: =IF('(2-4) 퇴직자 및 DC전환자 명부'!D14="","",'(2-4) 퇴직자 및 DC전환자 명부'!D14) -> 1 | E12: =IF('(2-4) 퇴직자 및 DC전환자 명부'!E14="","",'(2-4) 퇴직자 및 DC전환자 명부'!E14) -> 20230918 | F12: =IF('(2-4) 퇴직자 및 DC전환자 명부'!F14="","",'(2-4) 퇴직자 및 DC전환자 명부'!F14) -> 20251017 | M12: =IF('(2-4) 퇴직자 및 DC전환자 명부'!G14="","",'(2-4) 퇴직자 및 DC전환자 명부'!G14) -> 10024710
A13: =IF('(2-4) 퇴직자 및 DC전환자 명부'!B14="","",'(2-4) 퇴직자 및 DC전환자 명부'!B14) -> 161 | B13: =IF(A13="","",A13) -> 161 | C13: =IF('(2-4) 퇴직자 및 DC전환자 명부'!C15="","",'(2-4) 퇴직자 및 DC전환자 명부'!C15) | D13: =IF('(2-4) 퇴직자 및 DC전환자 명부'!D15="","",'(2-4) 퇴직자 및 DC전환자 명부'!D15) | E13: =IF('(2-4) 퇴직자 및 DC전환자 명부'!E15="","",'(2-4) 퇴직자 및 DC전환자 명부'!E15) | F13: =IF('(2-4) 퇴직자 및 DC전환자 명부'!F15="","",'(2-4) 퇴직자 및 DC전환자 명부'!F15) | M13: =IF('(2-4) 퇴직자 및 DC전환자 명부'!G15="","",'(2-4) 퇴직자 및 DC전환자 명부'!G15)
A14: =IF('(2-4) 퇴직자 및 DC전환자 명부'!B15="","",'(2-4) 퇴직자 및 DC전환자 명부'!B15) | B14: =IF(A14="","",A14) | C14: =IF('(2-4) 퇴직자 및 DC전환자 명부'!#REF!="","",'(2-4) 퇴직자 및 DC전환자 명부'!#REF!) -> #REF! | D14: =IF('(2-4) 퇴직자 및 DC전환자 명부'!#REF!="","",'(2-4) 퇴직자 및 DC전환자 명부'!#REF!) -> #REF! | E14: =IF('(2-4) 퇴직자 및 DC전환자 명부'!#REF!="","",'(2-4) 퇴직자 및 DC전환자 명부'!#REF!) -> #REF! | F14: =IF('(2-4) 퇴직자 및 DC전환자 명부'!#REF!="","",'(2-4) 퇴직자 및 DC전환자 명부'!#REF!) -> #REF! | M14: =IF('(2-4) 퇴직자 및 DC전환자 명부'!#REF!="","",'(2-4) 퇴직자 및 DC전환자 명부'!#REF!) -> #REF!
A15: =IF('(2-4) 퇴직자 및 DC전환자 명부'!#REF!="","",'(2-4) 퇴직자 및 DC전환자 명부'!#REF!) -> #REF! | B15: =IF(A15="","",A15) -> #REF! | C15: =IF('(2-4) 퇴직자 및 DC전환자 명부'!#REF!="","",'(2-4) 퇴직자 및 DC전환자 명부'!#REF!) -> #REF! | D15: =IF('(2-4) 퇴직자 및 DC전환자 명부'!#REF!="","",'(2-4) 퇴직자 및 DC전환자 명부'!#REF!) -> #REF! | E15: =IF('(2-4) 퇴직자 및 DC전환자 명부'!#REF!="","",'(2-4) 퇴직자 및 DC전환자 명부'!#REF!) -> #REF! | F15: =IF('(2-4) 퇴직자 및 DC전환자 명부'!#REF!="","",'(2-4) 퇴직자 및 DC전환자 명부'!#REF!) -> #REF! | M15: =IF('(2-4) 퇴직자 및 DC전환자 명부'!#REF!="","",'(2-4) 퇴직자 및 DC전환자 명부'!#REF!) -> #REF!
A16: =IF('(2-4) 퇴직자 및 DC전환자 명부'!B16="","",'(2-4) 퇴직자 및 DC전환자 명부'!B16) | B16: =IF(A16="","",A16) | C16: =IF('(2-4) 퇴직자 및 DC전환자 명부'!C16="","",'(2-4) 퇴직자 및 DC전환자 명부'!C16) | D16: =IF('(2-4) 퇴직자 및 DC전환자 명부'!D16="","",'(2-4) 퇴직자 및 DC전환자 명부'!D16) | E16: =IF('(2-4) 퇴직자 및 DC전환자 명부'!E16="","",'(2-4) 퇴직자 및 DC전환자 명부'!E16) | F16: =IF('(2-4) 퇴직자 및 DC전환자 명부'!F16="","",'(2-4) 퇴직자 및 DC전환자 명부'!F16) | M16: =IF('(2-4) 퇴직자 및 DC전환자 명부'!G16="","",'(2-4) 퇴직자 및 DC전환자 명부'!G16)
A17: =IF('(2-4) 퇴직자 및 DC전환자 명부'!B17="","",'(2-4) 퇴직자 및 DC전환자 명부'!B17) | B17: =IF(A17="","",A17) | C17: =IF('(2-4) 퇴직자 및 DC전환자 명부'!C17="","",'(2-4) 퇴직자 및 DC전환자 명부'!C17) | D17: =IF('(2-4) 퇴직자 및 DC전환자 명부'!D17="","",'(2-4) 퇴직자 및 DC전환자 명부'!D17) | E17: =IF('(2-4) 퇴직자 및 DC전환자 명부'!E17="","",'(2-4) 퇴직자 및 DC전환자 명부'!E17) | F17: =IF('(2-4) 퇴직자 및 DC전환자 명부'!F17="","",'(2-4) 퇴직자 및 DC전환자 명부'!F17) | M17: =IF('(2-4) 퇴직자 및 DC전환자 명부'!G17="","",'(2-4) 퇴직자 및 DC전환자 명부'!G17)
A18: =IF('(2-4) 퇴직자 및 DC전환자 명부'!B18="","",'(2-4) 퇴직자 및 DC전환자 명부'!B18) | B18: =IF(A18="","",A18) | C18: =IF('(2-4) 퇴직자 및 DC전환자 명부'!C18="","",'(2-4) 퇴직자 및 DC전환자 명부'!C18) | D18: =IF('(2-4) 퇴직자 및 DC전환자 명부'!D18="","",'(2-4) 퇴직자 및 DC전환자 명부'!D18) | E18: =IF('(2-4) 퇴직자 및 DC전환자 명부'!E18="","",'(2-4) 퇴직자 및 DC전환자 명부'!E18) | F18: =IF('(2-4) 퇴직자 및 DC전환자 명부'!F18="","",'(2-4) 퇴직자 및 DC전환자 명부'!F18) | M18: =IF('(2-4) 퇴직자 및 DC전환자 명부'!G18="","",'(2-4) 퇴직자 및 DC전환자 명부'!G18)
A19: =IF('(2-4) 퇴직자 및 DC전환자 명부'!B19="","",'(2-4) 퇴직자 및 DC전환자 명부'!B19) | B19: =IF(A19="","",A19) | C19: =IF('(2-4) 퇴직자 및 DC전환자 명부'!C19="","",'(2-4) 퇴직자 및 DC전환자 명부'!C19) | D19: =IF('(2-4) 퇴직자 및 DC전환자 명부'!D19="","",'(2-4) 퇴직자 및 DC전환자 명부'!D19) | E19: =IF('(2-4) 퇴직자 및 DC전환자 명부'!E19="","",'(2-4) 퇴직자 및 DC전환자 명부'!E19) | F19: =IF('(2-4) 퇴직자 및 DC전환자 명부'!F19="","",'(2-4) 퇴직자 및 DC전환자 명부'!F19) | M19: =IF('(2-4) 퇴직자 및 DC전환자 명부'!G19="","",'(2-4) 퇴직자 및 DC전환자 명부'!G19)
A20: =IF('(2-4) 퇴직자 및 DC전환자 명부'!B20="","",'(2-4) 퇴직자 및 DC전환자 명부'!B20) | B20: =IF(A20="","",A20) | C20: =IF('(2-4) 퇴직자 및 DC전환자 명부'!C20="","",'(2-4) 퇴직자 및 DC전환자 명부'!C20) | D20: =IF('(2-4) 퇴직자 및 DC전환자 명부'!D20="","",'(2-4) 퇴직자 및 DC전환자 명부'!D20) | E20: =IF('(2-4) 퇴직자 및 DC전환자 명부'!E20="","",'(2-4) 퇴직자 및 DC전환자 명부'!E20) | F20: =IF('(2-4) 퇴직자 및 DC전환자 명부'!F20="","",'(2-4) 퇴직자 및 DC전환자 명부'!F20) | M20: =IF('(2-4) 퇴직자 및 DC전환자 명부'!G20="","",'(2-4) 퇴직자 및 DC전환자 명부'!G20)
A21: =IF('(2-4) 퇴직자 및 DC전환자 명부'!B21="","",'(2-4) 퇴직자 및 DC전환자 명부'!B21) | B21: =IF(A21="","",A21) | C21: =IF('(2-4) 퇴직자 및 DC전환자 명부'!C21="","",'(2-4) 퇴직자 및 DC전환자 명부'!C21) | D21: =IF('(2-4) 퇴직자 및 DC전환자 명부'!D21="","",'(2-4) 퇴직자 및 DC전환자 명부'!D21) | E21: =IF('(2-4) 퇴직자 및 DC전환자 명부'!E21="","",'(2-4) 퇴직자 및 DC전환자 명부'!E21) | F21: =IF('(2-4) 퇴직자 및 DC전환자 명부'!F21="","",'(2-4) 퇴직자 및 DC전환자 명부'!F21) | M21: =IF('(2-4) 퇴직자 및 DC전환자 명부'!G21="","",'(2-4) 퇴직자 및 DC전환자 명부'!G21)
A22: =IF('(2-4) 퇴직자 및 DC전환자 명부'!B22="","",'(2-4) 퇴직자 및 DC전환자 명부'!B22) | B22: =IF(A22="","",A22) | C22: =IF('(2-4) 퇴직자 및 DC전환자 명부'!C22="","",'(2-4) 퇴직자 및 DC전환자 명부'!C22) | D22: =IF('(2-4) 퇴직자 및 DC전환자 명부'!D22="","",'(2-4) 퇴직자 및 DC전환자 명부'!D22) | E22: =IF('(2-4) 퇴직자 및 DC전환자 명부'!E22="","",'(2-4) 퇴직자 및 DC전환자 명부'!E22) | F22: =IF('(2-4) 퇴직자 및 DC전환자 명부'!F22="","",'(2-4) 퇴직자 및 DC전환자 명부'!F22) | M22: =IF('(2-4) 퇴직자 및 DC전환자 명부'!G22="","",'(2-4) 퇴직자 및 DC전환자 명부'!G22)
A23: =IF('(2-4) 퇴직자 및 DC전환자 명부'!B23="","",'(2-4) 퇴직자 및 DC전환자 명부'!B23) | B23: =IF(A23="","",A23) | C23: =IF('(2-4) 퇴직자 및 DC전환자 명부'!C23="","",'(2-4) 퇴직자 및 DC전환자 명부'!C23) | D23: =IF('(2-4) 퇴직자 및 DC전환자 명부'!D23="","",'(2-4) 퇴직자 및 DC전환자 명부'!D23) | E23: =IF('(2-4) 퇴직자 및 DC전환자 명부'!E23="","",'(2-4) 퇴직자 및 DC전환자 명부'!E23) | F23: =IF('(2-4) 퇴직자 및 DC전환자 명부'!F23="","",'(2-4) 퇴직자 및 DC전환자 명부'!F23) | M23: =IF('(2-4) 퇴직자 및 DC전환자 명부'!G23="","",'(2-4) 퇴직자 및 DC전환자 명부'!G23)
A24: =IF('(2-4) 퇴직자 및 DC전환자 명부'!B24="","",'(2-4) 퇴직자 및 DC전환자 명부'!B24) | B24: =IF(A24="","",A24) | C24: =IF('(2-4) 퇴직자 및 DC전환자 명부'!C24="","",'(2-4) 퇴직자 및 DC전환자 명부'!C24) | D24: =IF('(2-4) 퇴직자 및 DC전환자 명부'!D24="","",'(2-4) 퇴직자 및 DC전환자 명부'!D24) | E24: =IF('(2-4) 퇴직자 및 DC전환자 명부'!E24="","",'(2-4) 퇴직자 및 DC전환자 명부'!E24) | F24: =IF('(2-4) 퇴직자 및 DC전환자 명부'!F24="","",'(2-4) 퇴직자 및 DC전환자 명부'!F24) | M24: =IF('(2-4) 퇴직자 및 DC전환자 명부'!G24="","",'(2-4) 퇴직자 및 DC전환자 명부'!G24)
A25: =IF('(2-4) 퇴직자 및 DC전환자 명부'!B25="","",'(2-4) 퇴직자 및 DC전환자 명부'!B25) | B25: =IF(A25="","",A25) | C25: =IF('(2-4) 퇴직자 및 DC전환자 명부'!C25="","",'(2-4) 퇴직자 및 DC전환자 명부'!C25) | D25: =IF('(2-4) 퇴직자 및 DC전환자 명부'!D25="","",'(2-4) 퇴직자 및 DC전환자 명부'!D25) | E25: =IF('(2-4) 퇴직자 및 DC전환자 명부'!E25="","",'(2-4) 퇴직자 및 DC전환자 명부'!E25) | F25: =IF('(2-4) 퇴직자 및 DC전환자 명부'!F25="","",'(2-4) 퇴직자 및 DC전환자 명부'!F25) | M25: =IF('(2-4) 퇴직자 및 DC전환자 명부'!G25="","",'(2-4) 퇴직자 및 DC전환자 명부'!G25)
A26: =IF('(2-4) 퇴직자 및 DC전환자 명부'!B26="","",'(2-4) 퇴직자 및 DC전환자 명부'!B26) | B26: =IF(A26="","",A26) | C26: =IF('(2-4) 퇴직자 및 DC전환자 명부'!C26="","",'(2-4) 퇴직자 및 DC전환자 명부'!C26) | D26: =IF('(2-4) 퇴직자 및 DC전환자 명부'!D26="","",'(2-4) 퇴직자 및 DC전환자 명부'!D26) | E26: =IF('(2-4) 퇴직자 및 DC전환자 명부'!E26="","",'(2-4) 퇴직자 및 DC전환자 명부'!E26) | F26: =IF('(2-4) 퇴직자 및 DC전환자 명부'!F26="","",'(2-4) 퇴직자 및 DC전환자 명부'!F26) | M26: =IF('(2-4) 퇴직자 및 DC전환자 명부'!G26="","",'(2-4) 퇴직자 및 DC전환자 명부'!G26)
A27: =IF('(2-4) 퇴직자 및 DC전환자 명부'!B27="","",'(2-4) 퇴직자 및 DC전환자 명부'!B27) | B27: =IF(A27="","",A27) | C27: =IF('(2-4) 퇴직자 및 DC전환자 명부'!C27="","",'(2-4) 퇴직자 및 DC전환자 명부'!C27) | D27: =IF('(2-4) 퇴직자 및 DC전환자 명부'!D27="","",'(2-4) 퇴직자 및 DC전환자 명부'!D27) | E27: =IF('(2-4) 퇴직자 및 DC전환자 명부'!E27="","",'(2-4) 퇴직자 및 DC전환자 명부'!E27) | F27: =IF('(2-4) 퇴직자 및 DC전환자 명부'!F27="","",'(2-4) 퇴직자 및 DC전환자 명부'!F27) | M27: =IF('(2-4) 퇴직자 및 DC전환자 명부'!G27="","",'(2-4) 퇴직자 및 DC전환자 명부'!G27)
... A2484: =IF('(2-4) 퇴직자 및 DC전환자 명부'!B2484="","",'(2-4) 퇴직자 및 DC전환자 명부'!B2484) | B2484: =IF(A2484="","",A2484) | C2484: =IF('(2-4) 퇴직자 및 DC전환자 명부'!C2484="","",'(2-4) 퇴직자 및 DC전환자 명부'!C2484) | D2484: =IF('(2-4) 퇴직자 및 DC전환자 명부'!D2484="","",'(2-4) 퇴직자 및 DC전환자 명부'!D2484) | E2484: =IF('(2-4) 퇴직자 및 DC전환자 명부'!E2484="","",'(2-4) 퇴직자 및 DC전환자 명부'!E2484) | F2484: =IF('(2-4) 퇴직자 및 DC전환자 명부'!F2484="","",'(2-4) 퇴직자 및 DC전환자 명부'!F2484) | M2484: =IF('(2-4) 퇴직자 및 DC전환자 명부'!G2484="","",'(2-4) 퇴직자 및 DC전환자 명부'!G2484)
M2485: =IF('(2-4) 퇴직자 및 DC전환자 명부'!G2485="","",'(2-4) 퇴직자 및 DC전환자 명부'!G2485)
M2486: =IF('(2-4) 퇴직자 및 DC전환자 명부'!G2486="","",'(2-4) 퇴직자 및 DC전환자 명부'!G2486)
M2487: =IF('(2-4) 퇴직자 및 DC전환자 명부'!G2487="","",'(2-4) 퇴직자 및 DC전환자 명부'!G2487)
M2488: =IF('(2-4) 퇴직자 및 DC전환자 명부'!G2488="","",'(2-4) 퇴직자 및 DC전환자 명부'!G2488)
M2489: =IF('(2-4) 퇴직자 및 DC전환자 명부'!G2489="","",'(2-4) 퇴직자 및 DC전환자 명부'!G2489)
M2490: =IF('(2-4) 퇴직자 및 DC전환자 명부'!G2490="","",'(2-4) 퇴직자 및 DC전환자 명부'!G2490)
M2491: =IF('(2-4) 퇴직자 및 DC전환자 명부'!G2491="","",'(2-4) 퇴직자 및 DC전환자 명부'!G2491)
M2492: =IF('(2-4) 퇴직자 및 DC전환자 명부'!G2492="","",'(2-4) 퇴직자 및 DC전환자 명부'!G2492)
M2493: =IF('(2-4) 퇴직자 및 DC전환자 명부'!G2493="","",'(2-4) 퇴직자 및 DC전환자 명부'!G2493)
M2494: =IF('(2-4) 퇴직자 및 DC전환자 명부'!G2494="","",'(2-4) 퇴직자 및 DC전환자 명부'!G2494)
M2495: =IF('(2-4) 퇴직자 및 DC전환자 명부'!G2495="","",'(2-4) 퇴직자 및 DC전환자 명부'!G2495)
M2496: =IF('(2-4) 퇴직자 및 DC전환자 명부'!G2496="","",'(2-4) 퇴직자 및 DC전환자 명부'!G2496)
...

Sheet 추계액검증
B2: 평가일 | C2: 20151231
B3: 정년 | C3: 60
C4: 1 | D4: =C4+1 -> 2 | E4: =D4+1 -> 3 | F4: =E4+1 -> 4 | G4: =F4+1 -> 5 | H4: =G4+1 -> 6 | I4: =H4+1 -> 7 | J4: =I4+1 -> 8 | L4: =J4+1 -> 9 | M4: =L4+1 -> 10
C6: 사원번호 | D6: 생년월일 | E6: 성별 | F6: 입사일자 | G6: 평균급여 | H6: 당년도 추계액 | I6: 차년도 추계액 | J6: 직종 | K6: 중간정산일 | L6: 적용배수 | M6: 중간정산일 | N6: 연령 | O6: 총근무기간 | P6: 중간정산이후 근무기간 | Q6: 당년도 퇴직금추계액 | R6: 차년도 퇴직금추계액 | S6: 당년도 차이 | T6: 차년도 차이 | U6: check | V6: check | W6: 확인요청여부 | X6: 확인요청여부
C7: ='(2-2) 재직자 명부'!B2 -> 1 | D7: ='(2-2) 재직자 명부'!C2 -> 19670702 | E7: ='(2-2) 재직자 명부'!D2 -> 1 | F7: ='(2-2) 재직자 명부'!E2 -> 36770 | G7: ='(2-2) 재직자 명부'!F2 -> 47270000 | H7: ='(2-2) 재직자 명부'!G2 -> 3.59252e+09 | I7: ='(2-2) 재직자 명부'!H2 -> 3.73433e+09 | J7: ='(2-2) 재직자 명부'!I2 -> 3 | K7: ='(2-2) 재직자 명부'!J2 -> 0 | L7: =IF('(2-2) 재직자 명부'!M2="",1,'(2-2) 재직자 명부'!M2) -> 3 | N7: =ROUNDDOWN(((LEFT($C$2,4)+(DATE(FALSE,MID($C$2,5,2),RIGHT($C$2,2))-1)/366)-((LEFT(D7,4)+(DATE(FALSE,MID(D7,5,2),RIGHT(D7,2))-1)/366))),0) -> 48 | O7: =((LEFT($C$2,4)+(DATE(FALSE,MID($C$2,5,2),RIGHT($C$2,2)))/366)-((LEFT(F7,4)+(DATE(FALSE,MID(F7,5,2),RIGHT(F7,2))-1)/366))) -> #NUM! | P7: =IF(K7=0,"",((LEFT($C$2,4)+(DATE(FALSE,MID($C$2,5,2),RIGHT($C$2,2)))/366)-((LEFT(K7,4)+(DATE(FALSE,MID(K7,5,2),RIGHT(K7,2)))/366)))) | Q7: =IF(K7=0,O7*G7,G7*P7)*L7 -> #NUM! | R7: =IF(K7=0,(O7+1)*G7,G7*(P7+1))*L7 -> #NUM! | S7: =H7-Q7 -> #NUM! | T7: =I7-R7 -> #NUM! | U7: =IF(AND(J7<3,LEFT(F7,4)="2015"),"-",IF(ABS(S7/H7)>0.1,"e","-")) -> #NUM! | V7: =IF(OR(J7>2,N7>$C$3),IF(ABS(T7/I7)>0.1,"e","-"),"-") -> #NUM! | W7: =IF(U7="e",C7,"") -> #NUM! | X7: =IF(V7="e",C7,"") -> #NUM!
C8: ='(2-2) 재직자 명부'!B3 -> 2 | D8: ='(2-2) 재직자 명부'!C3 -> 19691224 | E8: ='(2-2) 재직자 명부'!D3 -> 1 | F8: ='(2-2) 재직자 명부'!E3 -> 39083 | G8: ='(2-2) 재직자 명부'!F3 -> 77830000 | H8: ='(2-2) 재직자 명부'!G3 -> 4436310000 | I8: ='(2-2) 재직자 명부'!H3 -> 4669800000 | J8: ='(2-2) 재직자 명부'!I3 -> 3 | K8: ='(2-2) 재직자 명부'!J3 -> 0 | L8: =IF('(2-2) 재직자 명부'!M3="",1,'(2-2) 재직자 명부'!M3) -> 3 | M8: =IF('(2-2) 재직자 명부'!J3="","",LEFT('(2-2) 재직자 명부'!J3,4)&"-"&MID('(2-2) 재직자 명부'!J3,5,2)&"-"&RIGHT('(2-2) 재직자 명부'!J3,2)) | N8: =ROUNDDOWN(((LEFT($C$2,4)+(DATE(FALSE,MID($C$2,5,2),RIGHT($C$2,2))-1)/366)-((LEFT(D8,4)+(DATE(FALSE,MID(D8,5,2),RIGHT(D8,2))-1)/366))),0) -> 46 | O8: =((LEFT($C$2,4)+(DATE(FALSE,MID($C$2,5,2),RIGHT($C$2,2)))/366)-((LEFT(F8,4)+(DATE(FALSE,MID(F8,5,2),RIGHT(F8,2))-1)/366))) -> -1892.388 | P8: =IF(K8=0,"",((LEFT($C$2,4)+(DATE(FALSE,MID($C$2,5,2),RIGHT($C$2,2)))/366)-((LEFT(K8,4)+(DATE(FALSE,MID(K8,5,2),RIGHT(K8,2)))/366)))) | Q8: =IF(K8=0,O8*G8,G8*P8)*L8 -> -4.4185367e+11 | R8: =IF(K8=0,(O8+1)*G8,G8*(P8+1))*L8 -> -4.4162018e+11 | S8: =H8-Q8 -> 4.4628998e+11 | T8: =I8-R8 -> 4.4628998e+11 | U8: =IF(AND(J8<3,LEFT(F8,4)="2015"),"-",IF(ABS(S8/H8)>0.1,"e","-")) -> e | V8: =IF(OR(J8>2,N8>$C$3),IF(ABS(T8/I8)>0.1,"e","-"),"-") -> e | W8: =IF(U8="e",C8,"") -> 2 | X8: =IF(V8="e",C8,"") -> 2
C9: ='(2-2) 재직자 명부'!B4 -> 3 | D9: ='(2-2) 재직자 명부'!C4 -> 19580912 | E9: ='(2-2) 재직자 명부'!D4 -> 1 | F9: ='(2-2) 재직자 명부'!E4 -> 42811 | G9: ='(2-2) 재직자 명부'!F4 -> 23630000 | H9: ='(2-2) 재직자 명부'!G4 -> 638010000 | I9: ='(2-2) 재직자 명부'!H4 -> 708900000 | J9: ='(2-2) 재직자 명부'!I4 -> 3 | K9: ='(2-2) 재직자 명부'!J4 -> 0 | L9: =IF('(2-2) 재직자 명부'!M4="",1,'(2-2) 재직자 명부'!M4) -> 3 | M9: =IF('(2-2) 재직자 명부'!J4="","",LEFT('(2-2) 재직자 명부'!J4,4)&"-"&MID('(2-2) 재직자 명부'!J4,5,2)&"-"&RIGHT('(2-2) 재직자 명부'!J4,2)) | N9: =ROUNDDOWN(((LEFT($C$2,4)+(DATE(FALSE,MID($C$2,5,2),RIGHT($C$2,2))-1)/366)-((LEFT(D9,4)+(DATE(FALSE,MID(D9,5,2),RIGHT(D9,2))-1)/366))),0) -> 57 | O9: =((LEFT($C$2,4)+(DATE(FALSE,MID($C$2,5,2),RIGHT($C$2,2)))/366)-((LEFT(F9,4)+(DATE(FALSE,MID(F9,5,2),RIGHT(F9,2))-1)/366))) -> -2265.0273 | P9: =IF(K9=0,"",((LEFT($C$2,4)+(DATE(FALSE,MID($C$2,5,2),RIGHT($C$2,2)))/366)-((LEFT(K9,4)+(DATE(FALSE,MID(K9,5,2),RIGHT(K9,2)))/366)))) | Q9: =IF(K9=0,O9*G9,G9*P9)*L9 -> -1.6056779e+11 | R9: =IF(K9=0,(O9+1)*G9,G9*(P9+1))*L9 -> -1.604969e+11 | S9: =H9-Q9 -> 1.612058e+11 | T9: =I9-R9 -> 1.612058e+11 | U9: =IF(AND(J9<3,LEFT(F9,4)="2015"),"-",IF(ABS(S9/H9)>0.1,"e","-")) -> e | V9: =IF(OR(J9>2,N9>$C$3),IF(ABS(T9/I9)>0.1,"e","-"),"-") -> e | W9: =IF(U9="e",C9,"") -> 3 | X9: =IF(V9="e",C9,"") -> 3
C10: ='(2-2) 재직자 명부'!B5 -> 4 | D10: ='(2-2) 재직자 명부'!C5 -> 19681023 | E10: ='(2-2) 재직자 명부'!D5 -> 1 | F10: ='(2-2) 재직자 명부'!E5 -> 44927 | G10: ='(2-2) 재직자 명부'!F5 -> 12100000 | H10: ='(2-2) 재직자 명부'!G5 -> 108900000 | I10: ='(2-2) 재직자 명부'!H5 -> 145200000 | J10: ='(2-2) 재직자 명부'!I5 -> 3 | K10: ='(2-2) 재직자 명부'!J5 -> 0 | L10: =IF('(2-2) 재직자 명부'!M5="",1,'(2-2) 재직자 명부'!M5) -> 3 | M10: =IF('(2-2) 재직자 명부'!J5="","",LEFT('(2-2) 재직자 명부'!J5,4)&"-"&MID('(2-2) 재직자 명부'!J5,5,2)&"-"&RIGHT('(2-2) 재직자 명부'!J5,2)) | N10: =ROUNDDOWN(((LEFT($C$2,4)+(DATE(FALSE,MID($C$2,5,2),RIGHT($C$2,2))-1)/366)-((LEFT(D10,4)+(DATE(FALSE,MID(D10,5,2),RIGHT(D10,2))-1)/366))),0) -> 47 | O10: =((LEFT($C$2,4)+(DATE(FALSE,MID($C$2,5,2),RIGHT($C$2,2)))/366)-((LEFT(F10,4)+(DATE(FALSE,MID(F10,5,2),RIGHT(F10,2))-1)/366))) -> -2476.5683 | P10: =IF(K10=0,"",((LEFT($C$2,4)+(DATE(FALSE,MID($C$2,5,2),RIGHT($C$2,2)))/366)-((LEFT(K10,4)+(DATE(FALSE,MID(K10,5,2),RIGHT(K10,2)))/366)))) | Q10: =IF(K10=0,O10*G10,G10*P10)*L10 -> -8.989943e+10 | R10: =IF(K10=0,(O10+1)*G10,G10*(P10+1))*L10 -> -8.986313e+10 | S10: =H10-Q10 -> 9.000833e+10 | T10: =I10-R10 -> 9.000833e+10 | U10: =IF(AND(J10<3,LEFT(F10,4)="2015"),"-",IF(ABS(S10/H10)>0.1,"e","-")) -> e | V10: =IF(OR(J10>2,N10>$C$3),IF(ABS(T10/I10)>0.1,"e","-"),"-") -> e | W10: =IF(U10="e",C10,"") -> 4 | X10: =IF(V10="e",C10,"") -> 4
C11: ='(2-2) 재직자 명부'!B6 -> 5 | D11: ='(2-2) 재직자 명부'!C6 -> 19641227 | E11: ='(2-2) 재직자 명부'!D6 -> 1 | F11: ='(2-2) 재직자 명부'!E6 -> 45292 | G11: ='(2-2) 재직자 명부'!F6 -> 15900000 | H11: ='(2-2) 재직자 명부'!G6 -> 95400000 | I11: ='(2-2) 재직자 명부'!H6 -> 143100000 | J11: ='(2-2) 재직자 명부'!I6 -> 3 | K11: ='(2-2) 재직자 명부'!J6 -> 0 | L11: =IF('(2-2) 재직자 명부'!M6="",1,'(2-2) 재직자 명부'!M6) -> 3 | M11: =IF('(2-2) 재직자 명부'!J6="","",LEFT('(2-2) 재직자 명부'!J6,4)&"-"&MID('(2-2) 재직자 명부'!J6,5,2)&"-"&RIGHT('(2-2) 재직자 명부'!J6,2)) | N11: =ROUNDDOWN(((LEFT($C$2,4)+(DATE(FALSE,MID($C$2,5,2),RIGHT($C$2,2))-1)/366)-((LEFT(D11,4)+(DATE(FALSE,MID(D11,5,2),RIGHT(D11,2))-1)/366))),0) -> 51 | O11: =((LEFT($C$2,4)+(DATE(FALSE,MID($C$2,5,2),RIGHT($C$2,2)))/366)-((LEFT(F11,4)+(DATE(FALSE,MID(F11,5,2),RIGHT(F11,2))-1)/366))) -> -2513.3333 | P11: =IF(K11=0,"",((LEFT($C$2,4)+(DATE(FALSE,MID($C$2,5,2),RIGHT($C$2,2)))/366)-((LEFT(K11,4)+(DATE(FALSE,MID(K11,5,2),RIGHT(K11,2)))/366)))) | Q11: =IF(K11=0,O11*G11,G11*P11)*L11 -> -1.19886e+11 | R11: =IF(K11=0,(O11+1)*G11,G11*(P11+1))*L11 -> -1.198383e+11 | S11: =H11-Q11 -> 1.199814e+11 | T11: =I11-R11 -> 1.199814e+11 | U11: =IF(AND(J11<3,LEFT(F11,4)="2015"),"-",IF(ABS(S11/H11)>0.1,"e","-")) -> e | V11: =IF(OR(J11>2,N11>$C$3),IF(ABS(T11/I11)>0.1,"e","-"),"-") -> e | W11: =IF(U11="e",C11,"") -> 5 | X11: =IF(V11="e",C11,"") -> 5
C12: ='(2-2) 재직자 명부'!B7 -> 6 | D12: ='(2-2) 재직자 명부'!C7 -> 19930729 | E12: ='(2-2) 재직자 명부'!D7 -> 1 | F12: ='(2-2) 재직자 명부'!E7 -> 43435 | G12: ='(2-2) 재직자 명부'!F7 -> 4203350 | H12: ='(2-2) 재직자 명부'!G7 -> 29773730 | I12: ='(2-2) 재직자 명부'!H7 -> 0 | J12: ='(2-2) 재직자 명부'!I7 -> 1 | K12: ='(2-2) 재직자 명부'!J7 -> 0 | L12: =IF('(2-2) 재직자 명부'!M7="",1,'(2-2) 재직자 명부'!M7) -> 1 | M12: =IF('(2-2) 재직자 명부'!J7="","",LEFT('(2-2) 재직자 명부'!J7,4)&"-"&MID('(2-2) 재직자 명부'!J7,5,2)&"-"&RIGHT('(2-2) 재직자 명부'!J7,2)) | N12: =ROUNDDOWN(((LEFT($C$2,4)+(DATE(FALSE,MID($C$2,5,2),RIGHT($C$2,2))-1)/366)-((LEFT(D12,4)+(DATE(FALSE,MID(D12,5,2),RIGHT(D12,2))-1)/366))),0) -> 22 | O12: =((LEFT($C$2,4)+(DATE(FALSE,MID($C$2,5,2),RIGHT($C$2,2)))/366)-((LEFT(F12,4)+(DATE(FALSE,MID(F12,5,2),RIGHT(F12,2))-1)/366))) -> -2327.4235 | P12: =IF(K12=0,"",((LEFT($C$2,4)+(DATE(FALSE,MID($C$2,5,2),RIGHT($C$2,2)))/366)-((LEFT(K12,4)+(DATE(FALSE,MID(K12,5,2),RIGHT(K12,2)))/366)))) | Q12: =IF(K12=0,O12*G12,G12*P12)*L12 -> -9.7829756e+09 | R12: =IF(K12=0,(O12+1)*G12,G12*(P12+1))*L12 -> -9.7787722e+09 | S12: =H12-Q12 -> 9.8127493e+09 | T12: =I12-R12 -> 9.7787722e+09 | U12: =IF(AND(J12<3,LEFT(F12,4)="2015"),"-",IF(ABS(S12/H12)>0.1,"e","-")) -> e | V12: =IF(OR(J12>2,N12>$C$3),IF(ABS(T12/I12)>0.1,"e","-"),"-") -> - | W12: =IF(U12="e",C12,"") -> 6 | X12: =IF(V12="e",C12,"")
C13: ='(2-2) 재직자 명부'!B8 -> 7 | D13: ='(2-2) 재직자 명부'!C8 -> 19730205 | E13: ='(2-2) 재직자 명부'!D8 -> 1 | F13: ='(2-2) 재직자 명부'!E8 -> 43282 | G13: ='(2-2) 재직자 명부'!F8 -> 6465480 | H13: ='(2-2) 재직자 명부'!G8 -> 48491100 | I13: ='(2-2) 재직자 명부'!H8 -> 0 | J13: ='(2-2) 재직자 명부'!I8 -> 1 | K13: ='(2-2) 재직자 명부'!J8 -> 0 | L13: =IF('(2-2) 재직자 명부'!M8="",1,'(2-2) 재직자 명부'!M8) -> 1 | M13: =IF('(2-2) 재직자 명부'!J8="","",LEFT('(2-2) 재직자 명부'!J8,4)&"-"&MID('(2-2) 재직자 명부'!J8,5,2)&"-"&RIGHT('(2-2) 재직자 명부'!J8,2)) | N13: =ROUNDDOWN(((LEFT($C$2,4)+(DATE(FALSE,MID($C$2,5,2),RIGHT($C$2,2))-1)/366)-((LEFT(D13,4)+(DATE(FALSE,MID(D13,5,2),RIGHT(D13,2))-1)/366))),0) -> 42 | O13: =((LEFT($C$2,4)+(DATE(FALSE,MID($C$2,5,2),RIGHT($C$2,2)))/366)-((LEFT(F13,4)+(DATE(FALSE,MID(F13,5,2),RIGHT(F13,2))-1)/366))) -> -2312.306 | P13: =IF(K13=0,"",((LEFT($C$2,4)+(DATE(FALSE,MID($C$2,5,2),RIGHT($C$2,2)))/366)-((LEFT(K13,4)+(DATE(FALSE,MID(K13,5,2),RIGHT(K13,2)))/366)))) | Q13: =IF(K13=0,O13*G13,G13*P13)*L13 -> -1.4950168e+10 | R13: =IF(K13=0,(O13+1)*G13,G13*(P13+1))*L13 -> -1.4943703e+10 | S13: =H13-Q13 -> 1.4998659e+10 | T13: =I13-R13 -> 1.4943703e+10 | U13: =IF(AND(J13<3,LEFT(F13,4)="2015"),"-",IF(ABS(S13/H13)>0.1,"e","-")) -> e | V13: =IF(OR(J13>2,N13>$C$3),IF(ABS(T13/I13)>0.1,"e","-"),"-") -> - | W13: =IF(U13="e",C13,"") -> 7 | X13: =IF(V13="e",C13,"")
C14: ='(2-2) 재직자 명부'!B9 -> 8 | D14: ='(2-2) 재직자 명부'!C9 -> 19860403 | E14: ='(2-2) 재직자 명부'!D9 -> 1 | F14: ='(2-2) 재직자 명부'!E9 -> 43997 | G14: ='(2-2) 재직자 명부'!F9 -> 4780400 | H14: ='(2-2) 재직자 명부'!G9 -> 26514850 | I14: ='(2-2) 재직자 명부'!H9 -> 0 | J14: ='(2-2) 재직자 명부'!I9 -> 1 | K14: ='(2-2) 재직자 명부'!J9 -> 0 | L14: =IF('(2-2) 재직자 명부'!M9="",1,'(2-2) 재직자 명부'!M9) -> 1 | M14: =IF('(2-2) 재직자 명부'!J9="","",LEFT('(2-2) 재직자 명부'!J9,4)&"-"&MID('(2-2) 재직자 명부'!J9,5,2)&"-"&RIGHT('(2-2) 재직자 명부'!J9,2)) | N14: =ROUNDDOWN(((LEFT($C$2,4)+(DATE(FALSE,MID($C$2,5,2),RIGHT($C$2,2))-1)/366)-((LEFT(D14,4)+(DATE(FALSE,MID(D14,5,2),RIGHT(D14,2))-1)/366))),0) -> 29 | O14: =((LEFT($C$2,4)+(DATE(FALSE,MID($C$2,5,2),RIGHT($C$2,2)))/366)-((LEFT(F14,4)+(DATE(FALSE,MID(F14,5,2),RIGHT(F14,2))-1)/366))) -> -2383.7596 | P14: =IF(K14=0,"",((LEFT($C$2,4)+(DATE(FALSE,MID($C$2,5,2),RIGHT($C$2,2)))/366)-((LEFT(K14,4)+(DATE(FALSE,MID(K14,5,2),RIGHT(K14,2)))/366)))) | Q14: =IF(K14=0,O14*G14,G14*P14)*L14 -> -1.1395324e+10 | R14: =IF(K14=0,(O14+1)*G14,G14*(P14+1))*L14 -> -1.1390544e+10 | S14: =H14-Q14 -> 1.1421839e+10 | T14: =I14-R14 -> 1.1390544e+10 | U14: =IF(AND(J14<3,LEFT(F14,4)="2015"),"-",IF(ABS(S14/H14)>0.1,"e","-")) -> e | V14: =IF(OR(J14>2,N14>$C$3),IF(ABS(T14/I14)>0.1,"e","-"),"-") -> - | W14: =IF(U14="e",C14,"") -> 8 | X14: =IF(V14="e",C14,"")
C15: ='(2-2) 재직자 명부'!B10 -> 9 | D15: ='(2-2) 재직자 명부'!C10 -> 19720823 | E15: ='(2-2) 재직자 명부'!D10 -> 1 | F15: ='(2-2) 재직자 명부'!E10 -> 35202 | G15: ='(2-2) 재직자 명부'!F10 -> 7846620 | H15: ='(2-2) 재직자 명부'!G10 -> 232451640 | I15: ='(2-2) 재직자 명부'!H10 -> 0 | J15: ='(2-2) 재직자 명부'!I10 -> 1 | K15: ='(2-2) 재직자 명부'!J10 -> 0 | L15: =IF('(2-2) 재직자 명부'!M10="",1,'(2-2) 재직자 명부'!M10) -> 1 | M15: =IF('(2-2) 재직자 명부'!J10="","",LEFT('(2-2) 재직자 명부'!J10,4)&"-"&MID('(2-2) 재직자 명부'!J10,5,2)&"-"&RIGHT('(2-2) 재직자 명부'!J10,2)) | N15: =ROUNDDOWN(((LEFT($C$2,4)+(DATE(FALSE,MID($C$2,5,2),RIGHT($C$2,2))-1)/366)-((LEFT(D15,4)+(DATE(FALSE,MID(D15,5,2),RIGHT(D15,2))-1)/366))),0) -> 43 | O15: =((LEFT($C$2,4)+(DATE(FALSE,MID($C$2,5,2),RIGHT($C$2,2)))/366)-((LEFT(F15,4)+(DATE(FALSE,MID(F15,5,2),RIGHT(F15,2))-1)/366))) -> -1504.0874 | P15: =IF(K15=0,"",((LEFT($C$2,4)+(DATE(FALSE,MID($C$2,5,2),RIGHT($C$2,2)))/366)-((LEFT(K15,4)+(DATE(FALSE,MID(K15,5,2),RIGHT(K15,2)))/366)))) | Q15: =IF(K15=0,O15*G15,G15*P15)*L15 -> -1.1802003e+10 | R15: =IF(K15=0,(O15+1)*G15,G15*(P15+1))*L15 -> -1.1794156e+10 | S15: =H15-Q15 -> 1.2034454e+10 | T15: =I15-R15 -> 1.1794156e+10 | U15: =IF(AND(J15<3,LEFT(F15,4)="2015"),"-",IF(ABS(S15/H15)>0.1,"e","-")) -> e | V15: =IF(OR(J15>2,N15>$C$3),IF(ABS(T15/I15)>0.1,"e","-"),"-") -> - | W15: =IF(U15="e",C15,"") -> 9 | X15: =IF(V15="e",C15,"")
C16: ='(2-2) 재직자 명부'!B11 -> 10 | D16: ='(2-2) 재직자 명부'!C11 -> 19760126 | E16: ='(2-2) 재직자 명부'!D11 -> 1 | F16: ='(2-2) 재직자 명부'!E11 -> 36557 | G16: ='(2-2) 재직자 명부'!F11 -> 6783220 | H16: ='(2-2) 재직자 명부'!G11 -> 175798460 | I16: ='(2-2) 재직자 명부'!H11 -> 0 | J16: ='(2-2) 재직자 명부'!I11 -> 1 | K16: ='(2-2) 재직자 명부'!J11 -> 0 | L16: =IF('(2-2) 재직자 명부'!M11="",1,'(2-2) 재직자 명부'!M11) -> 1 | M16: =IF('(2-2) 재직자 명부'!J11="","",LEFT('(2-2) 재직자 명부'!J11,4)&"-"&MID('(2-2) 재직자 명부'!J11,5,2)&"-"&RIGHT('(2-2) 재직자 명부'!J11,2)) | N16: =ROUNDDOWN(((LEFT($C$2,4)+(DATE(FALSE,MID($C$2,5,2),RIGHT($C$2,2))-1)/366)-((LEFT(D16,4)+(DATE(FALSE,MID(D16,5,2),RIGHT(D16,2))-1)/366))),0) -> 39 | O16: =((LEFT($C$2,4)+(DATE(FALSE,MID($C$2,5,2),RIGHT($C$2,2)))/366)-((LEFT(F16,4)+(DATE(FALSE,MID(F16,5,2),RIGHT(F16,2))-1)/366))) -> -1639.6503 | P16: =IF(K16=0,"",((LEFT($C$2,4)+(DATE(FALSE,MID($C$2,5,2),RIGHT($C$2,2)))/366)-((LEFT(K16,4)+(DATE(FALSE,MID(K16,5,2),RIGHT(K16,2)))/366)))) | Q16: =IF(K16=0,O16*G16,G16*P16)*L16 -> -1.1122109e+10 | R16: =IF(K16=0,(O16+1)*G16,G16*(P16+1))*L16 -> -1.1115325e+10 | S16: =H16-Q16 -> 1.1297907e+10 | T16: =I16-R16 -> 1.1115325e+10 | U16: =IF(AND(J16<3,LEFT(F16,4)="2015"),"-",IF(ABS(S16/H16)>0.1,"e","-")) -> e | V16: =IF(OR(J16>2,N16>$C$3),IF(ABS(T16/I16)>0.1,"e","-"),"-") -> - | W16: =IF(U16="e",C16,"") -> 10 | X16: =IF(V16="e",C16,"")
C17: ='(2-2) 재직자 명부'!B12 -> 11 | D17: ='(2-2) 재직자 명부'!C12 -> 19670727 | E17: ='(2-2) 재직자 명부'!D12 -> 1 | F17: ='(2-2) 재직자 명부'!E12 -> 36825 | G17: ='(2-2) 재직자 명부'!F12 -> 6564940 | H17: ='(2-2) 재직자 명부'!G12 -> 165325580 | I17: ='(2-2) 재직자 명부'!H12 -> 0 | J17: ='(2-2) 재직자 명부'!I12 -> 1 | K17: ='(2-2) 재직자 명부'!J12 -> 0 | L17: =IF('(2-2) 재직자 명부'!M12="",1,'(2-2) 재직자 명부'!M12) -> 1 | M17: =IF('(2-2) 재직자 명부'!J12="","",LEFT('(2-2) 재직자 명부'!J12,4)&"-"&MID('(2-2) 재직자 명부'!J12,5,2)&"-"&RIGHT('(2-2) 재직자 명부'!J12,2)) | N17: =ROUNDDOWN(((LEFT($C$2,4)+(DATE(FALSE,MID($C$2,5,2),RIGHT($C$2,2))-1)/366)-((LEFT(D17,4)+(DATE(FALSE,MID(D17,5,2),RIGHT(D17,2))-1)/366))),0) -> 48 | O17: =((LEFT($C$2,4)+(DATE(FALSE,MID($C$2,5,2),RIGHT($C$2,2)))/366)-((LEFT(F17,4)+(DATE(FALSE,MID(F17,5,2),RIGHT(F17,2))-1)/366))) -> -1666.3962 | P17: =IF(K17=0,"",((LEFT($C$2,4)+(DATE(FALSE,MID($C$2,5,2),RIGHT($C$2,2)))/366)-((LEFT(K17,4)+(DATE(FALSE,MID(K17,5,2),RIGHT(K17,2)))/366)))) | Q17: =IF(K17=0,O17*G17,G17*P17)*L17 -> -1.0939791e+10 | R17: =IF(K17=0,(O17+1)*G17,G17*(P17+1))*L17 -> -1.0933226e+10 | S17: =H17-Q17 -> 1.1105116e+10 | T17: =I17-R17 -> 1.0933226e+10 | U17: =IF(AND(J17<3,LEFT(F17,4)="2015"),"-",IF(ABS(S17/H17)>0.1,"e","-")) -> e | V17: =IF(OR(J17>2,N17>$C$3),IF(ABS(T17/I17)>0.1,"e","-"),"-") -> - | W17: =IF(U17="e",C17,"") -> 11 | X17: =IF(V17="e",C17,"")
C18: ='(2-2) 재직자 명부'!B13 -> 12 | D18: ='(2-2) 재직자 명부'!C13 -> 19800220 | E18: ='(2-2) 재직자 명부'!D13 -> 1 | F18: ='(2-2) 재직자 명부'!E13 -> 37902 | G18: ='(2-2) 재직자 명부'!F13 -> 6476000 | H18: ='(2-2) 재직자 명부'!G13 -> 143977160 | I18: ='(2-2) 재직자 명부'!H13 -> 0 | J18: ='(2-2) 재직자 명부'!I13 -> 1 | K18: ='(2-2) 재직자 명부'!J13 -> 0 | L18: =IF('(2-2) 재직자 명부'!M13="",1,'(2-2) 재직자 명부'!M13) -> 1 | M18: =IF('(2-2) 재직자 명부'!J13="","",LEFT('(2-2) 재직자 명부'!J13,4)&"-"&MID('(2-2) 재직자 명부'!J13,5,2)&"-"&RIGHT('(2-2) 재직자 명부'!J13,2)) | N18: =ROUNDDOWN(((LEFT($C$2,4)+(DATE(FALSE,MID($C$2,5,2),RIGHT($C$2,2))-1)/366)-((LEFT(D18,4)+(DATE(FALSE,MID(D18,5,2),RIGHT(D18,2))-1)/366))),0) -> 35 | O18: =((LEFT($C$2,4)+(DATE(FALSE,MID($C$2,5,2),RIGHT($C$2,2)))/366)-((LEFT(F18,4)+(DATE(FALSE,MID(F18,5,2),RIGHT(F18,2))-1)/366))) -> -1774.0874 | P18: =IF(K18=0,"",((LEFT($C$2,4)+(DATE(FALSE,MID($C$2,5,2),RIGHT($C$2,2)))/366)-((LEFT(K18,4)+(DATE(FALSE,MID(K18,5,2),RIGHT(K18,2)))/366)))) | Q18: =IF(K18=0,O18*G18,G18*P18)*L18 -> -1.148899e+10 | R18: =IF(K18=0,(O18+1)*G18,G18*(P18+1))*L18 -> -1.1482514e+10 | S18: =H18-Q18 -> 1.1632967e+10 | T18: =I18-R18 -> 1.1482514e+10 | U18: =IF(AND(J18<3,LEFT(F18,4)="2015"),"-",IF(ABS(S18/H18)>0.1,"e","-")) -> e | V18: =IF(OR(J18>2,N18>$C$3),IF(ABS(T18/I18)>0.1,"e","-"),"-") -> - | W18: =IF(U18="e",C18,"") -> 12 | X18: =IF(V18="e",C18,"")
C19: ='(2-2) 재직자 명부'!B14 -> 13 | D19: ='(2-2) 재직자 명부'!C14 -> 19811219 | E19: ='(2-2) 재직자 명부'!D14 -> 1 | F19: ='(2-2) 재직자 명부'!E14 -> 39143 | G19: ='(2-2) 재직자 명부'!F14 -> 6594780 | H19: ='(2-2) 재직자 명부'!G14 -> 124194170 | I19: ='(2-2) 재직자 명부'!H14 -> 0 | J19: ='(2-2) 재직자 명부'!I14 -> 1 | K19: ='(2-2) 재직자 명부'!J14 -> 0 | L19: =IF('(2-2) 재직자 명부'!M14="",1,'(2-2) 재직자 명부'!M14) -> 1 | M19: =IF('(2-2) 재직자 명부'!J14="","",LEFT('(2-2) 재직자 명부'!J14,4)&"-"&MID('(2-2) 재직자 명부'!J14,5,2)&"-"&RIGHT('(2-2) 재직자 명부'!J14,2)) | N19: =ROUNDDOWN(((LEFT($C$2,4)+(DATE(FALSE,MID($C$2,5,2),RIGHT($C$2,2))-1)/366)-((LEFT(D19,4)+(DATE(FALSE,MID(D19,5,2),RIGHT(D19,2))-1)/366))),0) -> 34 | O19: =((LEFT($C$2,4)+(DATE(FALSE,MID($C$2,5,2),RIGHT($C$2,2)))/366)-((LEFT(F19,4)+(DATE(FALSE,MID(F19,5,2),RIGHT(F19,2))-1)/366))) -> -1898.2787 | P19: =IF(K19=0,"",((LEFT($C$2,4)+(DATE(FALSE,MID($C$2,5,2),RIGHT($C$2,2)))/366)-((LEFT(K19,4)+(DATE(FALSE,MID(K19,5,2),RIGHT(K19,2)))/366)))) | Q19: =IF(K19=0,O19*G19,G19*P19)*L19 -> -1.251873e+10 | R19: =IF(K19=0,(O19+1)*G19,G19*(P19+1))*L19 -> -1.2512136e+10 | S19: =H19-Q19 -> 1.2642924e+10 | T19: =I19-R19 -> 1.2512136e+10 | U19: =IF(AND(J19<3,LEFT(F19,4)="2015"),"-",IF(ABS(S19/H19)>0.1,"e","-")) -> e | V19: =IF(OR(J19>2,N19>$C$3),IF(ABS(T19/I19)>0.1,"e","-"),"-") -> - | W19: =IF(U19="e",C19,"") -> 13 | X19: =IF(V19="e",C19,"")
... C416: ='(2-2) 재직자 명부'!B411 -> 0 | D416: ='(2-2) 재직자 명부'!C411 -> 0 | E416: ='(2-2) 재직자 명부'!D411 -> 0 | F416: ='(2-2) 재직자 명부'!E411 -> 0 | G416: ='(2-2) 재직자 명부'!F411 -> 0 | H416: ='(2-2) 재직자 명부'!G411 -> 0 | I416: ='(2-2) 재직자 명부'!H411 -> 0 | J416: ='(2-2) 재직자 명부'!I411 -> 0 | K416: ='(2-2) 재직자 명부'!J411 -> 0 | L416: =IF('(2-2) 재직자 명부'!M411="",1,'(2-2) 재직자 명부'!M411) -> 1 | M416: =IF('(2-2) 재직자 명부'!J411="","",LEFT('(2-2) 재직자 명부'!J411,4)&"-"&MID('(2-2) 재직자 명부'!J411,5,2)&"-"&RIGHT('(2-2) 재직자 명부'!J411,2)) | N416: =ROUNDDOWN(((LEFT($C$2,4)+(DATE(FALSE,MID($C$2,5,2),RIGHT($C$2,2))-1)/366)-((LEFT(D416,4)+(DATE(FALSE,MID(D416,5,2),RIGHT(D416,2))-1)/366))),0) -> #VALUE! | O416: =((LEFT($C$2,4)+(DATE(FALSE,MID($C$2,5,2),RIGHT($C$2,2)))/366)-((LEFT(F416,4)+(DATE(FALSE,MID(F416,5,2),RIGHT(F416,2))-1)/366))) -> #VALUE! | P416: =IF(K416=0,"",((LEFT($C$2,4)+(DATE(FALSE,MID($C$2,5,2),RIGHT($C$2,2)))/366)-((LEFT(K416,4)+(DATE(FALSE,MID(K416,5,2),RIGHT(K416,2)))/366)))) | Q416: =IF(K416=0,O416*G416,G416*P416)*L416 -> #VALUE! | R416: =IF(K416=0,(O416+1)*G416,G416*(P416+1))*L416 -> #VALUE! | S416: =H416-Q416 -> #VALUE! | T416: =I416-R416 -> #VALUE! | U416: =IF(AND(J416<3,LEFT(F416,4)="2015"),"-",IF(ABS(S416/H416)>0.1,"e","-")) -> #VALUE! | V416: =IF(OR(J416>2,N416>$C$3),IF(ABS(T416/I416)>0.1,"e","-"),"-") -> #VALUE! | W416: =IF(U416="e",C416,"") -> #VALUE! | X416: =IF(V416="e",C416,"") -> #VALUE!

Sheet (1-1) self-checklist
A1: 예
A2: 아니오
B3: ***작성 완료 후 최종 확인사항
B5: 기초자료와 명부 작성 완료 후 아래 표에서 최종확인 부탁드립니다.
B6: 아니오 선택 시, (1_2) 기초자료_퇴직급여와 명부 시트에서 해당사항 수정 부탁드립니다.
B8: 시트 | C8: # | D8: 항목 | E8: 확인 사항 | F8: 답변(드롭박스에서 선택)
B9: (1-2) 기초자료 _퇴직급여 | C9: 1 | D9: 사외적립자산 | E9: 회계 장부 반영 금액과 일치합니까? | F9: 예
C10: 2 | D10: 정년 | E10: ="정년은 만 "&'(1-2) 기초자료_퇴직급여 '!$F$103&" 세 입니까?" -> 정년은 만 60 세 입니까? | F10: 예
C11: 3 | D11: 임금피크제 | E11: =IF('(1-2) 기초자료_퇴직급여 '!$F$104="","임금피크제 적용 여부 선택 부탁드립니다",IF('(1-2) 기초자료_퇴직급여 '!$F$104="YES","만 "&'(1-2) 기초자료_퇴직급여 '!I104&"세 부터 임금피크제가 적용됩니까?","임금피크제 미적용 기업입니까?")) -> 만 58세 부터 임금피크제가 적용됩니까? | F11: 예
C12: 4 | D12: 기타장기종업원급여 | E12: =IF('(1-2) 기초자료_퇴직급여 '!F105="","기타장기종업원급여 적용 여부 선택 부탁드립니다","기타장기종업원급여 "&IF('(1-2) 기초자료_퇴직급여 '!$F$105="YES","적용","미적용")&" 기업입니까?") -> 기타장기종업원급여 적용 기업입니까? | F12: 예
C13: 5 | D13: 퇴직금제도 | E13: =IF('(1-2) 기초자료_퇴직급여 '!$F$108="","퇴직금제도 선택 부탁드립니다","퇴직금제도는 "&'(1-2) 기초자료_퇴직급여 '!$F$108&"를 적용합니까?") -> 퇴직금제도는 법정제를 적용합니까? | F13: 예
C14: 6 | D14: 연봉제/호봉제 | E14: =IF('(1-2) 기초자료_퇴직급여 '!$I$112="","임금체계 선택 부탁드립니다.",IF('(1-2) 기초자료_퇴직급여 '!$I$112="예 (호봉제)","근무기간에 따른 호봉 적용 기업 맞습니까?","근무기간에 따른 호봉 미적용 기업입니까?")) -> 근무기간에 따른 호봉 미적용 기업입니까? | F14: 예
C15: ='(2-2) 재직자 명부'!B9 -> 8 | D15: 채권등급 | E15: ="할인율 산출기준 채권 "&'(1-2) 기초자료_퇴직급여 '!$D$121&" 적용 기업입니까?" -> 할인율 산출기준 채권 회사채AA- 적용 기업입니까? | F15: 예
B16: (2-2) 재직자명부 | C16: 1 | D16: 1년 미만 재직자 | E16: 1년 미만 재직자도 기재 하셨습니까? | F16: 예
C17: 2 | D17: 퇴직금 추계액 | E17: 모든 재직자의 당년도, 차년도 퇴직금 추계액을 입력하셨습니까? (1년 미만 재직자의 경우 일할 계산) | F17: 아니오 | G17: 당년도 : 완료 / 차년도 : 임원, 계약직 완료
C18: 3 | D18: 기준급여 | E18: 3개월 미만 재직자의 경우 한달 근무 시 지급받는 급여로 기재 하셨습니까? | F18: 예
C19: 4 | D19: 평가기준일 퇴사자 | E19: 평가기준일 발생 퇴직금을 비용(미지급 포함) 처리 하셨습니까? | F19: 예
C20: 5 | D20: 평가기준일 퇴사자 | E20: =IF(F19="예","재직자명부에서 평가기준일 퇴사자 제외 하셨습니까?","비용처리 안하셨다면 1월 퇴사 처리 예정입니까?") -> 재직자명부에서 평가기준일 퇴사자 제외 하셨습니까? | F20: 예
C21: 6 | D21: 중간정산 대상자 | E21: 근퇴법 시행령 제3조에(퇴직금 중간정산 사유)에 해당됩니까? | F21: 예
B22: (2-3) 퇴직자명부 | C22: 1 | D22: 평가기준일 퇴사자 | E22: =IF(F19="예","퇴직자명부에 평가기준일 퇴사자를 포함하셨습니까?","퇴직자명부에서 평가기준일 퇴사자를 제외하셨습니까?") -> 퇴직자명부에 평가기준일 퇴사자를 포함하셨습니까? | F22: 예

Sheet (1-2) 기초자료_퇴직급여 
B2: (1-2) 퇴직급여채무 평가를 위한 기초자료
B4: * 근퇴법에서는 퇴직급여제도를 퇴직금제도, 퇴직연금제도(DB, DC, IRP)로 구분합니다.
B5: IFRS 퇴직급여채무평가 대상은 DC(IRP 포함)에 가입한 재직자를 제외한 전 종업원(1년 미만 근속자 포함)입니다.
B6: 따라서 기초자료, 재직자 및 퇴직자명부는 IFRS 퇴직급여채무평가 대상자에 한하여 작성하여 주시기 바랍니다.
B8: ☞ 퇴직금 또는 기타장기종업원급여의 지급규정 변경시 변경내용을 제공하여 주시기 바랍니다. (예 : 법정제 → 누진제 등, 장기근속포상금 변경 등)
B10: 1. 일반사항
B12: 회사명 | N12: =D12 -> 0
B13: 담당자 | N13: =D13 -> 0
B14: 전화번호 | N14: =D14 -> 0
B15: 이메일 | N15: =D15 -> 0
B16: 결산월 | D16: 12월 | N16: =D17 -> 0
B17: 주 소 | N17: =D16 -> 12월
B19: 2. 평가대상 및 퇴직급여 지급(환입) 현황
B21: ☞ DC형 퇴직연금가입자(IRP 포함)를 제외한 전 임직원을 기준으로 작성
B22: ☞ 금액은 모두 (+)로 기재 | J22: ☞ FALSE일 경우 명부와 자료 불일치. 확인 부탁드립니다.
B24: 항목 | D24: 내용 | J24: 기초자료 및 명부 일치여부 | K24: 비 고
D25: 작성기준일 | I25: 251231 | K25: 기초자료 및 명부 작성 기준일
B26: 평가 대상 | C26: 재직자수 (명) | D26: 임원 | F26: 0 | G26: 0 | H26: 0 | I26: 5 | J26: =COUNTIF('(2-2) 재직자 명부'!I:I,3)=I26 -> TRUE | K26: 작성기준일 현재 재직자 수 (2-2) 재직자 명부의 재직자 수와 일치 | N26: false일 경우 데이터 확인
D27: 직원 | F27: 0 | G27: 0 | H27: 0 | I27: 67 | J27: =COUNTIF('(2-2) 재직자 명부'!I:I,1)+COUNTIF('(2-2) 재직자 명부'!I:I,2)=I27 -> TRUE
D28: 계약직 | F28: 0 | G28: 0 | H28: 0 | I28: 14 | J28: =COUNTIF('(2-2) 재직자 명부'!I:I,4)=I28 -> TRUE
D29: 합계 | F29: =SUM(F26:F28) -> 0 | G29: =SUM(G26:G28) -> 0 | H29: =SUM(H26:H28) -> 0 | I29: =SUM(I26:I28) -> 86 | J29: =COUNTA('(2-2) 재직자 명부'!B2:B60000)=I29 -> TRUE
C30: 퇴직자수 (명) | D30: 임원 | F30: 0 | G30: 0 | H30: 0 | I30: 1 | J30: =COUNTIFS('(2-4) 퇴직자 및 DC전환자 명부'!I:I,1,'(2-4) 퇴직자 및 DC전환자 명부'!H:H,3)=I30 -> TRUE | K30: 기초부터 누계 퇴직자 수 (2-3) 퇴직자 명부의 퇴직자 수와 일치
D31: 직원 | F31: 0 | G31: 0 | H31: 0 | I31: 8 | J31: =COUNTIFS('(2-4) 퇴직자 및 DC전환자 명부'!I:I,1,'(2-4) 퇴직자 및 DC전환자 명부'!H:H,1)+COUNTIFS('(2-4) 퇴직자 및 DC전환자 명부'!I:I,1,'(2-4) 퇴직자 및 DC전환자 명부'!H:H,2)=I31 -> TRUE
D32: 계약직 | F32: 0 | G32: 0 | H32: 0 | I32: 1 | J32: =COUNTIFS('(2-4) 퇴직자 및 DC전환자 명부'!I:I,1,'(2-4) 퇴직자 및 DC전환자 명부'!H:H,4)=I32 -> TRUE
D33: 합계 | F33: =SUM(F30:F32) -> 0 | G33: =SUM(G30:G32) -> 0 | H33: =SUM(H30:H32) -> 0 | I33: =SUM(I30:I32) -> 10 | J33: =COUNTIF('(2-4) 퇴직자 및 DC전환자 명부'!I:I,1)=I33 -> TRUE
C34: 중간정산자수 | D34: =SUM(IFERROR(YEAR('(2-2) 재직자 명부'!J:J)=2016,0)*1) -> 0 | E34: =SUM((LEFT('(2-2) 재직자 명부'!$J:$J,4)="2016")*1) -> 0 | F34: 0 | G34: 0 | H34: 0 | I34: 0 | J34: =I34=(E34+D34) -> TRUE | K34: 기초부터 누계 중간정산자 수 (2-2) 재직자 명부의 당기 중간정산자 수와 일치
C35: DC전환자수 | F35: 0 | G35: 0 | H35: 0 | I35: 3 | J35: =COUNTIF('(2-4) 퇴직자 및 DC전환자 명부'!I:I,2)=I35 -> TRUE | K35: 기초부터 누계 DC전환자 수 (2-3) DC전환자 명부의 DC전환자 수와 일치
B36: 퇴직금 추계액 (원) | D36: 임원 | F36: 0 | G36: 0 | H36: 0 | I36: 8871140000 | J36: =ABS(SUMIF('(2-2) 재직자 명부'!I:I,3,'(2-2) 재직자 명부'!G:G)-I36)<1 -> TRUE | K36: 작성기준일 현재 퇴직금 추계액 (2-2) 재직자 명부의 당년도 퇴직금추계액과 일치
D37: 직원 | F37: 0 | G37: 0 | H37: 0 | I37: 4326514630 | J37: =ABS(SUMIF('(2-2) 재직자 명부'!I:I,1,'(2-2) 재직자 명부'!G:G)+SUMIF('(2-2) 재직자 명부'!I:I,2,'(2-2) 재직자 명부'!G:G)-I37)<1 -> TRUE
D38: 계약직 | F38: 0 | G38: 0 | H38: 0 | I38: 245458190 | J38: =ABS(SUMIF('(2-2) 재직자 명부'!I:I,4,'(2-2) 재직자 명부'!G:G)-I38)<1 -> TRUE
D39: 합계 | F39: =SUM(F36:F38) -> 0 | G39: =SUM(G36:G38) -> 0 | H39: =SUM(H36:H38) -> 0 | I39: =SUM(I36:I38) -> 13443112820 | J39: =ABS(SUM('(2-2) 재직자 명부'!G:G)-I39)<1 -> TRUE
B41: 퇴직부채 감소 (증가)액(원) | C41: 급여지급액 (A) | D41: 퇴직금 (a) | F41: 0 | G41: 0 | H41: 0 | I41: 206210860 | J41: =ABS(SUMIF('(2-4) 퇴직자 및 DC전환자 명부'!I:I,1,'(2-4) 퇴직자 및 DC전환자 명부'!G:G)-I41)<1 -> TRUE | K41: 기초부터 누계 퇴직금 지급액(퇴직급여충당금 감소 처리) (2-3) 퇴직자 명부의 퇴직금 합계와 일치 | N41: false일 경우 데이터 확인
D42: 중간정산금액 (b) | F42: 0 | G42: 0 | H42: 0 | I42: 0 | J42: =ABS((K44+L44)-I42)<1 -> TRUE | K42: 기초부터 누계 중간정산금액(퇴직급여충당금 감소 처리) (2-2) 재직자 명부의 중간정산액 합계와 일치
D43: DC 전환금 (c) | F43: 0 | G43: 0 | H43: 0 | I43: 255706880 | J43: =ABS(SUMIF('(2-4) 퇴직자 및 DC전환자 명부'!I:I,2,'(2-4) 퇴직자 및 DC전환자 명부'!G:G)-I43)<1 -> TRUE | K43: 기초부터 누계 DC전환금액(퇴직급여충당금 감소 처리) (2-3) DC전환자 명부의 DC전환금 합계와 일치
D44: 소계 (a+b+c) | F44: =SUM(F41:F43) -> 0 | G44: =SUM(G41:G43) -> 0 | H44: =SUM(H41:H43) -> 0 | I44: =SUM(I41:I43) -> 461917740 | J44: =ABS((SUM('(2-4) 퇴직자 및 DC전환자 명부'!G:G)+I42)-I44)<1 -> TRUE | K44: =SUMIFS('(2-2) 재직자 명부'!K:K,'(2-2) 재직자 명부'!J:J,">10000000",'(2-2) 재직자 명부'!J:J,">"&LEFT(I25,4)&"0000") -> 0 | L44: =SUMIFS('(2-2) 재직자 명부'!K:K,'(2-2) 재직자 명부'!J:J,"<10000000",'(2-2) 재직자 명부'!J:J,">="&DATE(LEFT(I25,4),1,1)) -> 0
C45: 관계사전입(전출)액 (B) | D45: 관계사 전입액 (d) | F45: 0 | G45: 0 | H45: 0 | I45: 0 | J45: =ABS(SUMIF('(2-5) 추가 명부'!J:J,1,'(2-5) 추가 명부'!G:G)-I45)<1 -> TRUE | K45: 기초부터 누계 관계사 전입(전출)액 (2-4) 추가 명부의 관계사 전입(전출)액 합계와 일치
D46: 관계사 전출액 (e) | F46: 0 | G46: 0 | H46: 0 | I46: 0 | J46: =ABS(SUMIF('(2-5) 추가 명부'!J:J,2,'(2-5) 추가 명부'!G:G)-I46)<1 -> TRUE
