Workbook

Sheet (1-2) 기초자료_퇴직급여 
B2: (1-2) 퇴직급여채무 평가를 위한 기초자료
B4: * 근퇴법에서는 퇴직급여제도를 퇴직금제도, 퇴직연금제도(DB, DC, IRP)로 구분합니다.
B5: IFRS 퇴직급여채무평가 대상은 DC(IRP 포함)에 가입한 재직자를 제외한 전 종업원(1년 미만 근속자 포함)입니다.
B6: 따라서 기초자료, 재직자 및 퇴직자명부는 IFRS 퇴직급여채무평가 대상자에 한하여 작성하여 주시기 바랍니다.
B8: ☞ 퇴직금 또는 기타장기종업원급여의 지급규정 변경시 변경내용을 제공하여 주시기 바랍니다. (예 : 법정제 → 누진제 등, 장기근속포상금 변경 등)
B10: 1. 일반사항
B12: 회사명 | N12: =D12 -> 0
B13: 담당자 | N13: =D13 -> 0
B14: 전화번호 | N14: =D14 -> 0
B15: 이메일 | N15: =D15 -> 0
B16: 결산월 | D16: 2022.12월말 | N16: =D17 -> 0
B17: 주 소 | N17: =D16 -> 2022.12월말
B19: 2. 평가대상 및 퇴직급여 지급(환입) 현황
B21: ☞ DC형 퇴직연금가입자(IRP 포함)를 제외한 전 임직원을 기준으로 작성
B22: ☞ 금액은 모두 (+)로 기재 | J22: ☞ FALSE일 경우 명부와 자료 불일치. 확인 부탁드립니다.
B24: 항목 | D24: 내용 | J24: 기초자료 및 명부 일치여부 | K24: 비 고
D25: 작성기준일 | F25: 2022.03.31 | G25: 2022.06.30 | H25: 2022.09.30 | I25: 2022.12.31 | K25: 기초자료 및 명부 작성 기준일
B26: 평가 대상 | C26: 재직자수 (명) | D26: 임원 | F26: 13 | G26: 16 | H26: 16 | I26: =COUNTIF('(2-2) 재직자 명부'!$I:$I,3) -> 16 | J26: =COUNTIF('(2-2) 재직자 명부'!I:I,3)=I26 -> TRUE | K26: 작성기준일 현재 재직자 수 (2-2) 재직자 명부의 재직자 수와 일치 | N26: false일 경우 데이터 확인
D27: 직원 | F27: 293 | G27: 304 | H27: 304 | I27: =COUNTIF('(2-2) 재직자 명부'!$I:$I,1) -> 312 | J27: =COUNTIF('(2-2) 재직자 명부'!I:I,1)+COUNTIF('(2-2) 재직자 명부'!I:I,2)=I27 -> TRUE
D28: 계약직 | F28: 83 | G28: 77 | H28: 75 | I28: =COUNTIF('(2-2) 재직자 명부'!$I:$I,4) -> 70 | J28: =COUNTIF('(2-2) 재직자 명부'!I:I,4)=I28 -> TRUE
D29: 합계 | F29: =SUM(F26:F28) -> 389 | G29: =SUM(G26:G28) -> 397 | H29: =SUM(H26:H28) -> 395 | I29: =SUM(I26:I28) -> 398 | J29: =COUNTA('(2-2) 재직자 명부'!B2:B59779)=I29 -> TRUE
C30: 퇴직자수 (명) | D30: 임원 | F30: 0 | G30: 0 | H30: 0 | I30: =COUNTIFS('(2-3) 퇴직자 및 DC전환자 명부'!H:H,3,'(2-3) 퇴직자 및 DC전환자 명부'!I:I,1) -> 0 | J30: =COUNTIFS('(2-3) 퇴직자 및 DC전환자 명부'!I:I,1,'(2-3) 퇴직자 및 DC전환자 명부'!H:H,3)=I30 -> TRUE | K30: 기초부터 누계 퇴직자 수 (2-3) 퇴직자 명부의 퇴직자 수와 일치
D31: 직원 | F31: 6 | G31: 8 | H31: 18 | I31: =COUNTIFS('(2-3) 퇴직자 및 DC전환자 명부'!H:H,1,'(2-3) 퇴직자 및 DC전환자 명부'!I:I,1) -> 17 | J31: =COUNTIFS('(2-3) 퇴직자 및 DC전환자 명부'!I:I,1,'(2-3) 퇴직자 및 DC전환자 명부'!H:H,1)+COUNTIFS('(2-3) 퇴직자 및 DC전환자 명부'!I:I,1,'(2-3) 퇴직자 및 DC전환자 명부'!H:H,2)=I31 -> TRUE
D32: 계약직 | F32: 3 | G32: 7 | H32: 6 | I32: =COUNTIFS('(2-3) 퇴직자 및 DC전환자 명부'!H:H,4,'(2-3) 퇴직자 및 DC전환자 명부'!I:I,1) -> 7 | J32: =COUNTIFS('(2-3) 퇴직자 및 DC전환자 명부'!I:I,1,'(2-3) 퇴직자 및 DC전환자 명부'!H:H,4)=I32 -> TRUE
D33: 합계 | F33: =SUM(F30:F32) -> 9 | G33: =SUM(G30:G32) -> 15 | H33: =SUM(H30:H32) -> 24 | I33: =SUM(I30:I32) -> 24 | J33: =COUNTIF('(2-3) 퇴직자 및 DC전환자 명부'!I:I,1)=I33 -> TRUE
C34: 중간정산자수 | D34: =SUM(IFERROR(YEAR('(2-2) 재직자 명부'!J:J)=2019,0)*1) -> 0 | E34: =SUM((LEFT('(2-2) 재직자 명부'!$J:$J,4)="2019")*1) -> 0 | F34: 0 | G34: 0 | H34: 0 | I34: 0 | J34: =I34=(E34+D34) -> TRUE | K34: 기초부터 누계 중간정산자 수 (2-2) 재직자 명부의 당기 중간정산자 수와 일치
C35: DC전환자수 | F35: 0 | G35: 1 | H35: 2 | I35: =COUNTIFS('(2-3) 퇴직자 및 DC전환자 명부'!I:I,2) -> 1 | J35: =COUNTIF('(2-3) 퇴직자 및 DC전환자 명부'!I:I,2)=I35 -> TRUE | K35: 기초부터 누계 DC전환자 수 (2-3) DC전환자 명부의 DC전환자 수와 일치
B36: 퇴직금 추계액 (원) | D36: 임원 | F36: 2435613441 | G36: 3010179171 | H36: 3261641278 | I36: =SUMIF('(2-2) 재직자 명부'!$I:$I,3,'(2-2) 재직자 명부'!$G:$G) -> 3202123846 | J36: =ABS(SUMIF('(2-2) 재직자 명부'!I:I,3,'(2-2) 재직자 명부'!G:G)-I36)<1 -> TRUE | K36: 작성기준일 현재 퇴직금 추계액 (2-2) 재직자 명부의 당년도 퇴직금추계액과 일치
D37: 직원 | F37: 11542829564 | G37: 11925538571 | H37: 12126543815 | I37: =SUMIF('(2-2) 재직자 명부'!$I:$I,1,'(2-2) 재직자 명부'!$G:$G) -> 12557562547 | J37: =ABS(SUMIF('(2-2) 재직자 명부'!I:I,1,'(2-2) 재직자 명부'!G:G)+SUMIF('(2-2) 재직자 명부'!I:I,2,'(2-2) 재직자 명부'!G:G)-I37)<1 -> TRUE
D38: 계약직 | F38: 390452239 | G38: 384338643 | H38: 421228414 | I38: =SUMIF('(2-2) 재직자 명부'!$I:$I,4,'(2-2) 재직자 명부'!$G:$G) -> 354336017 | J38: =ABS(SUMIF('(2-2) 재직자 명부'!I:I,4,'(2-2) 재직자 명부'!G:G)-I38)<1 -> TRUE
D39: 합계 | F39: =SUM(F36:F38) -> 14368895244 | G39: =SUM(G36:G38) -> 15320056385 | H39: =SUM(H36:H38) -> 15809413507 | I39: =SUM(I36:I38) -> 16114022410 | J39: =ABS(SUM('(2-2) 재직자 명부'!G:G)-I39)<1 -> TRUE
B41: 퇴직부채 감소 (증가)액(원) | C41: 급여지급액 (A) | D41: 퇴직금 (a) | F41: 221134697 | G41: 173384916 | H41: 317036975 | I41: =SUMIF('(2-3) 퇴직자 및 DC전환자 명부'!I:I,1,'(2-3) 퇴직자 및 DC전환자 명부'!$G:$G)-I46 -> 598774099 | J41: =ABS(SUMIF('(2-3) 퇴직자 및 DC전환자 명부'!I:I,1,'(2-3) 퇴직자 및 DC전환자 명부'!G:G)-I41)<1 -> FALSE | K41: 기초부터 누계 퇴직금 지급액(퇴직급여충당금 감소 처리) (2-3) 퇴직자 명부의 퇴직금 합계와 일치 | N41: false일 경우 데이터 확인
D42: 중간정산금액 (b) | F42: 0 | G42: 0 | H42: 0 | I42: =SUM('(2-2) 재직자 명부'!K:K) -> 290723981 | J42: =ABS((K44+L44)-I42)<1 -> TRUE | K42: 기초부터 누계 중간정산금액(퇴직급여충당금 감소 처리) (2-2) 재직자 명부의 중간정산액 합계와 일치
D43: DC 전환금 (c) | F43: 0 | G43: 14495996 | H43: 70635323 | I43: =SUMIF('(2-3) 퇴직자 및 DC전환자 명부'!I:I,2,'(2-3) 퇴직자 및 DC전환자 명부'!$G:$G) -> 206697360 | J43: =ABS(SUMIF('(2-3) 퇴직자 및 DC전환자 명부'!I:I,2,'(2-3) 퇴직자 및 DC전환자 명부'!G:G)-I43)<1 -> TRUE | K43: 기초부터 누계 DC전환금액(퇴직급여충당금 감소 처리) (2-3) DC전환자 명부의 DC전환금 합계와 일치
D44: 소계 (a+b+c) | F44: =SUM(F41:F43) -> 221134697 | G44: =SUM(G41:G43) -> 187880912 | H44: =SUM(H41:H43) -> 387672298 | I44: =SUM(I41:I43) -> 1096195440 | J44: =ABS((SUM('(2-3) 퇴직자 및 DC전환자 명부'!G:G)+I42)-I44)<1 -> FALSE | K44: =SUMIFS('(2-2) 재직자 명부'!K:K,'(2-2) 재직자 명부'!J:J,">10000000",'(2-2) 재직자 명부'!J:J,">"&LEFT(I25,4)&"0000") -> 0 | L44: =SUMIFS('(2-2) 재직자 명부'!K:K,'(2-2) 재직자 명부'!J:J,"<10000000",'(2-2) 재직자 명부'!J:J,">="&DATE(LEFT(I25,4),1,1)) -> 290723981
C45: 관계사전입(전출)액 (B) | D45: 관계사 전입액 (d) | F45: 0 | G45: 0 | H45: 0 | I45: =SUMIF('(2-4) 추가 명부(장기근속)'!$J:$J,1,'(2-4) 추가 명부(장기근속)'!$G:$G) -> 0 | J45: =ABS(SUMIF('(2-4) 추가 명부(장기근속)'!J:J,1,'(2-4) 추가 명부(장기근속)'!G:G)-I45)<1 -> TRUE | K45: 기초부터 누계 관계사 전입(전출)액 (2-4) 추가 명부의 관계사 전입(전출)액 합계와 일치
D46: 관계사 전출액 (e) | F46: 0 | G46: 0 | H46: 0 | I46: 8737780 | J46: =ABS(SUMIF('(2-4) 추가 명부(장기근속)'!J:J,2,'(2-4) 추가 명부(장기근속)'!G:G)-I46)<1 -> FALSE
D47: 소계 (d-e) | F47: =F45-F46 -> 0 | G47: =G45-G46 -> 0 | H47: =H45-H46 -> 0 | I47: =I45-I46 -> -8737780 | J47: =ABS((SUMIF('(2-4) 추가 명부(장기근속)'!J:J,1,'(2-4) 추가 명부(장기근속)'!G:G)-SUMIF('(2-4) 추가 명부(장기근속)'!J:J,2,'(2-4) 추가 명부(장기근속)'!G:G))-I47)<1 -> FALSE
C48: 사업결합(처분)액 (C) | D48: 사업결합액 (f) | F48: 0 | G48: 0 | H48: 0 | I48: =+SUMIF('(2-4) 추가 명부(장기근속)'!$J:$J,3,'(2-4) 추가 명부(장기근속)'!$G:$G) -> 0 | J48: =ABS(SUMIF('(2-4) 추가 명부(장기근속)'!J:J,3,'(2-4) 추가 명부(장기근속)'!G:G)-I48)<1 -> TRUE | K48: 기초부터 누계 사업결합(처분)액 (2-4) 추가 명부의 사업결합(처분) 금액 합계와 일치
D49: 사업처분액 (g) | F49: 0 | G49: 0 | H49: 0 | I49: =+SUMIF('(2-4) 추가 명부(장기근속)'!$J:$J,4,'(2-4) 추가 명부(장기근속)'!$G:$G) -> 0 | J49: =ABS(SUMIF('(2-4) 추가 명부(장기근속)'!J:J,4,'(2-4) 추가 명부(장기근속)'!G:G)-I49)<1 -> TRUE
...

Sheet (1-3) 기초자료_기타장기종업원급여
B2: (1-3) 기타장기종업원급여채무 평가를 위한 기초자료
B4: 1. 기타장기종업원급여 지급규정
B5: - 관련규정을 다음과 같이 요약하여 주시기 바랍니다.
B6: - 아래 양식 이외에 필요한 정보가 있으면 양식에 추가하여 작성하여 주시기 바랍니다.
B7: - 아래의 표는 예시로 작성된 것이며, 귀사의 규정에 맞게 수정하여 주시면 됩니다.
B9: 근속년수 | C9: 포상금 | F9: 포상휴가
C10: 급여기준 | E10: 현물기준
C11: 지급율(월할기본연봉 X 직무그룹별 지급률)
C12: 기획관리/운영지원그룹 | D12: 영업관리그룹
B13: 5년 | E13: 10만원상당 상품권 | F13: -
B14: 10년 | C14: 0.19 | D14: 0.2 | E14: 금1돈 | F14: 3일
B15: 15년 | C15: 0.32 | D15: 0.335 | E15: 금5돈 | F15: 5일
B16: 20년 | C16: 0.445 | D16: 0.47 | E16: 금10돈 | F16: 7일
B17: 25년 | C17: 0.635 | D17: 0.67 | E17: 금15돈 | F17: 10일
B18: 30년 | C18: 0.95 | D18: 1.005 | E18: 금20돈 | F18: 15일
B19: * 12/31 기준, 한국조폐공사 국제금시세 기준(1돈당시세)
B22: 2. 기타장기종업원급여 지급내역 (최근 3년)
B23: - 아래 양식이 적합하지 않으면 양식을 변경하여 작성하여 주시기 바랍니다.
B24: - 인원은 명, 금액은 원입니다. 단위를 확인하여 주시기 바랍니다.
B25: - 과거 3년 동안, 연도별 지급내역을 기록하여 주십시오 (기간은 회사가 비용으로 처리한 날짜 기준입니다)
B26: - 아래의 표는 예시로 작성된 것이며, 예시를 참고로 하여 귀사의 실제 지급내역을 입력해 주시기 바랍니다.
B28: <작성방법>
B29: ① 근속자(명) | C29: 해당인원 수 기재
B30: ② 장기근속 축하금 | C30: 실적 발생금액 합계
B31: ③ 세부내역 | C31: 포인트, 현금, 실물(금, 또는 여행권) 지급 여부 기재
B33: 평가기준일 직전 1년 (2022.1.1~2022.12.31)
B34: 근속년수 | C34: 근속자(명) | D34: 장기근속축하금(합계, 원) | E34: 세부 내역
B35: 5년 | C35: 10 | D35: =1000000 -> 1000000 | E35: 10만원상당 복지포인트지급(2021년대상자)
B36: 10년 | C36: 5 | D36: =6116580+1911000 -> 8027580 | E36: 포상금(5명,6,116,580원)+금/환산금액(6명,1,911,000원) | F36: 인당3일
B37: 15년 | C37: 3 | D37: =6669600+3185000 -> 9854600 | E37: 포상금(3명,6,669,600원)+금/환산금액(2명,3,185,000원) | F37: 인당5일
B38: 20년 | C38: 6 | D38: =31863600+12740000 -> 44603600 | E38: 포상금(6명,31,863,600원)+금/환산금액(6명,12,740,000원) | F38: 인당7일
B39: 25년 | F39: 인당10일
B40: 30년
B41: 합계 | D41: =SUM(D35:D40) -> 63485780
B43: 평가기준일 직전 2년 (2021.1.1~2021.12.31)
B44: 근속년수 | C44: 근속자(명) | D44: 장기근속축하금(합계, 원) | E44: 세부 내역
B45: 5년 | C45: 22 | D45: =1000000+1200000 -> 2200000 | E45: 10만원상당 복지포인트지급(2019년,2020년대상자)
B46: 10년 | C46: 12 | D46: =(1363710+9595780+1681610+1401520)+3588000 -> 17630620 | E46: 포상금(12명,14,042,620원)+금/환산금액(12명,3,588,000원) | F46: 인당3일
B47: 15년 | C47: 7 | D47: =(2764260+2138430+2094780+2104260+2062560+2244610+3060960)+11960000 -> 28429860 | E47: 포상금(7명,16,469,860원)+금/환산금액(8명,11,960,000원) | F47: 인당5일
B48: 20년 | C48: 1 | D48: =3656280+8970000 -> 12626280 | E48: 포상금(1명,13,656,280원)+금/환산금액(3명,8,970,000원) | F48: 인당7일
...

Sheet (2-1) 명부 작성방법
C2: (2-1) 명부 작성방법
C3: ☞ 모든 항목은 필수 입력 사항입니다.
C4: ☞ 명부는 "(2-2) 재직자 명부", "(2-3) 퇴직자 및 DC 전환자 명부", "(2-3) 추가 명부" 로 구분됩니다.
C6: 구분 | D6: 항목명 | E6: 작성방법
C7: 공통 | E7: 평가기준일을 기준으로 작성 양식 변경 절대 불가 1년 미만 근속 재직자 포함 퇴직금을 지급하지 않는 재직자 제외 DC 또는 IRP 제도 가입자는 제외
D8: 사원번호 | E8: 회사가 정한 사원번호 입력
D9: 생년월일 | E9: yyyymmdd 형식
D10: 성별 | E10: 남 : 1, 여 : 2
D11: 입사일자 | E11: yyyymmdd 형식, 최초 입사일자 (퇴직금 산정 기준일) 입력
C12: 재직자 명부 | D12: 기준급여 | E12: 퇴직금 지급의 기준이 되는 월 기준급여 입력 (예: 법정제인 경우 평균임금)
D13: 당년도 퇴직금추계액 | E13: 사규에서 정하는 퇴직금 추계액 입력(평가기준일 기준) 임원, 계약직은 필수 입력
D14: 차년도 퇴직금추계액 | E14: 사규에서 정하는 차년도퇴직금추계액 입력(평가기준일로 부터 1년후 퇴직을 가정) 임원, 계약직은 필수 입력
D15: 종업원 구분 | E15: 일반직: 1, 임원: 3, 계약직: 4 계약직이라도 정규직의 퇴직금규정을 적용하고 정년이 일반직과 동일한 경우 2 입력(직종 3, 4는 정년이 적용되지 않음)
D16: 중간정산기준일 | E16: 입사 후 중간정산 한 적이 있는 경우 반드시 입력 중간정산일 당일 입력 여러 번 중간정산한 경우 최종 중간정산일자 입력
D17: 중간정산액 | E17: =LEFT('(1-2) 기초자료_퇴직급여 '!I25,4)&"년에 중간정산 한 재직자는 반드시 입력"& "(그 외의 중간정산자는 입력하지 않아도 됨)" -> 2022년에 중간정산 한 재직자는 반드시 입력(그 외의 중간정산자는 입력하지 않아도 됨)
D18: 제도구분 | E18: 퇴직금 제도가 구분 되어 적용되는 경우 숫자로 구분 (1,2,3..) 구분되지 않는 경우는 입력하지 않아도 됨 (예 생산: 1 , 사무직: 2)
C19: 퇴직자 및 DC전환자 명부 | E19: 300인 이상인 기업의 경우 3년치(평가기준일 직전 3년간) 퇴직자명부 작성 300인 미만인 경우 해당 회계년도의 퇴직자만 작성
D20: 퇴직일 / DC전환일 | E20: 퇴직일 또는 DC 전환일 입력
D21: 사유 | E21: 1: 퇴직, 2: DC전환 구분 입력
D22: 제도구분 | E22: 퇴직금 제도가 구분 되어 적용되는 경우 숫자로 구분 (1,2,3..) 구분되지 않는 경우는 입력하지 않아도 됨 (예 생산: 1 , 사무직: 2)
C23: 추가 명부 | D23: 유의적인 채무 변동이 있을 경우 변동 원인을 평가하여 반영하기 위한 명부
E24: 다음 중 해당사항이 있는 경우에만 입력 : 축소, 정산, 사업결합, 사업분할,기타장기종업원급여 해당 사건 발생일을 기준으로 작성
D25: 기준급여, 직종, 중간정산일 | E25: 재직자 명부와 동일한 방식으로 작성
D26: 사유발생일 시점 퇴직금추계액 | E26: 사유발생일 시점에 퇴직 시 지급하여야 하는 퇴직금 입력
D27: 사유 | E27: 1: 관계사전입, 2: 관계사전출, 3: 사업결합, 4: 사업처분, 5: 기타장기종업원 해당사항 숫자로 입력
D28: 사유발생일 | E28: 해당 사유 발생일 입력

Sheet (2-2) 재직자 명부
A1: 참고사항 | B1: 사원번호 | C1: 생년월일 | D1: 성별 (1:남자, 2:여자) | E1: 입사일자 | F1: 기준급여 | G1: 당년도 퇴직금추계액 | H1: 차년도 퇴직금추계액 | I1: 종업원 구분 (1:직원, 3:임원, 4:계약직) | J1: 중간정산기준일 | K1: 중간정산액 | L1: 제도구분 (1,2,3) | M1: 적용배수 | N1: 휴직기간등차감
A2: ※ 양식 변경 절대 불가 | B2: 1 | C2: 30962 | D2: 1 | E2: 40637 | F2: 7736629.8 | G2: 90931895 | H2: =IF(I2=3,G2+F2*M2,G2+F2) -> 98668525 | I2: 1 | J2: 40637 | N2: 0 | P2: =N2/366 -> 0
A3: 입사일자 | B3: 2 | C3: 27044 | D3: 1 | E3: 39034 | F3: 12309757 | G3: 150920996 | H3: =IF(I3=3,G3+F3*M3,G3+F3) -> 1.6323075e+08 | I3: 1 | J3: 40452 | N3: 0 | P3: =N3/366 -> 0
A4: 최초 입사일자 입력 | B4: 3 | C4: 29564 | D4: 1 | E4: 39574 | F4: 7345500.3 | G4: 107727297 | H4: =IF(I4=3,G4+F4*M4,G4+F4) -> 1.150728e+08 | I4: 1 | J4: 39574 | N4: 0 | P4: =N4/366 -> 0
A5: 기준급여 | B5: 4 | C5: 26828 | D5: 2 | E5: 37803 | F5: 6602487.7 | G5: 84276685 | H5: =IF(I5=3,G5+F5*M5,G5+F5) -> 90879173 | I5: 1 | J5: 40268 | N5: 0 | P5: =N5/366 -> 0
A6: 퇴직금 계산시 사용되는 평균임금 | B6: 5 | C6: 26109 | D6: 2 | E6: 37803 | F6: 7833694.8 | G6: 152896553 | H6: =IF(I6=3,G6+F6*M6,G6+F6) -> 1.6073025e+08 | I6: 1 | J6: 37803 | N6: 0 | P6: =N6/366 -> 0
A7: 당년도 퇴직금추계액 | B7: 6 | C7: 25911 | D7: 2 | E7: 37803 | F7: 6532637.7 | G7: 88271148 | H7: =IF(I7=3,G7+F7*M7,G7+F7) -> 94803786 | I7: 1 | J7: 39995 | N7: 0 | P7: =N7/366 -> 0
A8: 작성기준일 현재 퇴직시 지급하는 퇴직금 | B8: 7 | C8: 27008 | D8: 2 | E8: 37803 | F8: 6334743 | G8: 123640299 | H8: =IF(I8=3,G8+F8*M8,G8+F8) -> 129975042 | I8: 1 | J8: 37803 | N8: 0 | P8: =N8/366 -> 0
A9: (임원, 계약직 필수 입력) | B9: 8 | C9: 27132 | D9: 2 | E9: 37803 | F9: 6274895.1 | G9: 122472199 | H9: =IF(I9=3,G9+F9*M9,G9+F9) -> 1.2874709e+08 | I9: 1 | J9: 37803 | N9: 0 | P9: =N9/366 -> 0
A10: 차년도 퇴직금추계액 | B10: 9 | C10: 26956 | D10: 2 | E10: 37803 | F10: 6561839.8 | G10: 88665737 | H10: =IF(I10=3,G10+F10*M10,G10+F10) -> 95227577 | I10: 1 | J10: 39995 | N10: 0 | P10: =N10/366 -> 0
A11: 작성기준일로부터 1년 후 퇴직시 지급하는 퇴직금 | B11: 10 | C11: 26970 | D11: 2 | E11: 37803 | F11: 7045977.6 | G11: 137522039 | H11: =IF(I11=3,G11+F11*M11,G11+F11) -> 1.4456802e+08 | I11: 1 | J11: 37803 | N11: 0 | P11: =N11/366 -> 0
A12: (임원, 계약직 필수 입력) | B12: 11 | C12: 25734 | D12: 2 | E12: 37865 | F12: 8592587.4 | G12: 166248911 | H12: =IF(I12=3,G12+F12*M12,G12+F12) -> 1.748415e+08 | I12: 1 | J12: 37865 | N12: 0 | P12: =N12/366 -> 0
A13: 중간정산기준일 | B13: 12 | C13: 25213 | D13: 2 | E13: 37803 | F13: 6793644.5 | G13: 132597050 | H13: =IF(I13=3,G13+F13*M13,G13+F13) -> 1.3939069e+08 | I13: 1 | J13: 37803 | N13: 0 | P13: =N13/366 -> 0
... A16: 중간정산액 | B16: 15 | C16: 27775 | D16: 2 | E16: 37803 | F16: 6561880 | G16: 128073515 | H16: =IF(I16=3,G16+F16*M16,G16+F16) -> 134635395 | I16: 1 | J16: 37803 | N16: 0 | P16: =N16/366 -> 0
A17: =LEFT('(1-2) 기초자료_퇴직급여 '!I26,4)&"년에 중간정산한 종업원은 반드시 입력" -> 16년에 중간정산한 종업원은 반드시 입력 | B17: 16 | C17: 28158 | D17: 2 | E17: 37803 | F17: 6166967.9 | G17: 83330098 | H17: =IF(I17=3,G17+F17*M17,G17+F17) -> 89497066 | I17: 1 | J17: 39995 | N17: 0 | P17: =N17/366 -> 0
A18: 그 외 중간정산자는 입력하지 않아도 됨 | B18: 17 | C18: 28176 | D18: 2 | E18: 37803 | F18: 10214152 | G18: 199357866 | H18: =IF(I18=3,G18+F18*M18,G18+F18) -> 2.0957202e+08 | I18: 1 | J18: 37803 | N18: 0 | P18: =N18/366 -> 0
A19: 제도구분 | B19: 18 | C19: 25114 | D19: 1 | E19: 37803 | F19: 10488480 | G19: 141723788 | H19: =IF(I19=3,G19+F19*M19,G19+F19) -> 1.5221227e+08 | I19: 1 | J19: 39995 | N19: 0 | P19: =N19/366 -> 0
A20: 구분되는 제도를 반영하는 경우 입력 (숫자기입) | B20: 19 | C20: 28358 | D20: 2 | E20: 37803 | F20: 7170772.1 | G20: 135517769 | H20: =IF(I20=3,G20+F20*M20,G20+F20) -> 1.4268854e+08 | I20: 1 | J20: 37803 | N20: 226 | P20: =N20/366 -> 0.61748634
A21: 적용배수 | B21: 20 | C21: 25844 | D21: 1 | E21: 37803 | F21: 10501142 | G21: 141894884 | H21: =IF(I21=3,G21+F21*M21,G21+F21) -> 1.5239603e+08 | I21: 1 | J21: 39995 | N21: 0 | P21: =N21/366 -> 0
A22: 임원의 경우 적용 배수 입력 ( 예: 1.5, 2, 3... ) | B22: 21 | C22: 27607 | D22: 2 | E22: 37803 | F22: 6045081.7 | G22: 117986745 | H22: =IF(I22=3,G22+F22*M22,G22+F22) -> 1.2403183e+08 | I22: 1 | J22: 37803 | N22: 0 | P22: =N22/366 -> 0
A23: 기타 | B23: 22 | C23: 27654 | D23: 2 | E23: 37803 | F23: 7073588 | G23: 95580647 | H23: =IF(I23=3,G23+F23*M23,G23+F23) -> 102654235 | I23: 1 | J23: 39995 | N23: 0 | P23: =N23/366 -> 0
A24: 전액 확정기여형(DC) 제도 가입자는 제외 | B24: 23 | C24: 26314 | D24: 2 | E24: 37803 | F24: 6870782 | G24: 134102605 | H24: =IF(I24=3,G24+F24*M24,G24+F24) -> 140973387 | I24: 1 | J24: 37803 | N24: 0 | P24: =N24/366 -> 0
A25: 1년 미만 재직자도 입력 | B25: 24 | C25: 27542 | D25: 2 | E25: 37803 | F25: 9484587.7 | G25: 128158867 | H25: =IF(I25=3,G25+F25*M25,G25+F25) -> 1.3764345e+08 | I25: 1 | J25: 39995 | N25: 0 | P25: =N25/366 -> 0
A26: 기준급여 * 지급률 = 당년도 퇴직금추계액 | B26: 25 | C26: 27619 | D26: 2 | E26: 37803 | F26: 7504276.7 | G26: 101400253 | H26: =IF(I26=3,G26+F26*M26,G26+F26) -> 1.0890453e+08 | I26: 1 | J26: 39995 | N26: 0 | P26: =N26/366 -> 0
B27: 26 | C27: 28656 | D27: 1 | E27: 37895 | F27: 9668023.2 | G27: 130637508 | H27: =IF(I27=3,G27+F27*M27,G27+F27) -> 1.4030553e+08 | I27: 1 | J27: 39995 | N27: 0 | P27: =N27/366 -> 0
B28: 27 | C28: 25373 | D28: 1 | E28: 37895 | F28: 16666670 | G28: 22222227 | H28: =IF(I28=3,G28+F28*M28,G28+F28) -> 55555567 | I28: 3 | J28: 44682 | K28: 241905680 | M28: 2 | N28: 0 | O28: 임원승진에 따른 직원퇴직금정산 | P28: =N28/366 -> 0
B29: 28 | C29: 29169 | D29: 2 | E29: 38749 | F29: 9795410 | G29: 165797378 | H29: =IF(I29=3,G29+F29*M29,G29+F29) -> 175592788 | I29: 1 | J29: 38749 | N29: 0 | P29: =N29/366 -> 0
B30: 29 | C30: 29124 | D30: 2 | E30: 38749 | F30: 9530202.9 | G30: 161308476 | H30: =IF(I30=3,G30+F30*M30,G30+F30) -> 1.7083868e+08 | I30: 1 | J30: 38749 | N30: 0 | P30: =N30/366 -> 0
B31: 30 | C31: 28571 | D31: 1 | E31: 38749 | F31: 7564061.8 | G31: 128029516 | H31: =IF(I31=3,G31+F31*M31,G31+F31) -> 1.3559358e+08 | I31: 1 | J31: 38749 | N31: 0 | P31: =N31/366 -> 0
B32: 31 | C32: 29277 | D32: 1 | E32: 39301 | F32: 7466518.5 | G32: 115086666 | H32: =IF(I32=3,G32+F32*M32,G32+F32) -> 1.2255318e+08 | I32: 1 | J32: 39301 | N32: 0 | P32: =N32/366 -> 0
B33: 32 | C33: 29487 | D33: 1 | E33: 39489 | F33: 8128924.4 | G33: 115475269 | H33: =IF(I33=3,G33+F33*M33,G33+F33) -> 1.2360419e+08 | I33: 1 | J33: 39489 | N33: 253 | P33: =N33/366 -> 0.69125683
B34: 33 | C34: 30082 | D34: 1 | E34: 39489 | F34: 7303345.3 | G34: 108809841 | H34: =IF(I34=3,G34+F34*M34,G34+F34) -> 1.1611319e+08 | I34: 1 | J34: 39489 | N34: 0 | P34: =N34/366 -> 0
B35: 34 | C35: 29657 | D35: 2 | E35: 39575 | F35: 4872108.6 | G35: 71439795 | H35: =IF(I35=3,G35+F35*M35,G35+F35) -> 76311904 | I35: 1 | J35: 39575 | N35: 0 | P35: =N35/366 -> 0
B36: 35 | C36: 28203 | D36: 1 | E36: 39713 | F36: 9180632 | G36: 131144699 | H36: =IF(I36=3,G36+F36*M36,G36+F36) -> 140325331 | I36: 1 | J36: 39713 | N36: 0 | P36: =N36/366 -> 0
B37: 36 | C37: 31452 | D37: 2 | E37: 39972 | F37: 4795939.8 | G37: 65106525 | H37: =IF(I37=3,G37+F37*M37,G37+F37) -> 69902465 | I37: 1 | J37: 39972 | N37: 0 | P37: =N37/366 -> 0
B38: 37 | C38: 30831 | D38: 2 | E38: 40227 | F38: 3416324 | G38: 43991021 | H38: =IF(I38=3,G38+F38*M38,G38+F38) -> 47407345 | I38: 1 | J38: 40227 | N38: 0 | P38: =N38/366 -> 0
B39: 38 | C39: 31743 | D39: 2 | E39: 40429 | F39: 7730944.3 | G39: 95270651 | H39: =IF(I39=3,G39+F39*M39,G39+F39) -> 1.030016e+08 | I39: 1 | J39: 40429 | N39: 0 | P39: =N39/366 -> 0
B40: 39 | C40: 29809 | D40: 1 | E40: 40546 | F40: 8384847.2 | G40: 100641139 | H40: =IF(I40=3,G40+F40*M40,G40+F40) -> 1.0902599e+08 | I40: 1 | J40: 40546 | N40: 0 | P40: =N40/366 -> 0
... B52: 51 | C52: 32442 | D52: 2 | E52: 41092 | F52: 4658147.3 | G52: 48942452 | H52: =IF(I52=3,G52+F52*M52,G52+F52) -> 53600599 | I52: 1 | J52: 41092 | N52: 0 | P52: =N52/366 -> 0
B53: 52 | C53: 24660 | D53: 1 | E53: 37285 | F53: 23333340 | G53: 253561902 | H53: =IF(I53=3,G53+F53*M53,G53+F53) -> 311895252 | I53: 3 | J53: 43157 | M53: 2.5 | N53: 0 | P53: =N53/366 -> 0
...

Sheet (2-3) 퇴직자 및 DC전환자 명부
A1: 참고사항 | B1: 사원번호 | C1: 생년월일 | D1: 성별 (1:남자, 2:여자) | E1: 입사일자 | F1: 퇴직일 또는 DC전환일 | G1: 퇴직금 또는 DC전환금 | H1: 종업원 구분 (1:직원, 3:임원, 4:계약직) | I1: 사유 (1: 퇴직, 2: DC전환) | J1: 제도구분 (1,2,3)
A2: ※ 양식 변경 절대 불가 | B2: 861 | C2: 24685 | D2: 1 | E2: 37803 | F2: 44834 | G2: 165385618 | H2: 1 | I2: 1
A3: 해당 회계연도에 발생한 사항 입력 | B3: 862 | C3: 23757 | D3: 1 | E3: 43801 | F3: 44834 | G3: 31354996 | H3: 4 | I3: 1
A4: 퇴직금(DC전환금)이 0인 경우에도 입력 | B4: 863 | C4: 29587 | D4: 1 | E4: 44378 | F4: 44834 | G4: 8737780 | H4: 4 | I4: 1 | K4: 케피탈복귀로 퇴직금이관
A5: 전액 확정기여형(DC)을 가입한 퇴직자 제외 | B5: 864 | C5: 26568 | D5: 1 | E5: 44396 | F5: 44838 | G5: 9525000 | H5: 4 | I5: 1
B6: 865 | C6: 30742 | D6: 2 | E6: 44508 | F6: 44848 | G6: 0 | H6: 1 | I6: 1
B7: 866 | C7: 29841 | D7: 1 | E7: 44743 | F7: 44851 | G7: 0 | H7: 1 | I7: 1
B8: 867 | C8: 32285 | D8: 2 | E8: 42877 | F8: 44866 | G8: 41042243 | H8: 1 | I8: 1
B9: 868 | C9: 33268 | D9: 2 | E9: 43335 | F9: 44866 | G9: 13839118 | H9: 1 | I9: 1
B10: 869 | C10: 32288 | D10: 2 | E10: 44179 | F10: 44866 | G10: 5586770 | H10: 4 | I10: 1
B11: 870 | C11: 30293 | D11: 1 | E11: 43460 | F11: 44871 | G11: 24414417 | H11: 1 | I11: 1
B12: 871 | C12: 26306 | D12: 1 | E12: 44312 | F12: 44874 | G12: 14434627 | H12: 1 | I12: 1
B13: 872 | C13: 32864 | D13: 2 | E13: 44448 | F13: 44875 | G13: 5093062 | H13: 1 | I13: 1
B14: 873 | C14: 29338 | D14: 1 | E14: 44382 | F14: 44876 | G14: 8575080 | H14: 1 | I14: 1
B15: 874 | C15: 35789 | D15: 2 | E15: 44697 | F15: 44895 | G15: 0 | H15: 1 | I15: 1
B16: 875 | C16: 26247 | D16: 1 | E16: 39077 | F16: 44895 | G16: 206697360 | H16: 1 | I16: 2
B17: 876 | C17: 30538 | D17: 1 | E17: 43206 | F17: 44897 | G17: 31625538 | H17: 1 | I17: 1
... B21: 402 | C21: 34362 | D21: 2 | E21: 43866 | F21: 44926 | G21: 13507040 | H21: 1 | I21: 1
B22: 403 | C22: 24634 | D22: 1 | E22: 37803 | F22: 44926 | G22: 147597294 | H22: 1 | I22: 1 | K22: 147597294 | L22: 1/2사외적립자산차감예정
B23: 404 | C23: 23364 | D23: 1 | E23: 43388 | F23: 44926 | G23: 63223026 | H23: 4 | I23: 1 | K23: 63223026 | L23: 1/2사외적립자산차감예정
B24: 405 | C24: 29355 | D24: 2 | E24: 44851 | F24: 44926 | G24: 0 | H24: 1 | I24: 1
B25: 406 | C25: 35163 | D25: 1 | E25: 44767 | F25: 44926 | G25: 0 | H25: 1 | I25: 1
B26: 407 | C26: 32166 | D26: 2 | E26: 44622 | F26: 44926 | G26: 0 | H26: 4 | I26: 1
B27: 408 | C27: 27397 | D27: 1 | E27: 44921 | F27: 5833333 | G27: 95890 | H27: =IF(I27=3,G27+F27*M27,G27+F27) -> 5929223 | I27: 4 | J27: 44921 | N27: 0 | P27: =N27/366 -> 0

Sheet (2-4) 추가 명부(장기근속)
A1: 참고사항 | B1: 사원번호 | C1: 생년월일 | D1: 성별 (1:남자, 2:여자) | E1: 입사일자 | F1: 기준급여 | G1: 사유발생일 시점 발생금액 | H1: 종업원 구분 (1:직원, 3:임원, 4:계약직) | I1: 중간정산기준일 | J1: 사유 (1:관계사전입, 2:관계사전출, 3:사업결합, 4:사업처분 5:기타장기종업원) | K1: 사유발생일 | L1: 직무그룹 | N1: 제도구분
A2: ※ 양식 변경 절대 불가 | B2: 409 | C2: 30962 | D2: 1 | E2: 40637 | F2: 7736629.8 | H2: 1 | I2: 40637 | J2: 5 | L2: 기획관리그룹
B3: 410 | C3: 26880 | D3: 1 | E3: 42062 | F3: 13533758 | H3: 1 | J3: 5 | L3: 실장 | N3: DC형
A4: 아래의 사항에 해당하는 경우 입력 | B4: 411 | C4: 27044 | D4: 1 | E4: 39034 | F4: 12309757 | H4: 1 | I4: 40452 | J4: 5 | L4: 기획관리그룹
A5: : 축소, 정산, 사업결합, 사업분할 | B5: 412 | C5: 29564 | D5: 1 | E5: 39574 | F5: 7345500.3 | H5: 1 | I5: 39574 | J5: 5 | L5: 기획관리그룹
A6: 해당 사유 발생일을 기준으로 입력 | B6: 413 | C6: 26828 | D6: 2 | E6: 37803 | F6: 6602487.7 | H6: 1 | I6: 40268 | J6: 5 | L6: 운영지원그룹
A7: 입사일자 | B7: 414 | C7: 26109 | D7: 2 | E7: 37803 | F7: 7833694.8 | H7: 1 | I7: 37803 | J7: 5 | L7: 기획관리그룹
A8: 최초 입사일자 입력 | B8: 415 | C8: 25911 | D8: 2 | E8: 37803 | F8: 6532637.7 | H8: 1 | I8: 39995 | J8: 5 | L8: 운영지원그룹
B9: 416 | C9: 24766 | D9: 1 | E9: 37803 | F9: 7538496.9 | H9: 1 | J9: 5 | L9: 기획관리그룹 | N9: DC형
A10: 기준급여 | B10: 417 | C10: 27008 | D10: 2 | E10: 37803 | F10: 6334743 | H10: 1 | I10: 37803 | J10: 5 | L10: 운영지원그룹
A11: 퇴직금 계산시 사용되는 평균임금 | B11: 418 | C11: 27132 | D11: 2 | E11: 37803 | F11: 6274895.1 | H11: 1 | I11: 37803 | J11: 5 | L11: 운영지원그룹
A12: 사유 발생일 기준 | B12: 419 | C12: 26956 | D12: 2 | E12: 37803 | F12: 6561839.8 | H12: 1 | I12: 39995 | J12: 5 | L12: 운영지원그룹
B13: 420 | C13: 24852 | D13: 1 | E13: 37803 | F13: 8171718.9 | H13: 1 | J13: 5 | L13: 기획관리그룹 | N13: DC형
B14: 421 | C14: 24748 | D14: 1 | E14: 37803 | F14: 7943603.2 | H14: 1 | J14: 5 | L14: 기획관리그룹 | N14: DC형
B15: 422 | C15: 24341 | D15: 1 | E15: 37803 | F15: 11152499 | H15: 1 | J15: 5 | L15: 부실장 | N15: DC형
A16: 당년도 퇴직금추계액 | B16: 423 | C16: 26970 | D16: 2 | E16: 37803 | F16: 7045977.6 | H16: 1 | I16: 37803 | J16: 5 | L16: 기획관리그룹
A17: 사유발생일 현재 퇴직금추계액 | B17: 424 | C17: 25734 | D17: 2 | E17: 37865 | F17: 8592587.4 | H17: 1 | I17: 37865 | J17: 5 | L17: 영업관리그룹
A18: (임원, 계약직 필수 입력) | B18: 425 | C18: 25213 | D18: 2 | E18: 37803 | F18: 6793644.5 | H18: 1 | I18: 37803 | J18: 5 | L18: 운영지원그룹
A19: 중간정산기준일 | B19: 426 | C19: 26343 | D19: 2 | E19: 37803 | F19: 6386893.8 | H19: 1 | I19: 39995 | J19: 5 | L19: 운영지원그룹
B20: 427 | C20: 25365 | D20: 1 | E20: 37803 | F20: 7914821.4 | H20: 1 | J20: 5 | L20: 기획관리그룹 | N20: DC형
B21: 428 | C21: 25292 | D21: 1 | E21: 37803 | F21: 7778194.8 | H21: 1 | J21: 5 | L21: 기획관리그룹 | N21: DC형
B22: 429 | C22: 27592 | D22: 2 | E22: 37803 | F22: 6665050.8 | H22: 1 | J22: 5 | L22: 운영지원그룹 | N22: DC형
A23: 입사 후 중간정산한 적이 있는 경우 반드시 입력 | B23: 430 | C23: 27504 | D23: 2 | E23: 37803 | F23: 6785991.6 | H23: 1 | I23: 39995 | J23: 5 | L23: 운영지원그룹
A24: 중간정산 당일로 입력 | B24: 431 | C24: 27775 | D24: 2 | E24: 37803 | F24: 6561880 | H24: 1 | I24: 37803 | J24: 5 | L24: 운영지원그룹
B25: 432 | C25: 27747 | D25: 2 | E25: 37803 | F25: 7173571.2 | H25: 1 | J25: 5 | L25: 기획관리그룹 | N25: DC형
B26: 433 | C26: 25571 | D26: 1 | E26: 37803 | F26: 7930676.9 | H26: 1 | J26: 5 | L26: 기획관리그룹 | N26: DC형
B27: 434 | C27: 28158 | D27: 2 | E27: 37803 | F27: 6166967.9 | H27: 1 | I27: 39995 | J27: 5 | L27: 운영지원그룹
B28: 435 | C28: 24938 | D28: 1 | E28: 37803 | F28: 8006557.3 | H28: 1 | J28: 5 | L28: 기획관리그룹 | N28: DC형
B29: 436 | C29: 25834 | D29: 1 | E29: 37803 | F29: 8859316.4 | H29: 1 | J29: 5 | L29: 기획관리그룹 | N29: DC형
B30: 437 | C30: 28176 | D30: 2 | E30: 37803 | F30: 10214152 | H30: 1 | I30: 37803 | J30: 5 | L30: 기획관리그룹
B31: 438 | C31: 24877 | D31: 1 | E31: 37803 | F31: 12835224 | H31: 1 | J31: 5 | L31: 실장 | N31: DC형
B32: 439 | C32: 25554 | D32: 1 | E32: 37803 | F32: 8320970.8 | H32: 1 | J32: 5 | L32: 기획관리그룹 | N32: DC형
B33: 440 | C33: 24835 | D33: 1 | E33: 37803 | F33: 8796689.7 | H33: 1 | J33: 5 | L33: 기획관리그룹 | N33: DC형
B34: 441 | C34: 25304 | D34: 1 | E34: 37803 | F34: 7706941.9 | H34: 1 | J34: 5 | L34: 기획관리그룹 | N34: DC형
B35: 442 | C35: 25294 | D35: 1 | E35: 37803 | F35: 8592963.3 | H35: 1 | J35: 5 | L35: 기획관리그룹 | N35: DC형
B36: 443 | C36: 25207 | D36: 1 | E36: 37803 | F36: 8121482.2 | H36: 1 | J36: 5 | L36: 기획관리그룹 | N36: DC형
B37: 444 | C37: 25114 | D37: 1 | E37: 37803 | F37: 10488480 | H37: 1 | I37: 39995 | J37: 5 | L37: 기획관리그룹
B38: 445 | C38: 25030 | D38: 1 | E38: 37803 | F38: 7132440.3 | H38: 1 | J38: 5 | L38: 기획관리그룹 | N38: DC형
B39: 446 | C39: 28358 | D39: 2 | E39: 37803 | F39: 7170772.1 | H39: 1 | I39: 37803 | J39: 5 | L39: 기획관리그룹
B40: 447 | C40: 25378 | D40: 1 | E40: 37803 | F40: 8305324 | H40: 1 | J40: 5 | L40: 기획관리그룹 | N40: DC형
...
